Workbook

Sheet 견적
A2: 견 적 서
A4: 받으실분 | C4: (주)씨젠 | E4: 에프에이리눅스 주식회사 오 재 경
C5: 김성조 차장 귀하 | E5: (16006) 경기도 의왕시 포일동 653
A6: T E L | C6: 02-2195-6266 / 010-8682-1192 | E6: 인덕원IT밸리 B동 1001호
A7: F A X | E7: TEL/FAX : 02-572-9527 / 070-7862-5155
A8: 견적일자 | C8: 45076 | E8: 담 당 : 박문식 이사
A9: 견적번호 | C9: PH1-230530001 | E9: 연락처 : 070-7862-5148/010-9429-7998
A10: 유효기간 | C10: 견적일로부터 15일 | E10: E-mail : boggle70@falinux.com
A12: 견 적 명 | D12: 매니코어 기반 고성능 컴퓨터 자원 인프라 병렬처리시스템 라이브러리 통합 환경 구축
A13: 납 기 | D13: 별도 계약서 상의 일정 명시
A14: 합 계 금 액 | D14: =TEXT(H52,"일금 [DBNum4][$-412]G/표준원정(")&TEXT(H52,"###,### - VAT별도 )") -> 일금 칠억이천만원정(720,000,000 - VAT별도 )
D15: =TEXT(H52+(H52/10),"일금 [DBNum4][$-412]G/표준원정(")&TEXT(H52+(H52/10),"###,### - VAT포함 )") -> 일금 칠억구천이백만원정(792,000,000 - VAT포함 )
A16: NO | B16: 품 명 | D16: 규 격 | E16: 수 량 | G16: 단 가 | H16: 금 액
A17: 1 | B17: 고성능 컴퓨팅(HPC) 및 병렬 프로그래밍 환경 구축 및 안정화 | D17: 로그 데이터 수집, 저장, 검색, 분석 기능 구현 | E17: 1 | G17: =Sheet6!B1 -> 20700000 | H17: =G17 -> 20700000
D18: 사용자별, 작업별 로그 데이터 관리 기능 제공 | E18: 1 | G18: =Sheet6!B2 -> 18630000 | H18: =G18 -> 18630000
D19: 병렬 프로그램의 실행 상태, 성능 의 실시간 모니터링 기능 제공 | E19: 1 | G19: =Sheet6!B3 -> 22770000 | H19: =SUM(G19:G20) -> 41400000
D20: 병렬 분산 처리를 위한 효율적인 라이브러리 구축 및 테스트 | E20: 1 | G20: =Sheet6!B4 -> 18630000
D21: 안정적인 서비스를 위한 에러 및 예외 처리 시스템 구현 | E21: 1 | G21: =Sheet6!B5 -> 22770000 | H21: =SUM(G21:G22) -> 43470000
D22: HPC 시스템에 대한 사용자 인터페이스 및 API 제공 | E22: 1 | G22: =Sheet6!B6 -> 20700000
D23: 시스템의 성능 모니터링 및 리포트 생성 기능 제공 | E23: 1 | G23: =Sheet6!B7 -> 22770000 | H23: =G23 -> 22770000
D24: 병렬 프로그래밍을 위한 개발 환경 구축 | E24: 1 | G24: =Sheet6!B8 -> 16560000 | H24: =G24 -> 16560000
D25: HPC 사용자 및 개발자를 위한 사용자 문서 지원 | E25: 1 | G25: =Sheet6!B9 -> 24840000 | H25: =G25 -> 24840000
D26: 시스템 확장성 및 고가용성을 고려한 인프라 설계 | E26: 1 | G26: =Sheet6!B10 -> 18630000 | H26: =G26 -> 18630000
D27: 소 계 | H27: =SUM(H17:H26) -> 207000000
A28: 2 | B28: 인실리코 분석응용 지원을 위한 데이터 분산 처리 시스템 구축 | D28: 대규모 데이터를 효율적으로 처리할 수 있는 분산처리 시스템 구현 | E28: 1 | G28: =Sheet6!D1 -> 24030000 | H28: =SUM(G28:G30) -> 72090000
D29: 인실리코 분석응용의 필요한 자원별 시스템 자원 동적 할당 관리 시스템 | E29: 1 | G29: =Sheet6!D2 -> 24030000
D30: 사용자 친화적인 인터페이스 및 API 제공 | E30: 1 | G30: =Sheet6!D3 -> 24030000
D31: 성능 모니터링 및 최적화 도구 제공 | E31: 1 | G31: =Sheet6!D4 -> 29370000 | H31: =G31 -> 29370000
D32: 데이터 처리 결과의 신속한 전달을 위한 메시징 시스템 구축 | E32: 1 | G32: =Sheet6!D5 -> 21360000 | H32: =SUM(G32:G33) -> 45390000
D33: HPC 산출물 관리 전략 수립 | E33: 1 | G33: =Sheet6!D6 -> 24030000
D34: HPC 시스템의 안정성을 위한 모니터링 및 알림 시스템 구현 | E34: 1 | G34: =Sheet6!D7 -> 24030000 | H34: =SUM(G34:G35) -> 48060000
D35: 분석응용 상태 단계별 프로세싱 보고기능 제공 | E35: 1 | G35: =Sheet6!D8 -> 24030000
D36: 인실리코 소프트웨어 통합을 위한 확장 가능한 API 설계 | E36: 1 | G36: =Sheet6!D9 -> 21360000 | H36: =SUM(G36:G37) -> 48060000
D37: 데이터 처리의 효율성을 높이기 위한 최적화 전략 수립 | E37: 1 | G37: =Sheet6!D10 -> 26700000
D38: 인실리코 분석응용 버전 관리 및 업데이트 시스템 구축 | E38: 1 | G38: =Sheet6!D11 -> 24030000 | H38: =E38*G38 -> 24030000
D39: 소 계 | H39: =SUM(H28:H38) -> 267000000
A40: 3 | B40: 현 시스템 분석 및 전략 수립을 통한 병렬 분산처리 라이브러리 구축 | D40: 시스템의 성능, 자원 사용량, 문제점 등을 분석하는 기능제공 | E40: 1 | G40: =Sheet6!F1 -> 14760000 | H40: =SUM(G40:G42) -> 59040000
D41: 병렬 분산처리 라이브러리 구축 전략 수립 | E41: 1 | G41: =Sheet6!F2 -> 17220000
D42: 병렬 분산처리 자원 시스템 확장을 위한 로드맵 제시 | E42: 1 | G42: =Sheet6!F3 -> 27060000
D43: 병렬 라이브러리에 대한 교육 및 문서 지원 | E43: 1 | G43: =Sheet6!F4 -> 19680000 | H43: =G43 -> 19680000
...

Sheet 1
A1: NO | B1: 품 명 | D1: 규 격 | F1: 수 량 | H1: 단 가 | I1: 금 액
A2: 1 | B2: 고성능 컴퓨팅(HPC) 및 병렬 프로그래밍 환경 구축 및 안정화 | D2: =견적!D17 -> 로그 데이터 수집, 저장, 검색, 분석 기능 구현 | E2: HPC 로그 데이터 수집기 개발 | F2: 1 | H2: =Sheet6!B1 -> 20700000 | I2: =H2 -> 20700000
E3: HPC 로그 데이터 분석기 개발
E4: HPC 로그 데이트 검색기 개발
D5: =견적!D18 -> 사용자별, 작업별 로그 데이터 관리 기능 제공 | E5: 사용자 로그 데이터 관리 시스템 개발 | F5: 1 | H5: =Sheet6!B2 -> 18630000 | I5: =H5 -> 18630000
E6: 작업별 로그 데이터 관리 시스템 개발
E7: 사용자 및 작업 데이터 통합 관리 시스템 개발
D8: =견적!D19 -> 병렬 프로그램의 실행 상태, 성능 의 실시간 모니터링 기능 제공 | E8: 실시간 병렬 프로그램 실행 상태 추적 기능 개발 | F8: 1 | H8: =Sheet6!B3 -> 22770000 | I8: =H8 -> 22770000
E9: 병렬 프로그램 성능 모니터링 기능 개발
E10: 병렬 프로그램의 다양한 메트릭스를 확인할 수 있는 대시보드 제공 기능 개발
D11: =견적!D20 -> 병렬 분산 처리를 위한 효율적인 라이브러리 구축 및 테스트 | E11: 병렬 분산처리를 지원하는 라이브러리 개발 및 테스트 | F11: 1 | H11: =Sheet6!B4 -> 18630000 | I11: =H11 -> 18630000
E12: 효율적인 병렬 분산처리를 위한 라이브러리 설계 및 검증
E13: 병렬 분산 처리를 위한 고성능 라이브러리 구축 및 테스트 실행
D14: =견적!D21 -> 안정적인 서비스를 위한 에러 및 예외 처리 시스템 구현 | E14: 안정성 확보를 위한 에러 및 예외 상황 대응 시스템 설계 및 구축 | F14: 1 | H14: =Sheet6!B5 -> 22770000 | I14: =H14 -> 22770000
E15: 서비스의 안정성 향상을 위한 에러 및 예외 처리 메커니즘 구현
E16: 신뢰성 있는 서비스 제공을 위한 에러 및 예외 관리 시스템 구축
D17: =견적!D22 -> HPC 시스템에 대한 사용자 인터페이스 및 API 제공 | E17: 사용자 친화적인 HPC 시스템 인터페이스 및 API 설계 및 제공 | F17: 1 | H17: =Sheet6!B6 -> 20700000 | I17: =H17 -> 20700000
E18: HPC 시스템의 접근성 향상을 위한 사용자 인터페이스 및 API 제공
E19: 사용자 대상 HPC 시스템 인터페이스 및 API 개발 및 배포
D20: =견적!D23 -> 시스템의 성능 모니터링 및 리포트 생성 기능 제공 | E20: 시스템 성능 추적 및 보고서 생성 기능 구현 | F20: 1 | H20: =Sheet6!B7 -> 22770000 | I20: =H20 -> 22770000
E21: 정기적인 성능 모니터링 및 리포팅 시스템 개발
E22: 시스템의 성능을 측정하고 분석 리포트를 생성하는 기능 구현 | F22: 1
D23: =견적!D24 -> 병렬 프로그래밍을 위한 개발 환경 구축 | E23: 병렬 프로그래밍 지원을 위한 개발 도구 및 디버깅 툴 제공 | F23: 1 | H23: =Sheet6!B8 -> 16560000 | I23: =H23 -> 16560000
E24: 병렬 코드 작성 및 디버깅을 지원하는 도구 세트 구축
E25: 병렬 프로그래밍 개발 및 디버깅 도구의 설계 및 배포 | F25: 1
D26: =견적!D25 -> HPC 사용자 및 개발자를 위한 사용자 문서 지원 | E26: HPC 활용을 위한 사용자 및 개발자 문서 제공 | F26: 1 | H26: =Sheet6!B9 -> 24840000 | I26: =H26 -> 24840000
E27: HPC 시스템에 대한 사용자 및 개발자 가이드라인 및 지원문서 구축
E28: 사용자와 개발자를 위한 HPC 시스템 설명서 및 도움말 문서 작성 및 배포
D29: =견적!D26 -> 시스템 확장성 및 고가용성을 고려한 인프라 설계 | E29: 확장성과 고가용성을 중심으로 한 시스템 인프라 설계 | F29: 1 | H29: =Sheet6!B10 -> 18630000 | I29: =H29 -> 18630000
E30: 시스템의 확장성 및 고가용성을 보장하는 인프라 구조 설계
E31: 높은 확장성과 안정성을 고려한 시스템 인프라 설계 및 구현
D32: 소 계 | I32: =SUM(I2:I31) -> 207000000

Sheet 2
A1: NO | B1: 품 명 | D1: 규 격 | F1: 수 량 | H1: 단 가 | I1: 금 액
A2: 2 | B2: 인실리코 분석응용 지원을 위한 데이터 분산 처리 시스템 구축 | D2: =견적!D28 -> 대규모 데이터를 효율적으로 처리할 수 있는 분산처리 시스템 구현 | E2: 대용량 데이터 효과적 처리를 위한 분산처리 시스템 구축 | F2: 1 | H2: =Sheet6!D1 -> 24030000 | I2: =H2 -> 24030000
E3: 분산처리 시스템을 이용한 대규모 데이터의 효율적 처리 구현
E4: 대규모 데이터 처리를 위한 고성능 분산처리 시스템 설계 및 구현
D5: =견적!D29 -> 인실리코 분석응용의 필요한 자원별 시스템 자원 동적 할당 관리 시스템 | E5: 인실리코 분석응용에 필요한 자원을 동적으로 할당하는 시스템 구축 | F5: 1 | H5: =Sheet6!D2 -> 24030000 | I5: =H5 -> 24030000
E6: 시스템 자원의 동적 할당 관리를 통한 인실리코 분석응용 지원
E7: 자원별 동적 할당을 위한 시스템 자원 관리 시스템 개발
D8: =견적!D30 -> 사용자 친화적인 인터페이스 및 API 제공 | E8: 사용자 중심 인터페이스와 API 제공 | F8: 1 | H8: =Sheet6!D3 -> 24030000 | I8: =H8 -> 24030000
E9: 사용자 친화적인 UI/UX와 API 설계 및 제공
E10: 사용자 친화적인 인터페이스 및 편리한 API 개발 및 배포
D11: =견적!D31 -> 성능 모니터링 및 최적화 도구 제공 | E11: 시스템 성능 모니터링 및 최적화를 위한 도구 제공 | F11: 1 | H11: =Sheet6!D4 -> 29370000 | I11: =H11 -> 29370000
E12: 성능 모니터링과 최적화 도구의 개발 및 배포
E13: 성능 추적 및 최적화 도구의 설계 및 제공
D14: =견적!D32 -> 데이터 처리 결과의 신속한 전달을 위한 메시징 시스템 구축 | E14: 데이터 처리 결과를 빠르게 전달하는 메시징 시스템 설계 및 구축 | F14: 1 | H14: =Sheet6!D5 -> 21360000 | I14: =H14 -> 21360000
E15: 신속한 데이터 처리 결과 전달을 위한 메시징 시스템 개발
E16: 효율적인 데이터 처리 결과 전달을 위한 메시징 시스템 구현
D17: =견적!D33 -> HPC 산출물 관리 전략 수립 | E17: 데이터의 롤링 및 로테이션 처리 기능 구현 | F17: 1 | H17: =Sheet6!D6 -> 24030000 | I17: =H17 -> 24030000
E18: 데이터 롤링과 로테이션을 지원하는 기능 제공
E19: 데이터 롤링 및 로테이션을 위한 기능 개발 및 제공
D20: =견적!D34 -> HPC 시스템의 안정성을 위한 모니터링 및 알림 시스템 구현 | E20: 안정적인 HPC 시스템 운영을 위한 모니터링 및 알림 시스템 설계 및 구축 | F20: 1 | H20: =Sheet6!D7 -> 24030000 | I20: =H20 -> 24030000
E21: HPC 시스템의 안정성 확보를 위한 모니터링 및 알림 기능 개발
E22: HPC 시스템 안정성을 위한 상시 모니터링 및 알림 시스템 구현 | F22: 1
D23: =견적!D35 -> 분석응용 상태 단계별 프로세싱 보고기능 제공 | E23: 작업 실패 시 자동 재시도 및 오류 복구 기능 개발 | F23: 1 | H23: =Sheet6!D8 -> 24030000 | I23: =H23 -> 24030000
E24: 실패한 작업에 대해 자동 재실행 및 오류 복구 기능 구현
E25: 작업 실패에 대한 자동 재시도 및 오류 복구 메커니즘 구축 | F25: 1
D26: =견적!D36 -> 인실리코 소프트웨어 통합을 위한 확장 가능한 API 설계 | E26: 확장성 있는 API를 통한 인실리코 소프트웨어 통합 설계 | F26: 1 | H26: =Sheet6!D9 -> 21360000 | I26: =H26 -> 21360000
E27: 인실리코 소프트웨어 통합을 위한 확장 가능한 API 개발
E28: 통합 소프트웨어 설계를 위한 확장 가능한 API 구축
D29: =견적!D37 -> 데이터 처리의 효율성을 높이기 위한 최적화 전략 수립 | E29: 데이터 처리 효율 향상을 위한 최적화 전략 개발 | F29: 1 | H29: =Sheet6!D10 -> 26700000 | I29: =H29 -> 26700000
E30: 데이터 처리 효율성 향상을 위한 최적화 전략 구축
E31: 효율적인 데이터 처리를 위한 최적화 전략 설정 및 실행
D32: =견적!D38 -> 인실리코 분석응용 버전 관리 및 업데이트 시스템 구축 | E32: 인실리코 분석응용에 대한 버전 관리 및 업데이트 시스템 설계 및 구축 | F32: 1 | H32: =Sheet6!D11 -> 24030000 | I32: =H32 -> 24030000
E33: 인실리코 분석응용의 버전 관리 및 업데이트를 위한 시스템 개발
E34: 버전 관리 및 업데이트 시스템을 통한 인실리코 분석응용 관리
D35: 소 계 | I35: =SUM(I2:I34) -> 267000000

Sheet 3
A1: NO | B1: 품 명 | D1: 규 격 | F1: 수 량 | H1: 단 가 | I1: 금 액
A2: 3 | B2: 현 시스템 분석 및 전략 수립을 통한 병렬 분산처리 라이브러리 구축 | D2: =견적!D40 -> 시스템의 성능, 자원 사용량, 문제점 등을 분석하는 기능제공 | E2: 시스템 성능, 자원 사용, 문제점 등을 파악하는 분석 기능 구현 | F2: 1 | H2: =Sheet6!F1 -> 14760000 | I2: =H2 -> 14760000
E3: 시스템의 현 상태를 이해하는 데 필요한 성능, 자원 사용량, 문제점 분석 기능
E4: 현재 시스템 상태 분석을 위한 성능, 자원 사용량, 문제점 등의 체크 기능
D5: =견적!D41 -> 병렬 분산처리 라이브러리 구축 전략 수립 | E5: 병렬 분산 처리를 위한 라이브러리 구축을 위한 전략 설정 | F5: 1 | H5: =Sheet6!F2 -> 17220000 | I5: =H5 -> 17220000
E6: 병렬 분산처리 라이브러리 설계 및 구현을 위한 전략 수립
E7: 효율적인 병렬 분산처리 라이브러리 구축을 위한 전략 개발
D8: =견적!D42 -> 병렬 분산처리 자원 시스템 확장을 위한 로드맵 제시 | E8: 시스템 확장 계획을 위한 로드맵 개발 | F8: 1 | H8: =Sheet6!F3 -> 27060000 | I8: =H8 -> 27060000
E9: 미래 시스템 확장을 지원하기 위한 로드맵 구성
E10: 시스템 확장에 대한 장래 로드맵 제공
D11: =견적!D43 -> 병렬 라이브러리에 대한 교육 및 문서 지원 | E11: 라이브러리 사용을 위한 교육자료 및 문서화 작업 제공 | F11: 1 | H11: =Sheet6!F4 -> 19680000 | I11: =H11 -> 19680000
E12: 구축된 라이브러리의 사용자 교육 및 관련 문서 작성
E13: 라이브러리 사용자를 위한 교육 프로그램 및 문서화 실행
D14: =견적!D44 -> 병렬 라이브러리의 안정화를 위한 패키지 업데이트 및 유지보수 계획 수립 | E14: 라이브러리의 안정적 운영을 위한 업데이트 및 유지보수 계획 설정 | F14: 1 | H14: =Sheet6!F5 -> 29520000 | I14: =H14 -> 29520000
E15: 구축된 라이브러리의 안정화를 위해 패키지 업데이트 및 유지보수 전략을 개발
E16: 패키지 업데이트 및 유지보수를 통한 라이브러리 안정성 확보 계획 수립
D17: =견적!D45 -> 병렬 분산 라이브러리의 호환성 및 통합성 검사 기능 제공 | E17: 병렬 분산처리 라이브러리에 대한 호환성 및 통합성 확인 기능 구현 | F17: 1 | H17: =Sheet6!F6 -> 17220000 | I17: =H17 -> 17220000
E18: 라이브러리의 호환성 및 통합성 검사를 위한 기능 제공
E19: 병렬 분산 라이브러리의 호환 및 통합 검사 기능 개발
D20: =견적!D46 -> 분산처리 라이브러리에 대한 성능 벤치마킹 도구 제공 | E20: 라이브러리 성능 평가를 위한 벤치마킹 도구 제공 | F20: 1 | H20: =Sheet6!F7 -> 31980000 | I20: =H20 -> 31980000
E21: 분산처리 라이브러리의 성능을 측정하는 벤치마킹 도구 제공
E22: 성능 벤치마킹 도구를 통한 분산처리 라이브러리 성능 평가 기능 | F22: 1
D23: =견적!D47 -> 사용자 피드백을 통한 라이브러리 개선 절차 수립 | E23: 사용자 피드백 기반 라이브러리 개선 전략 개발 | F23: 1 | H23: =Sheet6!F8 -> 14760000 | I23: =H23 -> 14760000
E24: 사용자 피드백을 이용한 라이브러리의 개선 절차 설정
E25: 사용자 피드백을 활용한 라이브러리의 향상 절차 설계 | F25: 1
D26: =견적!D48 -> 시스템 장애 대응 및 복구 프로세스 구현 | E26: 시스템 오류 대처 및 복구 방법을 위한 프로세스 구축 | F26: 1 | H26: =Sheet6!F9 -> 27060000 | I26: =H26 -> 27060000
E27: 시스템 장애에 대응하고 복구하는 프로세스 설계 및 구현
E28: 시스템 장애 발생 시 대응 및 복구 과정을 위한 프로세스 개발
D29: =견적!D49 -> 라이브러리 사용을 위한 샘플 코드 및 튜토리얼 제공 | E29: 라이브러리 이용자를 위한 샘플 코드 및 튜토리얼 제작 | F29: 1 | H29: =Sheet6!F10 -> 24600000 | I29: =H29 -> 24600000
E30: 라이브러리 사용 방법을 설명하는 샘플 코드 및 튜토리얼 제공
E31: 사용자가 이해하고 사용할 수 있도록 샘플 코드 및 튜토리얼 제작
D32: =견적!D50 -> 운영과 개발 환경 분리 및 지속적인 통합(CI/CD) 프로세스 구축 | E32: 개발과 운영 환경의 분리와 지속적 통합 프로세스 구축 | F32: 1 | H32: =Sheet6!F11 -> 22140000 | I32: =H32 -> 22140000
E33: CI/CD 프로세스를 통해 운영과 개발 환경 분리 및 지속적 통합 시행
E34: 운영과 개발 환경의 분리 및 지속적 통합(CI/CD) 전략을 구현
D35: 소 계 | I35: =SUM(I2:I34) -> 246000000

Sheet Sheet6
A1: 0.1 | B1: =$B$13*A1 -> 20700000 | C1: 0.09 | D1: =$D$13*C1 -> 24030000 | E1: 0.06 | F1: =$F$13*E1 -> 14760000
A2: 0.09 | B2: =$B$13*A2 -> 18630000 | C2: 0.09 | D2: =$D$13*C2 -> 24030000 | E2: 0.07 | F2: =$F$13*E2 -> 17220000
A3: 0.11 | B3: =$B$13*A3 -> 22770000 | C3: 0.09 | D3: =$D$13*C3 -> 24030000 | E3: 0.11 | F3: =$F$13*E3 -> 27060000
A4: 0.09 | B4: =$B$13*A4 -> 18630000 | C4: 0.11 | D4: =$D$13*C4 -> 29370000 | E4: 0.08 | F4: =$F$13*E4 -> 19680000
A5: 0.11 | B5: =$B$13*A5 -> 22770000 | C5: 0.08 | D5: =$D$13*C5 -> 21360000 | E5: 0.12 | F5: =$F$13*E5 -> 29520000
A6: 0.1 | B6: =$B$13*A6 -> 20700000 | C6: 0.09 | D6: =$D$13*C6 -> 24030000 | E6: 0.07 | F6: =$F$13*E6 -> 17220000
A7: 0.11 | B7: =$B$13*A7 -> 22770000 | C7: 0.09 | D7: =$D$13*C7 -> 24030000 | E7: 0.13 | F7: =$F$13*E7 -> 31980000
A8: 0.08 | B8: =$B$13*A8 -> 16560000 | C8: 0.09 | D8: =$D$13*C8 -> 24030000 | E8: 0.06 | F8: =$F$13*E8 -> 14760000
A9: 0.12 | B9: =$B$13*A9 -> 24840000 | C9: 0.08 | D9: =$D$13*C9 -> 21360000 | E9: 0.11 | F9: =$F$13*E9 -> 27060000
A10: 0.09 | B10: =$B$13*A10 -> 18630000 | C10: 0.1 | D10: =$D$13*C10 -> 26700000 | E10: 0.1 | F10: =$F$13*E10 -> 24600000
B11: =$B$13*A11 -> 0 | C11: 0.09 | D11: =$D$13*C11 -> 24030000 | E11: 0.09 | F11: =$F$13*E11 -> 22140000
A12: 비율 | B12: =SUM(A1:A11) -> 1 | D12: =SUM(C1:C11) -> 1 | F12: =SUM(E1:E11) -> 1
A13: 총 값 | B13: 207000000 | D13: 267000000 | F13: 246000000
A15: 더한 값 | B15: =SUM(B1:B11) -> 207000000 | D15: =SUM(D1:D11) -> 267000000 | F15: =SUM(F1:F11) -> 246000000
