Workbook

Sheet 견적
A2: 견 적 서
A4: 받으실분 | C4: (주)씨젠 | E4: 에프에이리눅스 주식회사 오 재 경
C5: 김성조 차장 귀하 | E5: (16006) 경기도 의왕시 포일동 653
A6: T E L | C6: 02-2195-6266 / 010-8682-1192 | E6: 인덕원IT밸리 B동 1001호
A7: F A X | E7: TEL/FAX : 02-572-9527 / 070-7862-5155
A8: 견적일자 | C8: 45078 | E8: 담 당 : 박문식 이사
A9: 견적번호 | C9: PH1-230601001 | E9: 연락처 : 070-7862-5148/010-9429-7998
A10: 유효기간 | C10: 견적일로부터 15일 | E10: E-mail : boggle70@falinux.com
A12: 견 적 명 | D12: 매니코어 기반 고성능 컴퓨터 자원 인프라 병렬처리시스템 라이브러리 통합 환경 구축
A13: 납 기 | D13: 별도 계약서 상의 일정 명시
A14: 합 계 금 액 | D14: =TEXT(H50,"일금 [DBNum4][$-412]G/표준원정(")&TEXT(H50,"###,### - VAT별도 )") -> 일금 칠억이천만원정(720,000,000 - VAT별도 )
D15: =TEXT(H50+(H50/10),"일금 [DBNum4][$-412]G/표준원정(")&TEXT(H50+(H50/10),"###,### - VAT포함 )") -> 일금 칠억구천이백만원정(792,000,000 - VAT포함 )
A16: NO | B16: 품 명 | D16: 규 격 | E16: 수 량 | G16: 단 가 | H16: 금 액
A17: 1 | B17: 고성능 컴퓨팅을 활용한 병렬 프로그래밍 환경 구축 및 안정화 | D17: 로그 데이터 수집, 저장, 검색, 분석 기능 구현 | E17: 1 | G17: =Sheet6!C10 -> 24840000 | H17: =SUM(G17:G18) -> 47196000
D18: 사용자별, 작업별 로그 데이터 관리 기능 제공 | E18: 1 | G18: =Sheet6!C11 -> 22356000
D19: 병렬 프로그램의 실행 상태, 성능 의 실시간 모니터링 기능 제공 | E19: 1 | G19: =Sheet6!C12 -> 22356000 | H19: =SUM(G19:G20) -> 49680000
D20: 병렬 분산 처리를 위한 효율적인 라이브러리 구축 및 테스트 | E20: 1 | G20: =Sheet6!C13 -> 27324000
D21: 분석 응용 프로그램의 에러 및 예외 처리 프로세스 구현 | E21: 1 | G21: =Sheet6!C14 -> 27324000 | H21: =G21 -> 27324000
D22: HPC 시스템에 대한 사용자 인터페이스 및 API 제공 | E22: 1 | G22: =Sheet6!C15 -> 27324000 | H22: =G22 -> 27324000
D23: 시스템의 성능 모니터링 및 리포트 생성 기능 제공 | E23: 1 | G23: =Sheet6!C16 -> 24840000 | H23: =G23 -> 24840000
D24: 병렬 프로그래밍을 위한 개발 환경 구축 | E24: 1 | G24: =Sheet6!C17 -> 29808000 | H24: =G24 -> 29808000
D25: HPC 사용자 및 개발자를 위한 사용자 문서 제작 | E25: 1 | G25: =Sheet6!C18 -> 19872000 | H25: =G25 -> 19872000
D26: 시스템 확장성 및 고가용성을 고려한 인프라 설계 | E26: 1 | G26: =Sheet6!C19 -> 22356000 | H26: =G26 -> 22356000
D27: 소 계 | H27: =SUM(H17:H26) -> 248400000
A28: 2 | B28: 인실리코 분석응용 지원을 위한 데이터 분산처리시스템 구축 | D28: 분석 응용 프로그램 자원 동적 할당 시스템 구축 | E28: 1 | G28: =Sheet6!C22 -> 24948000 | H28: =G28 -> 24948000
D29: 분석 응용 단계별 산출물 관리 | E29: 1 | G29: =Sheet6!C23 -> 27324000 | H29: =G29 -> 27324000
D30: 성능 모니터링 및 최적화 도구 제공 | E30: 1 | G30: =Sheet6!C24 -> 21384000 | H30: =G30 -> 21384000
D31: 바이오 빅데이터 처리 결과 전달을 위한 메시징 시스템 구축 | E31: 1 | G31: =Sheet6!C25 -> 23760000 | H31: =G31 -> 23760000
D32: HPC 산출물 관리 프로세스 구축 | E32: 1 | G32: =Sheet6!C26 -> 26136000 | H32: =G32 -> 26136000
D33: 바이오 빅데이터 처리 시스템 모니터링 및 알람 시스템 구현 | E33: 1 | G33: =Sheet6!C27 -> 20196000 | H33: =G33 -> 20196000
D34: 분석응용 실행 결과 상태 리포팅기능 제공 | E34: 1 | G34: =Sheet6!C28 -> 19008000 | H34: =G34 -> 19008000
D35: 분석응용 산출물 데이터 관리 기능 제공 | E35: 1 | G35: =Sheet6!C29 -> 24948000 | H35: =SUM(G35:G36) -> 51084000
D36: 분석응용 버전 정보 확인 기능 제공 | E36: 1 | G36: =Sheet6!C30 -> 26136000
D37: 인실리코 분석응용 버전 관리 및 업데이트 시스템 구축 | E37: 1 | G37: =Sheet6!C31 -> 23760000 | H37: =G37 -> 23760000
D38: 소 계 | H38: =SUM(H28:H37) -> 237600000
A39: 3 | B39: 고성능 컴퓨팅 시스템 분석을 통한 병렬분산처리 라이브러리 구축 | D39: 병렬 분산처리 라이브러리 버전 리스트 문서 제공 | E39: 1 | G39: =Sheet6!C34 -> 19188000 | H39: =SUM(G39:G40) -> 40014000
D40: 병렬 라이브러리에 대한 교육 및 문서 지원 | E40: 1 | G40: =Sheet6!C35 -> 20826000
D41: 병렬 분산 라이브러리 접근권한 설정 기능 제공 | E41: 1 | G41: =Sheet6!C36 -> 24570000 | H41: =G41 -> 24570000
D42: 병렬 라이브러리 패키지 업데이트 및 유지보수 시스템 구축 | E42: 1 | G42: =Sheet6!C37 -> 24336000 | H42: =G42 -> 24336000
D43: 분산처리 라이브러리에 대한 성능 벤치마킹 도구 제공 | E43: 1 | G43: =Sheet6!C38 -> 24804000 | H43: =G43 -> 24804000
...

Sheet 1
A1: NO | B1: 품 명 | D1: 규 격 | F1: 수 량 | H1: 단 가 | I1: 금 액
A2: 1 | B2: 고성능 컴퓨팅(HPC) 및 병렬 프로그래밍 환경 구축 및 안정화 | D2: =견적!D17 -> 로그 데이터 수집, 저장, 검색, 분석 기능 구현 | E2: HPC 로그 데이터 수집기 개발 | F2: 1 | H2: =견적!G17 -> 24840000 | I2: =H2 -> 24840000
E3: HPC 로그 데이터 분석기 개발
E4: HPC 로그 데이트 검색기 개발
D5: =견적!D18 -> 사용자별, 작업별 로그 데이터 관리 기능 제공 | E5: 사용자 로그 데이터 관리 시스템 개발 | F5: 1 | H5: =견적!G18 -> 22356000 | I5: =H5 -> 22356000
E6: 작업별 로그 데이터 관리 시스템 개발
E7: 사용자 및 작업 데이터 통합 관리 시스템 개발
D8: =견적!D19 -> 병렬 프로그램의 실행 상태, 성능 의 실시간 모니터링 기능 제공 | E8: 실시간 병렬 프로그램 실행 상태 추적 기능 개발 | F8: 1 | H8: =견적!G19 -> 22356000 | I8: =H8 -> 22356000
E9: 병렬 프로그램 성능 모니터링 기능 개발
E10: 병렬 프로그램의 다양한 메트릭스를 확인할 수 있는 대시보드 제공 기능 개발
D11: =견적!D20 -> 병렬 분산 처리를 위한 효율적인 라이브러리 구축 및 테스트 | E11: 병렬 분산처리를 지원하는 라이브러리 개발 및 테스트 | F11: 1 | H11: =견적!G20 -> 27324000 | I11: =H11 -> 27324000
E12: 효율적인 병렬 분산처리를 위한 라이브러리 설계 및 검증
E13: 병렬 분산 처리를 위한 고성능 라이브러리 구축 및 테스트 실행
D14: =견적!D21 -> 분석 응용 프로그램의 에러 및 예외 처리 프로세스 구현 | E14: 안정성 확보를 위한 에러 및 예외 상황 대응 시스템 설계 및 구축 | F14: 1 | H14: =견적!G21 -> 27324000 | I14: =H14 -> 27324000
E15: 서비스의 안정성 향상을 위한 에러 및 예외 처리 메커니즘 구현
E16: 신뢰성 있는 서비스 제공을 위한 에러 및 예외 관리 시스템 구축
D17: =견적!D22 -> HPC 시스템에 대한 사용자 인터페이스 및 API 제공 | E17: 사용자 친화적인 HPC 시스템 인터페이스 및 API 설계 및 제공 | F17: 1 | H17: =견적!G22 -> 27324000 | I17: =H17 -> 27324000
E18: HPC 시스템의 접근성 향상을 위한 사용자 인터페이스 및 API 제공
E19: 사용자 대상 HPC 시스템 인터페이스 및 API 개발 및 배포
D20: =견적!D23 -> 시스템의 성능 모니터링 및 리포트 생성 기능 제공 | E20: 시스템 성능 추적 및 보고서 생성 기능 구현 | F20: 1 | H20: =견적!G23 -> 24840000 | I20: =H20 -> 24840000
E21: 정기적인 성능 모니터링 및 리포팅 시스템 개발
E22: 시스템의 성능을 측정하고 분석 리포트를 생성하는 기능 구현 | F22: 1
D23: =견적!D24 -> 병렬 프로그래밍을 위한 개발 환경 구축 | E23: 병렬 프로그래밍 지원을 위한 개발 도구 및 디버깅 툴 제공 | F23: 1 | H23: =견적!G24 -> 29808000 | I23: =H23 -> 29808000
E24: 병렬 코드 작성 및 디버깅을 지원하는 도구 세트 구축
E25: 병렬 프로그래밍 개발 및 디버깅 도구의 설계 및 배포 | F25: 1
D26: =견적!D25 -> HPC 사용자 및 개발자를 위한 사용자 문서 제작 | E26: HPC 활용을 위한 사용자 및 개발자 문서 제공 | F26: 1 | H26: =견적!G25 -> 19872000 | I26: =H26 -> 19872000
E27: HPC 시스템에 대한 사용자 및 개발자 가이드라인 및 지원문서 구축
E28: 사용자와 개발자를 위한 HPC 시스템 설명서 및 도움말 문서 작성 및 배포
D29: =견적!D26 -> 시스템 확장성 및 고가용성을 고려한 인프라 설계 | E29: 확장성과 고가용성을 중심으로 한 시스템 인프라 설계 | F29: 1 | H29: =견적!G26 -> 22356000 | I29: =H29 -> 22356000
E30: 시스템의 확장성 및 고가용성을 보장하는 인프라 구조 설계
E31: 높은 확장성과 안정성을 고려한 시스템 인프라 설계 및 구현
D32: 소 계 | I32: =SUM(I2:I31) -> 248400000

Sheet 2
A1: NO | B1: 품 명 | D1: 규 격 | F1: 수 량 | H1: 단 가 | I1: 금 액
A2: 2 | B2: 인실리코 분석응용 지원을 위한 데이터 분산 처리 시스템 구축 | D2: =견적!D28 -> 분석 응용 프로그램 자원 동적 할당 시스템 구축 | E2: 대용량 데이터 효과적 처리를 위한 분산처리 시스템 구축 | F2: 1 | H2: =견적!G28 -> 24948000 | I2: =H2 -> 24948000
E3: 분산처리 시스템을 이용한 대규모 데이터의 효율적 처리 구현
E4: 대규모 데이터 처리를 위한 고성능 분산처리 시스템 설계 및 구현
D5: =견적!D29 -> 분석 응용 단계별 산출물 관리 | E5: 인실리코 분석응용에 필요한 자원을 동적으로 할당하는 시스템 구축 | F5: 1 | H5: =견적!G29 -> 27324000 | I5: =H5 -> 27324000
E6: 시스템 자원의 동적 할당 관리를 통한 인실리코 분석응용 지원
E7: 자원별 동적 할당을 위한 시스템 자원 관리 시스템 개발
D8: =견적!D30 -> 성능 모니터링 및 최적화 도구 제공 | E8: 사용자 중심 인터페이스와 API 제공 | F8: 1 | H8: =견적!G30 -> 21384000 | I8: =H8 -> 21384000
E9: 사용자 친화적인 UI/UX와 API 설계 및 제공
E10: 사용자 친화적인 인터페이스 및 편리한 API 개발 및 배포
D11: =견적!D31 -> 바이오 빅데이터 처리 결과 전달을 위한 메시징 시스템 구축 | E11: 시스템 성능 모니터링 및 최적화를 위한 도구 제공 | F11: 1 | H11: =견적!G31 -> 23760000 | I11: =H11 -> 23760000
E12: 성능 모니터링과 최적화 도구의 개발 및 배포
E13: 성능 추적 및 최적화 도구의 설계 및 제공
D14: =견적!D32 -> HPC 산출물 관리 프로세스 구축 | E14: 데이터 처리 결과를 빠르게 전달하는 메시징 시스템 설계 및 구축 | F14: 1 | H14: =견적!G32 -> 26136000 | I14: =H14 -> 26136000
E15: 신속한 데이터 처리 결과 전달을 위한 메시징 시스템 개발
E16: 효율적인 데이터 처리 결과 전달을 위한 메시징 시스템 구현
D17: =견적!D33 -> 바이오 빅데이터 처리 시스템 모니터링 및 알람 시스템 구현 | E17: 데이터의 롤링 및 로테이션 처리 기능 구현 | F17: 1 | H17: =견적!G33 -> 20196000 | I17: =H17 -> 20196000
E18: 데이터 롤링과 로테이션을 지원하는 기능 제공
E19: 데이터 롤링 및 로테이션을 위한 기능 개발 및 제공
D20: =견적!D34 -> 분석응용 실행 결과 상태 리포팅기능 제공 | E20: 안정적인 HPC 시스템 운영을 위한 모니터링 및 알림 시스템 설계 및 구축 | F20: 1 | H20: =견적!G34 -> 19008000 | I20: =H20 -> 19008000
E21: HPC 시스템의 안정성 확보를 위한 모니터링 및 알림 기능 개발
E22: HPC 시스템 안정성을 위한 상시 모니터링 및 알림 시스템 구현 | F22: 1
D23: =견적!D35 -> 분석응용 산출물 데이터 관리 기능 제공 | E23: 작업 실패 시 자동 재시도 및 오류 복구 기능 개발 | F23: 1 | H23: =견적!G35 -> 24948000 | I23: =H23 -> 24948000
E24: 실패한 작업에 대해 자동 재실행 및 오류 복구 기능 구현
E25: 작업 실패에 대한 자동 재시도 및 오류 복구 메커니즘 구축 | F25: 1
D26: =견적!D36 -> 분석응용 버전 정보 확인 기능 제공 | E26: 확장성 있는 API를 통한 인실리코 소프트웨어 통합 설계 | F26: 1 | H26: =견적!G36 -> 26136000 | I26: =H26 -> 26136000
E27: 인실리코 소프트웨어 통합을 위한 확장 가능한 API 개발
E28: 통합 소프트웨어 설계를 위한 확장 가능한 API 구축
D29: =견적!D37 -> 인실리코 분석응용 버전 관리 및 업데이트 시스템 구축 | E29: 데이터 처리 효율 향상을 위한 최적화 전략 개발 | F29: 1 | H29: =견적!G37 -> 23760000 | I29: =H29 -> 23760000
E30: 데이터 처리 효율성 향상을 위한 최적화 전략 구축
E31: 효율적인 데이터 처리를 위한 최적화 전략 설정 및 실행
D32: 소 계 | I32: =SUM(I2:I31) -> 237600000

Sheet 3
A1: NO | B1: 품 명 | D1: 규 격 | F1: 수 량 | H1: 단 가 | I1: 금 액
A2: 3 | B2: 현 시스템 분석 및 전략 수립을 통한 병렬 분산처리 라이브러리 구축 | D2: =견적!D39 -> 병렬 분산처리 라이브러리 버전 리스트 문서 제공 | E2: 시스템 성능, 자원 사용, 문제점 등을 파악하는 분석 기능 구현 | F2: 1 | H2: =견적!G39 -> 19188000 | I2: =H2 -> 19188000
E3: 시스템의 현 상태를 이해하는 데 필요한 성능, 자원 사용량, 문제점 분석 기능
E4: 현재 시스템 상태 분석을 위한 성능, 자원 사용량, 문제점 등의 체크 기능
D5: =견적!D40 -> 병렬 라이브러리에 대한 교육 및 문서 지원 | E5: 병렬 분산 처리를 위한 라이브러리 구축을 위한 전략 설정 | F5: 1 | H5: =견적!G40 -> 20826000 | I5: =H5 -> 20826000
E6: 병렬 분산처리 라이브러리 설계 및 구현을 위한 전략 수립
E7: 효율적인 병렬 분산처리 라이브러리 구축을 위한 전략 개발
D8: =견적!D41 -> 병렬 분산 라이브러리 접근권한 설정 기능 제공 | E8: 시스템 확장 계획을 위한 로드맵 개발 | F8: 1 | H8: =견적!G41 -> 24570000 | I8: =H8 -> 24570000
E9: 미래 시스템 확장을 지원하기 위한 로드맵 구성
E10: 시스템 확장에 대한 장래 로드맵 제공
D11: =견적!D42 -> 병렬 라이브러리 패키지 업데이트 및 유지보수 시스템 구축 | E11: 라이브러리 사용을 위한 교육자료 및 문서화 작업 제공 | F11: 1 | H11: =견적!G42 -> 24336000 | I11: =H11 -> 24336000
E12: 구축된 라이브러리의 사용자 교육 및 관련 문서 작성
E13: 라이브러리 사용자를 위한 교육 프로그램 및 문서화 실행
D14: =견적!D43 -> 분산처리 라이브러리에 대한 성능 벤치마킹 도구 제공 | E14: 라이브러리의 안정적 운영을 위한 업데이트 및 유지보수 계획 설정 | F14: 1 | H14: =견적!G43 -> 24804000 | I14: =H14 -> 24804000
E15: 구축된 라이브러리의 안정화를 위해 패키지 업데이트 및 유지보수 전략을 개발
E16: 패키지 업데이트 및 유지보수를 통한 라이브러리 안정성 확보 계획 수립
D17: =견적!D44 -> 분산처리 라이브러리 사용자 인터뷰를 통한 요구사항 적용 | E17: 병렬 분산처리 라이브러리에 대한 호환성 및 통합성 확인 기능 구현 | F17: 1 | H17: =견적!G44 -> 21060000 | I17: =H17 -> 21060000
E18: 라이브러리의 호환성 및 통합성 검사를 위한 기능 제공
E19: 병렬 분산 라이브러리의 호환 및 통합 검사 기능 개발
D20: =견적!D45 -> 별령 분산처리 운영 환경_x0008_및 개발 환경 구축 | E20: 라이브러리 성능 평가를 위한 벤치마킹 도구 제공 | F20: 1 | H20: =견적!G45 -> 25038000 | I20: =H20 -> 25038000
E21: 분산처리 라이브러리의 성능을 측정하는 벤치마킹 도구 제공
E22: 성능 벤치마킹 도구를 통한 분산처리 라이브러리 성능 평가 기능 | F22: 1
D23: =견적!D46 -> 병렬 라이브러리 사용을 위한 샘플 코드 및 튜토리얼 제공 | E23: 사용자 피드백 기반 라이브러리 개선 전략 개발 | F23: 1 | H23: =견적!G46 -> 25506000 | I23: =H23 -> 25506000
E24: 사용자 피드백을 이용한 라이브러리의 개선 절차 설정
E25: 사용자 피드백을 활용한 라이브러리의 향상 절차 설계 | F25: 1
D26: =견적!D47 -> 지속적인 통합배포 프로세스 구축 | E26: 시스템 오류 대처 및 복구 방법을 위한 프로세스 구축 | F26: 1 | H26: =견적!G47 -> 24102000 | I26: =H26 -> 24102000
E27: 시스템 장애에 대응하고 복구하는 프로세스 설계 및 구현
E28: 시스템 장애 발생 시 대응 및 복구 과정을 위한 프로세스 개발
D29: =견적!D48 -> 병렬 컴퓨팅 하드웨어 자원 추가 프로세스 구축 | E29: 라이브러리 이용자를 위한 샘플 코드 및 튜토리얼 제작 | F29: 1 | H29: =견적!G48 -> 24570000 | I29: =H29 -> 24570000
E30: 라이브러리 사용 방법을 설명하는 샘플 코드 및 튜토리얼 제공
E31: 사용자가 이해하고 사용할 수 있도록 샘플 코드 및 튜토리얼 제작
D32: 소 계 | I32: =SUM(I2:I31) -> 234000000

Sheet Sheet6
A1: 총 견적 | B1: 720000000
A3: 대제목당 비율 | B3: 대제목 | C3: 가격
A4: 0.345 | B4: =견적!B17 -> 고성능 컴퓨팅을 활용한 병렬 프로그래밍 환경 구축 및 안정화 | C4: =B1*A4 -> 2.484e+08
A5: 0.33 | B5: =견적!B28 -> 인실리코 분석응용 지원을 위한 데이터 분산처리시스템 구축 | C5: =B1*A5 -> 237600000
A6: 0.325 | B6: =견적!B39 -> 고성능 컴퓨팅 시스템 분석을 통한 병렬분산처리 라이브러리 구축 | C6: =B1*A6 -> 234000000
A7: 총 비율 | B7: =SUM(A4:A6) -> 1
A9: 요구사항당 비율 | B9: 요구사항 | C9: 가격
A10: 0.1 | B10: =견적!D17 -> 로그 데이터 수집, 저장, 검색, 분석 기능 구현 | C10: =$C$4*A10 -> 24840000
A11: 0.09 | B11: =견적!D18 -> 사용자별, 작업별 로그 데이터 관리 기능 제공 | C11: =$C$4*A11 -> 22356000
A12: 0.09 | B12: =견적!D19 -> 병렬 프로그램의 실행 상태, 성능 의 실시간 모니터링 기능 제공 | C12: =$C$4*A12 -> 22356000
A13: 0.11 | B13: =견적!D20 -> 병렬 분산 처리를 위한 효율적인 라이브러리 구축 및 테스트 | C13: =$C$4*A13 -> 27324000
A14: 0.11 | B14: =견적!D21 -> 분석 응용 프로그램의 에러 및 예외 처리 프로세스 구현 | C14: =$C$4*A14 -> 27324000
A15: 0.11 | B15: =견적!D22 -> HPC 시스템에 대한 사용자 인터페이스 및 API 제공 | C15: =$C$4*A15 -> 27324000
A16: 0.1 | B16: =견적!D23 -> 시스템의 성능 모니터링 및 리포트 생성 기능 제공 | C16: =$C$4*A16 -> 24840000
A17: 0.12 | B17: =견적!D24 -> 병렬 프로그래밍을 위한 개발 환경 구축 | C17: =$C$4*A17 -> 29808000
A18: 0.08 | B18: =견적!D25 -> HPC 사용자 및 개발자를 위한 사용자 문서 제작 | C18: =$C$4*A18 -> 19872000
A19: 0.09 | B19: =견적!D26 -> 시스템 확장성 및 고가용성을 고려한 인프라 설계 | C19: =$C$4*A19 -> 22356000
A20: =SUM(A10:A19) -> 1 | B20: 합계 | C20: =SUM(C10:C19) -> 248400000
A22: 0.105 | B22: =견적!D28 -> 분석 응용 프로그램 자원 동적 할당 시스템 구축 | C22: =$C$5*A22 -> 24948000
A23: 0.115 | B23: =견적!D29 -> 분석 응용 단계별 산출물 관리 | C23: =$C$5*A23 -> 27324000
A24: 0.09 | B24: =견적!D30 -> 성능 모니터링 및 최적화 도구 제공 | C24: =$C$5*A24 -> 21384000
A25: 0.1 | B25: =견적!D31 -> 바이오 빅데이터 처리 결과 전달을 위한 메시징 시스템 구축 | C25: =$C$5*A25 -> 23760000
A26: 0.11 | B26: =견적!D32 -> HPC 산출물 관리 프로세스 구축 | C26: =$C$5*A26 -> 26136000
A27: 0.085 | B27: =견적!D33 -> 바이오 빅데이터 처리 시스템 모니터링 및 알람 시스템 구현 | C27: =$C$5*A27 -> 20196000
A28: 0.08 | B28: =견적!D34 -> 분석응용 실행 결과 상태 리포팅기능 제공 | C28: =$C$5*A28 -> 19008000
A29: 0.105 | B29: =견적!D35 -> 분석응용 산출물 데이터 관리 기능 제공 | C29: =$C$5*A29 -> 24948000
A30: 0.11 | B30: =견적!D36 -> 분석응용 버전 정보 확인 기능 제공 | C30: =$C$5*A30 -> 26136000
A31: 0.1 | B31: =견적!D37 -> 인실리코 분석응용 버전 관리 및 업데이트 시스템 구축 | C31: =$C$5*A31 -> 23760000
A32: =SUM(A22:A31) -> 1 | B32: 합계 | C32: =SUM(C22:C31) -> 237600000
A34: 0.082 | B34: =견적!D39 -> 병렬 분산처리 라이브러리 버전 리스트 문서 제공 | C34: =$C$6*A34 -> 19188000
A35: 0.089 | B35: =견적!D40 -> 병렬 라이브러리에 대한 교육 및 문서 지원 | C35: =$C$6*A35 -> 20826000
A36: 0.105 | B36: =견적!D41 -> 병렬 분산 라이브러리 접근권한 설정 기능 제공 | C36: =$C$6*A36 -> 24570000
A37: 0.104 | B37: =견적!D42 -> 병렬 라이브러리 패키지 업데이트 및 유지보수 시스템 구축 | C37: =$C$6*A37 -> 24336000
A38: 0.106 | B38: =견적!D43 -> 분산처리 라이브러리에 대한 성능 벤치마킹 도구 제공 | C38: =$C$6*A38 -> 24804000
A39: 0.09 | B39: =견적!D44 -> 분산처리 라이브러리 사용자 인터뷰를 통한 요구사항 적용 | C39: =$C$6*A39 -> 21060000
A40: 0.107 | B40: =견적!D45 -> 별령 분산처리 운영 환경_x0008_및 개발 환경 구축 | C40: =$C$6*A40 -> 25038000
A41: 0.109 | B41: =견적!D46 -> 병렬 라이브러리 사용을 위한 샘플 코드 및 튜토리얼 제공 | C41: =$C$6*A41 -> 25506000
A42: 0.103 | B42: =견적!D47 -> 지속적인 통합배포 프로세스 구축 | C42: =$C$6*A42 -> 24102000
A43: 0.105 | B43: =견적!D48 -> 병렬 컴퓨팅 하드웨어 자원 추가 프로세스 구축 | C43: =$C$6*A43 -> 24570000
A44: =SUM(A34:A43) -> 1 | B44: 합계 | C44: =SUM(C34:C43) -> 234000000
...
