Workbook

Sheet 총괄(사업자번호 입력)
C2: 노란색 칸은 꼭 입력 해주시기 바랍니다 | F2: 사업자번호(- 제외, 숫자만 입력) | G2: 7228602927 | I2: 노란색 입력 필요
B4: 과제번호 | C4: =IFERROR(VLOOKUP(G2,Sheet2!$A$2:$G$556,2,0),"자동입력") -> RS-2024-00443036 | E4: 주관연구개발기관명 | F4: =IFERROR(VLOOKUP(G2,Sheet2!$A$2:$G$556,3,0),"자동입력") -> 젝사젠 주식회사
B5: 집체협약 일정 | C5: =IFERROR(VLOOKUP(G2,Sheet2!$A$2:$G$556,4,0),"자동입력") -> 2024-08-22(목) 10:00 | E5: 확정 정부지원금 (천원) | F5: =IFERROR(VLOOKUP(G2,Sheet2!$A$2:$G$556,7,0),"자동입력") -> 120000
B7: 0. 연구개발비 구성 | E7: 정부출연금, 기관부담금 비율은 7.5:2.5 | H7: 기관부담금 현물, 현금 비율은 9:1까지 가능함.
M8: (단위:천원)
B9: 차수 | C9: 정부지원연구개발비(천원) | E9: 기관부담연구개발비(천원) | I9: 소 계 | M9: 합계
C10: 현금 | D10: 비율 | E10: 현금 | F10: 비율 | G10: 현물 | H10: 기관부담금 합계 | I10: 현금 | J10: 비율 | K10: 현물 | L10: 비율
B11: 1차년도 | C11: =C13/2 -> 60000 | D11: =IFERROR(C11/M11*100,"") -> 75 | E11: =E13/2 -> 2000 | F11: =IFERROR(E11/(E11+G11)*100,"") -> 10 | G11: =G13/2 -> 18000 | H11: =E11+G11 -> 20000 | I11: =C11+E11 -> 62000 | J11: =IFERROR(I11/M11,"") -> 0.775 | K11: =G11 -> 18000 | L11: =IFERROR(K11/M11,"") -> 0.225 | M11: =I11+K11 -> 80000
B12: 2차년도 | C12: =C13/2 -> 60000 | D12: =IFERROR(C12/M12*100,"") -> 75 | E12: =E13/2 -> 2000 | F12: =IFERROR(E12/(E12+G12)*100,"") -> 10 | G12: =G13/2 -> 18000 | H12: =E12+G12 -> 20000 | I12: =C12+E12 -> 62000 | J12: =IFERROR(I12/M12,"") -> 0.775 | K12: =G12 -> 18000 | L12: =IFERROR(K12/M12,"") -> 0.225 | M12: =I12+K12 -> 80000
B13: 합계 | C13: =F5 -> 120000 | D13: =IFERROR(C13/M13*100,"") -> 75 | E13: =ROUNDUP(C13/3*0.1,0) -> 4000 | F13: =IFERROR(E13/(E13+G13)*100,"") -> 10 | G13: =C13/3*0.9 -> 36000 | H13: =E13+G13 -> 40000 | I13: =C13+E13 -> 124000 | J13: =IFERROR(I13/M13,"") -> 0.775 | K13: =G13 -> 36000 | L13: =IFERROR(K13/M13,"") -> 0.225 | M13: =I13+K13 -> 160000
F14: =IFERROR((E13+G13)/M13,"") -> 0.25 | G14: =IF(F13>=10,"적절","부적절") -> 적절 | H14: =IF(((E13+G13)/(C13+E13+G13))<0.25,"기관부담연구개발비 부족","적절") -> 적절

Sheet 1차년도
H1: 노란색 입력 필요
B2: 1차년도 연구개발비 구성
M3: (단위:천원)
B4: 차수 | C4: 정부지원연구개발비(천원) | E4: 기관부담연구개발비(천원) | I4: 소 계 | M4: 합계 | P4: ★3-1 인건비 작성여부★(엑셀 오른쪽에 있습니다.)
C5: 현금 | D5: 비율 | E5: 현금 | F5: 비율 | G5: 현물 | H5: 기관부담금 합계 | I5: 현금 | J5: 비율 | K5: 현물 | L5: 비율
B6: 1 | C6: ='총괄(사업자번호 입력)'!C11 -> 60000 | D6: =IFERROR(C6/M6*100,"") -> 75 | E6: =ROUNDUP(C6/3*0.1,0) -> 2000 | F6: =IFERROR(E6/(E6+G6)*100,"") -> 10 | G6: =C6/3*0.9 -> 18000 | H6: =E6+G6 -> 20000 | I6: =C6+E6 -> 62000 | J6: =IFERROR(I6/M6,"") -> 0.775 | K6: =G6 -> 18000 | L6: =IFERROR(K6/M6,"") -> 0.225 | M6: =I6+K6 -> 80000
F7: =IFERROR((E6+G6)/M6,"") -> 0.25 | G7: =IF(F6>=10,"적절","부적절") -> 적절 | H7: =IF(((E6+G6)/(C6+E6+G6))<0.2,"기관부담연구개발비 부족","적절") -> 적절
B12: 1. 연구개발비 분담내역(작성필요) | D12: *공동, 위탁은 있는 경우만 작성
J13: (단위:천원)
B14: 차수 | C14: 구분 | D14: 기관명 | E14: 정부지원연구개발비 | F14: 기관부담연구개발비 | I14: 총연구개발비 | J14: 검증결과 (적절, 부적절)
E15: 현금 | F15: 현금 | G15: 현물 | H15: 계
B16: 1 | C16: 주관연구개발기관 | D16: ='총괄(사업자번호 입력)'!F4 -> 젝사젠 주식회사 | E16: 60000 | F16: 2000 | G16: 18000 | H16: =SUM(F16:G16) -> 20000 | I16: =H16+E16 -> 80000 | J16: =IF(COUNTBLANK(D16)=1,"적절",IF(I16=L86,"적절","부적절")) -> 적절
B17: 1 | C17: 공동연구개발기관(1) | H17: =SUM(F17:G17) -> 0 | I17: =H17+E17 -> 0 | J17: =IF(COUNTBLANK(D17)=1,"적절",IF(I17=L111,"적절","부적절")) -> 적절
B18: 1 | C18: 공동연구개발기관(2) | H18: =SUM(F18:G18) -> 0 | I18: =H18+E18 -> 0 | J18: =IF(COUNTBLANK(D18)=1,"적절",IF(I18=L136,"적절","부적절")) -> 적절
B19: 1 | C19: 위탁연구개발기관(1) | H19: =SUM(F19:G19) -> 0 | I19: =H19+E19 -> 0 | J19: =IF(COUNTBLANK(D19)=1,"적절",IF(I19=L162,"적절","부적절")) -> 적절
B20: 1 | C20: 위탁연구개발기관(2) | H20: =SUM(F20:G20) -> 0 | I20: =H20+E20 -> 0 | J20: =IF(COUNTBLANK(D20)=1,"적절",IF(I20=L188,"적절","부적절")) -> 적절
B21: 합계 | E21: =SUM(E16:E19) -> 60000 | F21: =SUM(F16:F19) -> 2000 | G21: =SUM(G16:G19) -> 18000 | H21: =SUM(F21:G21) -> 20000 | I21: =SUM(I16:I19) -> 80000 | J21: =IF(I21=L54,"적절","부적절") -> 적절
E22: =IF(E21=C6,"적절","부적절") -> 적절 | F22: =IF(F21=E6,"적절","부적절") -> 적절 | G22: =IF(G21=G6,"적절","부적절") -> 적절
B24: 2. 연구개발비(총괄-자동반영), 직접 입력 금지
M25: (단위:천원)
B26: 차수 | C26: 구분 | D26: 과제번호 | E26: 구 분 | F26: 비목 | H26: 현금 | J26: 현물 | L26: 총계 | N26: 주요 검토결과 (적절, 부적절)
H27: 현금(천원) (A) | I27: 비율 (A/C) | J27: 현물(천원) (B) | K27: 비율 (B/C) | L27: 소계(천원) (C) | M27: 총연구개발비대비 비율
B28: 1 | C28: 총 연구개발비 | D28: ='총괄(사업자번호 입력)'!C4:D4 -> 0 | E28: 직접비 | F28: 인건비 | G28: 기존인력인건비 | H28: =H61+H90+H115 -> 7500 | I28: =IFERROR(H28/L28,"") -> 0.29411765 | J28: =J61+J90+J115 -> 18000 | K28: =IFERROR(J28/L28,"") -> 0.70588235 | L28: =H28+J28 -> 25500 | M28: =IFERROR(L28/$L$54,"") -> 0.31875
G29: 신규인력인건비 | H29: =H62+H91+H116 -> 43333 | I29: =IFERROR(H29/L29,"") -> 1 | J29: =J62+J91+J116 -> 0 | K29: =IFERROR(J29/L29,"") -> 0 | L29: =H29+J29 -> 43333 | M29: =IFERROR(L29/$L$54,"") -> 0.5416625
G30: 외부인건비 | H30: =H63+H92+H117 -> 0 | I30: =IFERROR(H30/L30,"") | J30: =J63+J92+J117 -> 0 | K30: =IFERROR(J30/L30,"") | L30: =H30+J30 -> 0 | M30: =IFERROR(L30/$L$54,"") -> 0
F31: 인건비 소계 | H31: =H28+H29+H30 -> 50833 | I31: =IFERROR(H31/L31,"") -> 0.73849752 | J31: =SUM(J28:J30) -> 18000 | K31: =IFERROR(J31/L31,"") -> 0.26150248 | L31: =H31+J31 -> 68833 | M31: =IFERROR(L31/$L$54,"") -> 0.8604125
F32: 연구시설·장비비 | H32: =H65+H94+H119 -> 0 | I32: =IFERROR(H32/L32,"") | J32: =J65+J94+J119 -> 0 | K32: =IFERROR(J32/L32,"") | L32: =H32+J32 -> 0 | M32: =IFERROR(L32/$L$54,"") -> 0
F33: 연구재료비 | H33: =H66+H95+H120 -> 0 | I33: =IFERROR(H33/L33,"") | J33: =J66+J95+J120 -> 0 | K33: =IFERROR(J33/L33,"") | L33: =H33+J33 -> 0 | M33: =IFERROR(L33/$L$54,"") -> 0
F34: 연구활동비 | G34: 지식재산 창출활동비 | H34: =H67+H96+H121 -> 0 | I34: =IFERROR(H34/L34,"") | L34: =H34+J34 -> 0 | M34: =IFERROR(L34/$L$54,"") -> 0
G35: 외부 전문기술 활용비 | H35: =H68+H97+H122 -> 600 | I35: =IFERROR(H35/L35,"") -> 1 | L35: =H35+J35 -> 600 | M35: =IFERROR(L35/$L$54,"") -> 0.0075 | N35: =IFERROR(L35/L49,"") -> 0.0076726343 | O35: =IF(N35<0.4,"적절","부적절") -> 적절
G36: 회의비 | H36: =H69+H98+H123 -> 1000 | I36: =IFERROR(H36/L36,"") -> 1 | L36: =H36+J36 -> 1000 | M36: =IFERROR(L36/$L$54,"") -> 0.0125
G37: 출장비 | H37: =H70+H99+H124 -> 0 | I37: =IFERROR(H37/L37,"") | L37: =H37+J37 -> 0 | M37: =IFERROR(L37/$L$54,"") -> 0
G38: 클라우드컴퓨팅 서비스 활용비 | H38: =H71+H100+H125 -> 3000 | I38: =IFERROR(H38/L38,"") -> 1 | L38: =H38+J38 -> 3000 | M38: =IFERROR(L38/$L$54,"") -> 0.0375
G39: 소프트웨어 활용비 | H39: =H72+H101+H126 -> 0 | I39: =IFERROR(H39/L39,"") | L39: =H39+J39 -> 0 | M39: =IFERROR(L39/$L$54,"") -> 0
G40: 연구실운영비 | H40: =H73+H102+H127 -> 0 | I40: =IFERROR(H40/L40,"") | L40: =H40+J40 -> 0 | M40: =IFERROR(L40/$L$54,"") -> 0
G41: 연구인력 지원비 | H41: =H74+H103+H128 -> 0 | I41: =IFERROR(H41/L41,"") | L41: =H41+J41 -> 0 | M41: =IFERROR(L41/$L$54,"") -> 0
G42: 그 밖의 비용 | H42: =H76+H104+H129+H75 -> 267 | I42: =IFERROR(H42/L42,"") -> 1 | L42: =H42+J42 -> 267 | M42: =IFERROR(L42/$L$54,"") -> 0.0033375
F43: 연구활동비 소계 | H43: =SUM(H34:H42) -> 4867 | I43: =IFERROR(H43/L43,"") -> 1 | L43: =H43+J43 -> 4867 | M43: =IFERROR(L43/$L$54,"") -> 0.0608375
F44: 연구수당 | H44: =H78+H105+H130 -> 4500 | I44: =IFERROR(H44/L44,"") -> 1 | L44: =H44+J44 -> 4500 | M44: =IFERROR(L44/$L$54,"") -> 0.05625
F45: 위탁연구개발비 | G45: 직접비(인건비) | H45: =H144+H170 -> 0 | I45: =IFERROR(H45/L45,"") | L45: =H45+J45 -> 0 | M45: =IFERROR(L45/$L$54,"") -> 0
...

Sheet 2차년도
H1: 노란색 입력 필요
B2: 2차년도 연구개발비 구성
M3: (단위:천원)
B4: 차수 | C4: 정부지원연구개발비(천원) | E4: 기관부담연구개발비(천원) | I4: 소 계 | M4: 합계
C5: 현금 | D5: 비율 | E5: 현금 | F5: 비율 | G5: 현물 | H5: 기관부담금 합계 | I5: 현금 | J5: 비율 | K5: 현물 | L5: 비율
B6: 1 | C6: ='총괄(사업자번호 입력)'!C12 -> 60000 | D6: =IFERROR(C6/M6*100,"") -> 75 | E6: =ROUNDUP(C6/3*0.1,0) -> 2000 | F6: =IFERROR(E6/(E6+G6)*100,"") -> 10 | G6: =C6/3*0.9 -> 18000 | H6: =E6+G6 -> 20000 | I6: =C6+E6 -> 62000 | J6: =IFERROR(I6/M6,"") -> 0.775 | K6: =G6 -> 18000 | L6: =IFERROR(K6/M6,"") -> 0.225 | M6: =I6+K6 -> 80000
F7: =IFERROR((E6+G6)/M6,"") -> 0.25 | G7: =IF(F6>=10,"적절","부적절") -> 적절 | H7: =IF(((E6+G6)/(C6+E6+G6))<0.2,"기관부담연구개발비 부족","적절") -> 적절
B12: 1. 연구개발비 분담내역(작성필요) | D12: *공동, 위탁은 있는 경우만 작성
J13: (단위:천원)
B14: 차수 | C14: 구분 | D14: 기관명 | E14: 정부지원연구개발비 | F14: 기관부담연구개발비 | I14: 총연구개발비 | J14: 검증결과 (적절, 부적절) | L14: ★3-1 인건비 작성여부★(엑셀 오른쪽에 있습니다.)
E15: 현금 | F15: 현금 | G15: 현물 | H15: 계
B16: 1 | C16: 주관연구개발기관 | D16: ='총괄(사업자번호 입력)'!F4 -> 젝사젠 주식회사 | E16: 60000 | F16: 2000 | G16: 18000 | H16: =SUM(F16:G16) -> 20000 | I16: =H16+E16 -> 80000 | J16: =IF(COUNTBLANK(D16)=1,"적절",IF(I16=L86,"적절","부적절")) -> 적절
B17: 1 | C17: 공동연구개발기관(1) | H17: =SUM(F17:G17) -> 0 | I17: =H17+E17 -> 0 | J17: =IF(COUNTBLANK(D17)=1,"적절",IF(I17=L111,"적절","부적절")) -> 적절
B18: 1 | C18: 공동연구개발기관(2) | H18: =SUM(F18:G18) -> 0 | I18: =H18+E18 -> 0 | J18: =IF(COUNTBLANK(D18)=1,"적절",IF(I18=L136,"적절","부적절")) -> 적절
B19: 1 | C19: 위탁연구개발기관(1) | H19: =SUM(F19:G19) -> 0 | I19: =H19+E19 -> 0 | J19: =IF(COUNTBLANK(D19)=1,"적절",IF(I19=L162,"적절","부적절")) -> 적절
B20: 1 | C20: 위탁연구개발기관(2) | H20: =SUM(F20:G20) -> 0 | I20: =H20+E20 -> 0 | J20: =IF(COUNTBLANK(D20)=1,"적절",IF(I20=L188,"적절","부적절")) -> 적절
B21: 합계 | E21: =SUM(E16:E19) -> 60000 | F21: =SUM(F16:F19) -> 2000 | G21: =SUM(G16:G19) -> 18000 | H21: =SUM(F21:G21) -> 20000 | I21: =SUM(I16:I19) -> 80000 | J21: =IF(I21=L54,"적절","부적절") -> 적절
E22: =IF(E21=C6,"적절","부적절") -> 적절 | F22: =IF(F21=E6,"적절","부적절") -> 적절 | G22: =IF(G21=G6,"적절","부적절") -> 적절
B24: 2. 연구개발비(총괄-자동반영), 직접 입력 금지
M25: (단위:천원)
B26: 차수 | C26: 구분 | D26: 과제번호 | E26: 구 분 | F26: 비목 | H26: 현금 | J26: 현물 | L26: 총계 | N26: 주요 검토결과 (적절, 부적절)
H27: 현금(천원) (A) | I27: 비율 (A/C) | J27: 현물(천원) (B) | K27: 비율 (B/C) | L27: 소계(천원) (C) | M27: 총연구개발비대비 비율
B28: 1 | C28: 총 연구개발비 | D28: ='총괄(사업자번호 입력)'!C4:D4 -> 0 | E28: 직접비 | F28: 인건비 | G28: 기존인력인건비 | H28: =H61+H90+H115 -> 0 | I28: =IFERROR(H28/L28,"") -> 0 | J28: =J61+J90+J115 -> 18000 | K28: =IFERROR(J28/L28,"") -> 1 | L28: =H28+J28 -> 18000 | M28: =IFERROR(L28/$L$54,"") -> 0.225
G29: 신규인력인건비 | H29: =H62+H91+H116 -> 50895 | I29: =IFERROR(H29/L29,"") -> 1 | J29: =J62+J91+J116 -> 0 | K29: =IFERROR(J29/L29,"") -> 0 | L29: =H29+J29 -> 50895 | M29: =IFERROR(L29/$L$54,"") -> 0.6361875
G30: 외부인건비 | H30: =H63+H92+H117 -> 0 | I30: =IFERROR(H30/L30,"") | J30: =J63+J92+J117 -> 0 | K30: =IFERROR(J30/L30,"") | L30: =H30+J30 -> 0 | M30: =IFERROR(L30/$L$54,"") -> 0
F31: 인건비 소계 | H31: =H28+H29+H30 -> 50895 | I31: =IFERROR(H31/L31,"") -> 0.73873285 | J31: =SUM(J28:J30) -> 18000 | K31: =IFERROR(J31/L31,"") -> 0.26126715 | L31: =H31+J31 -> 68895 | M31: =IFERROR(L31/$L$54,"") -> 0.8611875
F32: 연구시설·장비비 | H32: =H65+H94+H119 -> 0 | I32: =IFERROR(H32/L32,"") | J32: =J65+J94+J119 -> 0 | K32: =IFERROR(J32/L32,"") | L32: =H32+J32 -> 0 | M32: =IFERROR(L32/$L$54,"") -> 0
F33: 연구재료비 | H33: =H66+H95+H120 -> 0 | I33: =IFERROR(H33/L33,"") | J33: =J66+J95+J120 -> 0 | K33: =IFERROR(J33/L33,"") | L33: =H33+J33 -> 0 | M33: =IFERROR(L33/$L$54,"") -> 0
F34: 연구활동비 | G34: 지식재산 창출활동비 | H34: =H67+H96+H121 -> 0 | I34: =IFERROR(H34/L34,"") | L34: =H34+J34 -> 0 | M34: =IFERROR(L34/$L$54,"") -> 0
G35: 외부 전문기술 활용비 | H35: =H68+H97+H122 -> 900 | I35: =IFERROR(H35/L35,"") -> 1 | L35: =H35+J35 -> 900 | M35: =IFERROR(L35/$L$54,"") -> 0.01125 | N35: =IFERROR(L35/L49,"") -> 0.011292346 | O35: =IF(N35<0.4,"적절","부적절") -> 적절
G36: 회의비 | H36: =H69+H98+H123 -> 1000 | I36: =IFERROR(H36/L36,"") -> 1 | L36: =H36+J36 -> 1000 | M36: =IFERROR(L36/$L$54,"") -> 0.0125
G37: 출장비 | H37: =H70+H99+H124 -> 0 | I37: =IFERROR(H37/L37,"") | L37: =H37+J37 -> 0 | M37: =IFERROR(L37/$L$54,"") -> 0
G38: 클라우드컴퓨팅 서비스 활용비 | H38: =H71+H100+H125 -> 3000 | I38: =IFERROR(H38/L38,"") -> 1 | L38: =H38+J38 -> 3000 | M38: =IFERROR(L38/$L$54,"") -> 0.0375
G39: 소프트웨어 활용비 | H39: =H72+H101+H126 -> 0 | I39: =IFERROR(H39/L39,"") | L39: =H39+J39 -> 0 | M39: =IFERROR(L39/$L$54,"") -> 0
G40: 연구실운영비 | H40: =H73+H102+H127 -> 0 | I40: =IFERROR(H40/L40,"") | L40: =H40+J40 -> 0 | M40: =IFERROR(L40/$L$54,"") -> 0
G41: 연구인력 지원비 | H41: =H74+H103+H128 -> 0 | I41: =IFERROR(H41/L41,"") | L41: =H41+J41 -> 0 | M41: =IFERROR(L41/$L$54,"") -> 0
G42: 그 밖의 비용 | H42: =H76+H104+H129+H75 -> 1405 | I42: =IFERROR(H42/L42,"") -> 1 | L42: =H42+J42 -> 1405 | M42: =IFERROR(L42/$L$54,"") -> 0.0175625
F43: 연구활동비 소계 | H43: =SUM(H34:H42) -> 6305 | I43: =IFERROR(H43/L43,"") -> 1 | L43: =H43+J43 -> 6305 | M43: =IFERROR(L43/$L$54,"") -> 0.0788125
F44: 연구수당 | H44: =H78+H105+H130 -> 4500 | I44: =IFERROR(H44/L44,"") -> 1 | L44: =H44+J44 -> 4500 | M44: =IFERROR(L44/$L$54,"") -> 0.05625
F45: 위탁연구개발비 | G45: 직접비(인건비) | H45: =H144+H170 -> 0 | I45: =IFERROR(H45/L45,"") | L45: =H45+J45 -> 0 | M45: =IFERROR(L45/$L$54,"") -> 0
...

Sheet Sheet2
A1: 사업자등록번호 | B1: 과제번호 | C1: 주관연구개발기관명 | D1: 집체협약일정 | E1: 1차년도 | F1: 2차년도 | G1: 총합
A2: 6948703079 | B2: RS-2024-00467565 | C2: 주식회사 프로덕트테크 | D2: 2024-08-22(목) 10:00 | E2: 60000 | F2: 60000 | G2: 120000
A3: 6118701514 | B3: RS-2024-00467338 | C3: 주식회사 레이어와이즈 | D3: 2024-08-22(목) 10:00 | E3: 60000 | F3: 60000 | G3: 120000
A4: 8308101826 | B4: RS-2024-00467377 | C4: 머티리얼포레스트 | D4: 2024-08-22(목) 10:40 | E4: 60000 | F4: 60000 | G4: 120000
A5: 5608603105 | B5: RS-2024-00467957 | C5: 갈포드(주) | D5: 2024-08-22(목) 10:40 | E5: 60000 | F5: 60000 | G5: 120000
A6: 5788102719 | B6: RS-2024-00467955 | C6: 지케이(주) | D6: 2024-08-22(목) 11:20 | E6: 60000 | F6: 60000 | G6: 120000
A7: 5858602589 | B7: RS-2024-00467589 | C7: 주식회사 이지스네이처 | D7: 2024-08-22(목) 13:00 | E7: 60000 | F7: 60000 | G7: 120000
A8: 2058143826 | B8: RS-2024-00468533 | C8: 주식회사 더다봄 | D8: 2024-08-22(목) 13:00 | E8: 60000 | F8: 60000 | G8: 120000
A9: 6851202267 | B9: RS-2024-00468295 | C9: 다한엔지니어링 | D9: 2024-08-22(목) 13:40 | E9: 60000 | F9: 60000 | G9: 120000
A10: 7218101430 | B10: RS-2024-00467812 | C10: (주)준시스템 | D10: 2024-08-23(금) 10:00 | E10: 60000 | F10: 60000 | G10: 120000
A11: 1518601640 | B11: RS-2024-00468526 | C11: 에이지로보틱스 주식회사 | D11: 2024-08-23(금) 10:00 | E11: 60000 | F11: 60000 | G11: 120000
A12: 7158702867 | B12: RS-2024-00467963 | C12: 에코진웍스 주식회사 | D12: 2024-08-23(금) 10:40 | E12: 60000 | F12: 60000 | G12: 120000
A13: 5608702608 | B13: RS-2024-00468782 | C13: 시엑스 주식회사 | D13: 2024-08-23(금) 10:40 | E13: 60000 | F13: 60000 | G13: 120000
... A556: 4298701462 | B556: RS-2024-00468674 | C556: 주식회사씨포스 | D556: 2024-08-30(금) 13:00 | E556: 60000 | F556: 60000 | G556: 120000
