Workbook
Name 산재보상기준: '[1]계산기(입력)'!#REF!
Name 실업급여: '[1]계산기(입력)'!#REF!

Sheet 연차일수
A1: 계산 기초 | D1: 연차휴가 계산기
A2: 입사일자 | B2: 첫회계일 | C2: 최종근무 | I2: 옵션 | J2: ■ 소수점 처리
A3: =IF(ISERR(DATE(F7,G7,H7)),"e",DATE(F7,G7,H7)) -> 45048 | B3: =IF(A5<2,DATE(F7+1,M7,N7),DATE(F7,M7,N7)) -> 45292 | C3: =IF(ISERR(DATE(I7,K7,L7)),"e",DATE(I7,K7,L7)-1) -> e | D3: (회계연도 기준) | I3: 설정 | J3: ■ 근속년수가산
A4: 회계일:입사일 | B4: 초년월수 | C4: 재직월수
A5: =IF(G7*100+H7>M7*100+N7,0,IF(G7*100+H7=M7*100+N7,1,2)) -> 0 | B5: =DATEDIF(A3,B3,"m")-IF(H7=N7,1,0) -> 7 | C5: =IF(C3="e",1200,DATEDIF(A3,C3,"m")) -> 1200 | D5: 인 적 사 항 | F5: 입 사 일 자 | I5: 퇴사일자 (메모확인 필수) | M5: 회계연도첫날
A6: 월차개정 | B6: 기준일(1) | C6: 기준일(2) | D6: 소속/직책 | E6: 성 명 | F6: 년 | G6: 월 | H6: 일 | I6: 년 | K6: 월 | L6: 일 | M6: 월 | N6: 일
A7: 차감여부 | B7: 42885 | C7: 43249 | F7: 2023 | G7: 5 | H7: 2 | M7: 1 | N7: 1
A8: 소멸시기 | B8: 43586 | C8: 43891
A9: 회계연도 기준 | D9: 근무년차 | E9: 휴가발생 | F9: 휴가발생일수 | I9: 연 간 | K9: 수당발생 | M9: 수당발생
A10: 회계연수 | B10: 기준일자 | C10: 재직여부 | E10: 일 자 | G10: 직접입력* | I10: 사용일수 | K10: 일 자 | M10: 일 수
A11: -1 | B11: =DATE(IF($A$5<2,$F$7+A11+1,$F$7+A11),$M$7,$N$7) -> 44927 | C11: =IF(AND(NOT($C$3="e"),B11>$C$3),1,0) -> 0 | D11: =A11+2&"년차(월차)" -> 1년차(월차) | E11: ="매월"&H7&"일(1개씩)" -> 매월2일(1개씩) | F11: =IF(B3>C3,C5,B5) -> 7 | K11: =IF(OR(AND(A3>=B7,C3>=C7),B12>C3),IF(C5<12,C3+1,IF(A3<B8,"발생 ",IF(A3<C8,"발생(입사)","입사 "))&"1년후"),"-") -> 입사 1년후 | M11: =IF(OR(AND(A3>=B7,C3>=C7),B12>C3),IF(G11="",F11,G11)-I11,"-") -> 7
A12: 0 | B12: =DATE(IF($A$5<2,$F$7+A12+1,$F$7+A12),$M$7,$N$7) -> 45292 | C12: =IF(AND(NOT($C$3="e"),B12>$C$3),1,0) -> 0 | D12: =IF(C12=1,"",A12+2&"년차") -> 2년차 | E12: =IF(C12=1,"",B12) -> 45292 | F12: =IF(C12=1,"",IF($B$42=3,15,IF($A$42=1,15*(B12-A3)/365,IF($A$42=2,ROUNDUP(15*(B12-A3)/365,0),ROUNDUP(15*(B12-A3)/365*2,0)/2)))-IF(AND(A3>=B7,C3>=C7),0,I11)) -> 10.027397 | K12: =IF(C12=1,"",IF(B14>$C$3,$C$3+1,B14)) -> 45658 | M12: =IF(C12=1,"",IF(G12="",F12,G12)-I12) -> 10.027397
A13: 0 | B13: =DATE(IF($A$5<2,$F$7+A13+1,$F$7+A13),$M$7,$N$7) -> 45292 | C13: =IF(AND(NOT($C$3="e"),B13>$C$3),1,0) -> 0 | D13: =IF(C13=1,"",A13+2&"년차(월차)") -> 2년차(월차) | E13: =IF(C13=1,"","매월"&H7&"일(1개씩)") -> 매월2일(1개씩) | F13: =IF(C13=1,"",IF(B14>C3,IF(C5>11,11,C5)-F11,11-B5)) -> 4 | K13: =IF(C13=1,"",IF(OR(AND(A3>=B7,C3>=C7),B14>C3),IF(C5<12,C3+1,IF(B3<B8,"발생 ",IF(B3<C8,"발생(입사)","입사 "))&"1년후"),"-")) -> 입사 1년후 | M13: =IF(C13=1,"",IF(OR(AND(A3>=B7,C3>=C7),B14>C3),IF(G13="",F13,G13)-I13,"-")) -> 4
A14: 1 | B14: =DATE(IF($A$5<2,$F$7+A14+1,$F$7+A14),$M$7,$N$7) -> 45658 | C14: =IF(AND(NOT($C$3="e"),B14>$C$3),1,0) -> 0 | D14: =IF(C14=1,"",A14+2&"년차") -> 3년차 | E14: =IF(C14=1,"",IF(C14=1,$C$3,B14)) -> 45658 | F14: =IF(C14=1,"",15-IF(AND(A3>=B7,C3>=C7),0,I13)) -> 15 | K14: =IF(C14=1,"",IF(B15>$C$3,$C$3+1,B15)) -> 46023 | M14: =IF(C14=1,"",IF(G14="",F14,G14)-I14) -> 15
A15: 2 | B15: =DATE(IF($A$5<2,$F$7+A15+1,$F$7+A15),$M$7,$N$7) -> 46023 | C15: =IF(AND(NOT($C$3="e"),B15>$C$3),1,0) -> 0 | D15: =IF(C15=1,"",A15+2&"년차") -> 4년차 | E15: =IF(C15=1,"",IF(C15=1,$C$3,B15)) -> 46023 | F15: =IF(C15=1,"",15+INT((A15+IF($B$42=1,0,1)-IF(AND($B$42=1,$A$5=1),0,1))/2)) -> 15 | K15: =IF(C15=1,"",IF(B16>$C$3,$C$3+1,B16)) -> 46388 | M15: =IF(C15=1,"",IF(G15="",F15,G15)-I15) -> 15
A16: 3 | B16: =DATE(IF($A$5<2,$F$7+A16+1,$F$7+A16),$M$7,$N$7) -> 46388 | C16: =IF(AND(NOT($C$3="e"),B16>$C$3),1,0) -> 0 | D16: =IF(C16=1,"",A16+2&"년차") -> 5년차 | E16: =IF(C16=1,"",IF(C16=1,$C$3,B16)) -> 46388 | F16: =IF(C16=1,"",15+INT((A16+IF($B$42=1,0,1)-IF(AND($B$42=1,$A$5=1),0,1))/2)) -> 16 | K16: =IF(C16=1,"",IF(B17>$C$3,$C$3+1,B17)) -> 46753 | M16: =IF(C16=1,"",IF(G16="",F16,G16)-I16) -> 16
A17: 4 | B17: =DATE(IF($A$5<2,$F$7+A17+1,$F$7+A17),$M$7,$N$7) -> 46753 | C17: =IF(AND(NOT($C$3="e"),B17>$C$3),1,0) -> 0 | D17: =IF(C17=1,"",A17+2&"년차") -> 6년차 | E17: =IF(C17=1,"",IF(C17=1,$C$3,B17)) -> 46753 | F17: =IF(C17=1,"",15+INT((A17+IF($B$42=1,0,1)-IF(AND($B$42=1,$A$5=1),0,1))/2)) -> 16 | K17: =IF(C17=1,"",IF(B18>$C$3,$C$3+1,B18)) -> 47119 | M17: =IF(C17=1,"",IF(G17="",F17,G17)-I17) -> 16
A18: 5 | B18: =DATE(IF($A$5<2,$F$7+A18+1,$F$7+A18),$M$7,$N$7) -> 47119 | C18: =IF(AND(NOT($C$3="e"),B18>$C$3),1,0) -> 0 | D18: =IF(C18=1,"",A18+2&"년차") -> 7년차 | E18: =IF(C18=1,"",IF(C18=1,$C$3,B18)) -> 47119 | F18: =IF(C18=1,"",15+INT((A18+IF($B$42=1,0,1)-IF(AND($B$42=1,$A$5=1),0,1))/2)) -> 17 | K18: =IF(C18=1,"",IF(B19>$C$3,$C$3+1,B19)) -> 47484 | M18: =IF(C18=1,"",IF(G18="",F18,G18)-I18) -> 17
A19: 6 | B19: =DATE(IF($A$5<2,$F$7+A19+1,$F$7+A19),$M$7,$N$7) -> 47484 | C19: =IF(AND(NOT($C$3="e"),B19>$C$3),1,0) -> 0 | D19: =IF(C19=1,"",A19+2&"년차") -> 8년차 | E19: =IF(C19=1,"",IF(C19=1,$C$3,B19)) -> 47484 | F19: =IF(C19=1,"",15+INT((A19+IF($B$42=1,0,1)-IF(AND($B$42=1,$A$5=1),0,1))/2)) -> 17 | K19: =IF(C19=1,"",IF(B20>$C$3,$C$3+1,B20)) -> 47849 | M19: =IF(C19=1,"",IF(G19="",F19,G19)-I19) -> 17
A20: 7 | B20: =DATE(IF($A$5<2,$F$7+A20+1,$F$7+A20),$M$7,$N$7) -> 47849 | C20: =IF(AND(NOT($C$3="e"),B20>$C$3),1,0) -> 0 | D20: =IF(C20=1,"",A20+2&"년차") -> 9년차 | E20: =IF(C20=1,"",IF(C20=1,$C$3,B20)) -> 47849 | F20: =IF(C20=1,"",15+INT((A20+IF($B$42=1,0,1)-IF(AND($B$42=1,$A$5=1),0,1))/2)) -> 18 | K20: =IF(C20=1,"",IF(B21>$C$3,$C$3+1,B21)) -> 48214 | M20: =IF(C20=1,"",IF(G20="",F20,G20)-I20) -> 18
A21: 8 | B21: =DATE(IF($A$5<2,$F$7+A21+1,$F$7+A21),$M$7,$N$7) -> 48214 | C21: =IF(AND(NOT($C$3="e"),B21>$C$3),1,0) -> 0 | D21: =IF(C21=1,"",A21+2&"년차") -> 10년차 | E21: =IF(C21=1,"",IF(C21=1,$C$3,B21)) -> 48214 | F21: =IF(C21=1,"",15+INT((A21+IF($B$42=1,0,1)-IF(AND($B$42=1,$A$5=1),0,1))/2)) -> 18 | K21: =IF(C21=1,"",IF(B22>$C$3,$C$3+1,B22)) -> 48580 | M21: =IF(C21=1,"",IF(G21="",F21,G21)-I21) -> 18
A22: 9 | B22: =DATE(IF($A$5<2,$F$7+A22+1,$F$7+A22),$M$7,$N$7) -> 48580 | C22: =IF(AND(NOT($C$3="e"),B22>$C$3),1,0) -> 0 | D22: =IF(C22=1,"",A22+2&"년차") -> 11년차 | E22: =IF(C22=1,"",IF(C22=1,$C$3,B22)) -> 48580 | F22: =IF(C22=1,"",15+INT((A22+IF($B$42=1,0,1)-IF(AND($B$42=1,$A$5=1),0,1))/2)) -> 19 | K22: =IF(C22=1,"",IF(B23>$C$3,$C$3+1,B23)) -> 48945 | M22: =IF(C22=1,"",IF(G22="",F22,G22)-I22) -> 19
A23: 10 | B23: =DATE(IF($A$5<2,$F$7+A23+1,$F$7+A23),$M$7,$N$7) -> 48945 | C23: =IF(AND(NOT($C$3="e"),B23>$C$3),1,0) -> 0 | D23: =IF(C23=1,"",A23+2&"년차") -> 12년차 | E23: =IF(C23=1,"",IF(C23=1,$C$3,B23)) -> 48945 | F23: =IF(C23=1,"",15+INT((A23+IF($B$42=1,0,1)-IF(AND($B$42=1,$A$5=1),0,1))/2)) -> 19 | K23: =IF(C23=1,"",IF(B24>$C$3,$C$3+1,B24)) -> 49310 | M23: =IF(C23=1,"",IF(G23="",F23,G23)-I23) -> 19
A24: 11 | B24: =DATE(IF($A$5<2,$F$7+A24+1,$F$7+A24),$M$7,$N$7) -> 49310 | C24: =IF(AND(NOT($C$3="e"),B24>$C$3),1,0) -> 0 | D24: =IF(C24=1,"",A24+2&"년차") -> 13년차 | E24: =IF(C24=1,"",IF(C24=1,$C$3,B24)) -> 49310 | F24: =IF(C24=1,"",15+INT((A24+IF($B$42=1,0,1)-IF(AND($B$42=1,$A$5=1),0,1))/2)) -> 20 | K24: =IF(C24=1,"",IF(B25>$C$3,$C$3+1,B25)) -> 49675 | M24: =IF(C24=1,"",IF(G24="",F24,G24)-I24) -> 20
A25: 12 | B25: =DATE(IF($A$5<2,$F$7+A25+1,$F$7+A25),$M$7,$N$7) -> 49675 | C25: =IF(AND(NOT($C$3="e"),B25>$C$3),1,0) -> 0 | D25: =IF(C25=1,"",A25+2&"년차") -> 14년차 | E25: =IF(C25=1,"",IF(C25=1,$C$3,B25)) -> 49675 | F25: =IF(C25=1,"",15+INT((A25+IF($B$42=1,0,1)-IF(AND($B$42=1,$A$5=1),0,1))/2)) -> 20 | K25: =IF(C25=1,"",IF(B26>$C$3,$C$3+1,B26)) -> 50041 | M25: =IF(C25=1,"",IF(G25="",F25,G25)-I25) -> 20
A26: 13 | B26: =DATE(IF($A$5<2,$F$7+A26+1,$F$7+A26),$M$7,$N$7) -> 50041 | C26: =IF(AND(NOT($C$3="e"),B26>$C$3),1,0) -> 0 | D26: =IF(C26=1,"",A26+2&"년차") -> 15년차 | E26: =IF(C26=1,"",IF(C26=1,$C$3,B26)) -> 50041 | F26: =IF(C26=1,"",15+INT((A26+IF($B$42=1,0,1)-IF(AND($B$42=1,$A$5=1),0,1))/2)) -> 21 | K26: =IF(C26=1,"",IF(B27>$C$3,$C$3+1,B27)) -> 50406 | M26: =IF(C26=1,"",IF(G26="",F26,G26)-I26) -> 21
... A33: 20 | B33: =DATE(IF($A$5<2,$F$7+A33+1,$F$7+A33),$M$7,$N$7) -> 52597 | C33: =IF(AND(NOT($C$3="e"),B33>$C$3),1,0) -> 0 | D33: =IF(C33=1,"",A33+2&"년차") -> 22년차 | E33: =IF(C33=1,"",IF(C33=1,$C$3,B33)) -> 52597 | F33: =IF(C33=1,"",15+INT((A33+IF($B$42=1,0,1)-IF(AND($B$42=1,$A$5=1),0,1))/2)) -> 24 | K33: =IF(C33=1,"",IF(B34>$C$3,$C$3+1,B34)) -> 52963 | M33: =IF(C33=1,"",IF(G33="",F33,G33)-I33) -> 24
A34: 21 | B34: =DATE(IF($A$5<2,$F$7+A34+1,$F$7+A34),$M$7,$N$7) -> 52963 | C34: =IF(AND(NOT($C$3="e"),B34>$C$3),1,0) -> 0 | D34: =IF(C35>0,"",A35+2&"년차**") -> 23년차** | E34: =IF(C35>0,"",IF(C3="e",IF(C35=1,C3,B35),"추가 "&A35-A33&"년치")) -> 52963 | F34: =IF(C35>0,"",IF(C3="e",15+INT((A35-1)/2),(A35-A33)*25)) -> 25 | K34: =IF(C35>0,"",IF(C3="e",IF(B36>C3,C3+1,B36),"추가 "&A35-A33&"년치")) -> 53328 | M34: =IF(C35>0,"",IF(G34="",F34,G34)-I34) -> 25
A35: =IF(C3="e",A33+1,IF(B3>C3,0,DATEDIF(B3,C3,"y"))) -> 21 | B35: =DATE(IF($A$5<2,$F$7+A35+1,$F$7+A35),$M$7,$N$7) -> 52963 | C35: =IF(A33>A35-1,2,IF(AND(NOT(C3="e"),B35>C3),1,0)) -> 0 | D35: =IF(NOT(C3="e"),IF(AND(A3=퇴직정산!A3,B3=퇴직정산!B3,C3=퇴직정산!C3,A42=퇴직정산!E6,B42=퇴직정산!F6),"[퇴직정산 총일수] "&ROUND(M35+IF(퇴직정산!$N$34>퇴직정산!$I$34,퇴직정산!N34-퇴직정산!I34,0),1)&"일분 (입사일 기준 미달 일수를 합한 일수)","(이 시트와 다음 시트 입력값이 모두 같으면 퇴직정산 총일수 표시)"),"") | K35: 합 계 | M35: =IF(C3="e","",SUM(M11:N34))
A36: =A35+1 -> 22 | B36: =DATE(IF($A$5<2,$F$7+A36+1,$F$7+A36),$M$7,$N$7) -> 53328 | D36: *. 전년 8할미만 출근자, 연도 중 휴직자, 1년미만 근속자로서 앞의 자동계산 일수와 다른 경우 직접 입력함
A37: 옵션 설정 | D37: **. 23년차 이후의 자는 휴가발생 일수가 25일로 같으므로 23년차 행에 총 발생일수, 총 사용일수를 입력함
A38: 소수점처리 | B38: 근속년수가산
A39: 소수점 그대로 | B39: 비례-15-15-16…
A40: １일단위 올림 | B40: 비례-15-16-16…
A41: 반일단위 올림 | B41: 15-15-16-16…
A42: 1 | B42: 1

Sheet 퇴직정산
A1: 계산 기초 | E1: 옵션 설정 | G1: 퇴직자 연차수당 정산
A2: 입사일자 | B2: 첫회계일 | C2: 최종근무 | E2: 소수점처리 | F2: 근속년수가산 | L2: 옵션 | M2: ■ 소수점 처리
A3: =IF(ISERR(DATE(I7,J7,K7)),"e",DATE(I7,J7,K7)) -> 45048 | B3: =IF(A5<2,DATE(I7+1,P7,Q7),DATE(I7,P7,Q7)) -> 45292 | C3: =IF(ISERR(DATE(L7,N7,O7)),"e",DATE(L7,N7,O7)-1) -> e | E3: 소수점 그대로 | F3: 비례-15-15-16… | G3: (회계연도 기준) | L3: 설정 | M3: ■ 근속년수가산
A4: 회계일:입사일 | B4: 초년월수 | C4: 재직월수 | E4: １일단위 올림 | F4: 비례-15-16-16…
A5: =IF(J7*100+K7>P7*100+Q7,0,IF(J7*100+K7=P7*100+Q7,1,2)) -> 0 | B5: =DATEDIF(A3,B3,"m") -> 7 | C5: =IF(C3="e",1200,DATEDIF(A3,C3,"m")) -> 1200 | E5: 반일단위 올림 | F5: 15-15-16-16… | G5: 인 적 사 항 | I5: 입 사 일 자 | L5: 퇴사일자 (메모확인 필수) | P5: 회계연도첫날
A6: 개 정 법 | B6: 대 상 자 | C6: 시행일자 | E6: 1 | F6: 1 | G6: 소속/직책 | H6: 성 명 | I6: 년 | J6: 월 | K6: 일 | L6: 년 | N6: 월 | O6: 일 | P6: 월 | Q6: 일
A7: 적용기준 | B7: =연차일수!B7 -> 42885 | C7: =연차일수!C7 -> 43249 | G7: =연차일수!D7 -> 0 | H7: =연차일수!E7 -> 0 | I7: =연차일수!F7 -> 2023 | J7: =연차일수!G7 -> 5 | K7: =연차일수!H7 -> 2 | L7: =연차일수!I7 -> 0 | N7: =연차일수!K7 -> 0 | O7: =연차일수!L7 -> 0 | P7: =연차일수!M7 -> 1 | Q7: =연차일수!N7 -> 1
A9: 회계연도 기준 | D9: 입사일 기준 | G9: 회계연도 기준 | J9: 입사일 기준 | P9: 추가수당
A10: 회계연수 | B10: 기준일자 | C10: 재직여부 | D10: 근속년수 | E10: 기준일자 | F10: 재직여부 | G10: 근무년차 | H10: 발생일자 | I10: 발생일수 | J10: 근속년수 | L10: 발생일자 | N10: 발생일수 | P10: 발생일수
A11: -1 | B11: =DATE(IF($A$5<2,$I$7+A11+1,$I$7+A11),$P$7,$Q$7) -> 44927 | C11: =IF(AND(NOT($C$3="e"),B11>$C$3),1,0) -> 0 | D11: 0 | E11: =DATE($I$7+D11,$J$7,$K$7) -> 45048 | F11: =IF(AND(NOT($C$3="e"),E11>$C$3),1,0) -> 0 | G11: 1년미만(월차) | H11: =IF(OR(AND(A3>=B7,C3>=C7),B13>C3),"매월"&K7&"일(1개씩)","-") -> 매월2일(1개씩) | I11: =IF(AND(A3>=B7,C3>=C7),IF(C5<12,C5,11),IF(B3>C3,C5,IF(B13>C3,IF(C5<12,C5,11)-B5,"-"))) -> 11 | J11: 1년미만(월차) | L11: =IF(OR(C5<12,AND(A3>=DATE(2017,5,30),C3>=DATE(2018,5,29))),"매월"&K7&"일(1개씩)","-") -> 매월2일(1개씩) | N11: =IF(OR(C5<12,AND(A3>=DATE(2017,5,30),C3>=DATE(2018,5,29))),IF(C5<12,C5,11),"-") -> 11
A12: 0 | B12: =DATE(IF($A$5<2,$I$7+A12+1,$I$7+A12),$P$7,$Q$7) -> 45292 | C12: =IF(AND(NOT($C$3="e"),B12>$C$3),1,0) -> 0 | D12: 1 | E12: =DATE($I$7+D12,$J$7,$K$7) -> 45414 | F12: =IF(AND(NOT($C$3="e"),E12>$C$3),1,0) -> 0 | G12: =IF(C12=1,"",A12+2&"년차") -> 2년차 | H12: =IF(C12=1,"",B12) -> 45292 | I12: =IF(C12=1,"",IF(OR($A$5=1,$F$6=3),15,IF($E$6=1,15*(B12-A3)/365,IF($E$6=2,ROUNDUP(15*(B12-A3)/365,0),ROUNDUP(15*(B12-A3)/365*2,0)/2)))) -> 10.027397 | J12: =IF(F12=1,"",D12&"년근속") -> 1년근속 | L12: =IF(F12=1,"",E12) -> 45414 | N12: =IF(F12=1,"",15+INT((D12-1)/2)) -> 15
A13: 1 | B13: =DATE(IF($A$5<2,$I$7+A13+1,$I$7+A13),$P$7,$Q$7) -> 45658 | C13: =IF(AND(NOT($C$3="e"),B13>$C$3),1,0) -> 0 | D13: 2 | E13: =DATE($I$7+D13,$J$7,$K$7) -> 45779 | F13: =IF(AND(NOT($C$3="e"),E13>$C$3),1,0) -> 0 | G13: =IF(C13=1,"",A13+2&"년차") -> 3년차 | H13: =IF(C13=1,"",B13) -> 45658 | I13: =IF(C13=1,"",15) -> 15 | J13: =IF(F13=1,"",D13&"년근속") -> 2년근속 | L13: =IF(F13=1,"",E13) -> 45779 | N13: =IF(F13=1,"",15+INT((D13-1)/2)) -> 15
A14: 2 | B14: =DATE(IF($A$5<2,$I$7+A14+1,$I$7+A14),$P$7,$Q$7) -> 46023 | C14: =IF(AND(NOT($C$3="e"),B14>$C$3),1,0) -> 0 | D14: 3 | E14: =DATE($I$7+D14,$J$7,$K$7) -> 46144 | F14: =IF(AND(NOT($C$3="e"),E14>$C$3),1,0) -> 0 | G14: =IF(C14=1,"",A14+2&"년차") -> 4년차 | H14: =IF(C14=1,"",B14) -> 46023 | I14: =IF(C14=1,"",15+INT((A14+IF($F$6=1,0,1)-IF(AND($F$6=1,$A$5=1),0,1))/2)) -> 15 | J14: =IF(F14=1,"",D14&"년근속") -> 3년근속 | L14: =IF(F14=1,"",E14) -> 46144 | N14: =IF(F14=1,"",15+INT((D14-1)/2)) -> 16
A15: 3 | B15: =DATE(IF($A$5<2,$I$7+A15+1,$I$7+A15),$P$7,$Q$7) -> 46388 | C15: =IF(AND(NOT($C$3="e"),B15>$C$3),1,0) -> 0 | D15: 4 | E15: =DATE($I$7+D15,$J$7,$K$7) -> 46509 | F15: =IF(AND(NOT($C$3="e"),E15>$C$3),1,0) -> 0 | G15: =IF(C15=1,"",A15+2&"년차") -> 5년차 | H15: =IF(C15=1,"",B15) -> 46388 | I15: =IF(C15=1,"",15+INT((A15+IF($F$6=1,0,1)-IF(AND($F$6=1,$A$5=1),0,1))/2)) -> 16 | J15: =IF(F15=1,"",D15&"년근속") -> 4년근속 | L15: =IF(F15=1,"",E15) -> 46509 | N15: =IF(F15=1,"",15+INT((D15-1)/2)) -> 16
A16: 4 | B16: =DATE(IF($A$5<2,$I$7+A16+1,$I$7+A16),$P$7,$Q$7) -> 46753 | C16: =IF(AND(NOT($C$3="e"),B16>$C$3),1,0) -> 0 | D16: 5 | E16: =DATE($I$7+D16,$J$7,$K$7) -> 46875 | F16: =IF(AND(NOT($C$3="e"),E16>$C$3),1,0) -> 0 | G16: =IF(C16=1,"",A16+2&"년차") -> 6년차 | H16: =IF(C16=1,"",B16) -> 46753 | I16: =IF(C16=1,"",15+INT((A16+IF($F$6=1,0,1)-IF(AND($F$6=1,$A$5=1),0,1))/2)) -> 16 | J16: =IF(F16=1,"",D16&"년근속") -> 5년근속 | L16: =IF(F16=1,"",E16) -> 46875 | N16: =IF(F16=1,"",15+INT((D16-1)/2)) -> 17
A17: 5 | B17: =DATE(IF($A$5<2,$I$7+A17+1,$I$7+A17),$P$7,$Q$7) -> 47119 | C17: =IF(AND(NOT($C$3="e"),B17>$C$3),1,0) -> 0 | D17: 6 | E17: =DATE($I$7+D17,$J$7,$K$7) -> 47240 | F17: =IF(AND(NOT($C$3="e"),E17>$C$3),1,0) -> 0 | G17: =IF(C17=1,"",A17+2&"년차") -> 7년차 | H17: =IF(C17=1,"",B17) -> 47119 | I17: =IF(C17=1,"",15+INT((A17+IF($F$6=1,0,1)-IF(AND($F$6=1,$A$5=1),0,1))/2)) -> 17 | J17: =IF(F17=1,"",D17&"년근속") -> 6년근속 | L17: =IF(F17=1,"",E17) -> 47240 | N17: =IF(F17=1,"",15+INT((D17-1)/2)) -> 17
A18: 6 | B18: =DATE(IF($A$5<2,$I$7+A18+1,$I$7+A18),$P$7,$Q$7) -> 47484 | C18: =IF(AND(NOT($C$3="e"),B18>$C$3),1,0) -> 0 | D18: 7 | E18: =DATE($I$7+D18,$J$7,$K$7) -> 47605 | F18: =IF(AND(NOT($C$3="e"),E18>$C$3),1,0) -> 0 | G18: =IF(C18=1,"",A18+2&"년차") -> 8년차 | H18: =IF(C18=1,"",B18) -> 47484 | I18: =IF(C18=1,"",15+INT((A18+IF($F$6=1,0,1)-IF(AND($F$6=1,$A$5=1),0,1))/2)) -> 17 | J18: =IF(F18=1,"",D18&"년근속") -> 7년근속 | L18: =IF(F18=1,"",E18) -> 47605 | N18: =IF(F18=1,"",15+INT((D18-1)/2)) -> 18
A19: 7 | B19: =DATE(IF($A$5<2,$I$7+A19+1,$I$7+A19),$P$7,$Q$7) -> 47849 | C19: =IF(AND(NOT($C$3="e"),B19>$C$3),1,0) -> 0 | D19: 8 | E19: =DATE($I$7+D19,$J$7,$K$7) -> 47970 | F19: =IF(AND(NOT($C$3="e"),E19>$C$3),1,0) -> 0 | G19: =IF(C19=1,"",A19+2&"년차") -> 9년차 | H19: =IF(C19=1,"",B19) -> 47849 | I19: =IF(C19=1,"",15+INT((A19+IF($F$6=1,0,1)-IF(AND($F$6=1,$A$5=1),0,1))/2)) -> 18 | J19: =IF(F19=1,"",D19&"년근속") -> 8년근속 | L19: =IF(F19=1,"",E19) -> 47970 | N19: =IF(F19=1,"",15+INT((D19-1)/2)) -> 18
A20: 8 | B20: =DATE(IF($A$5<2,$I$7+A20+1,$I$7+A20),$P$7,$Q$7) -> 48214 | C20: =IF(AND(NOT($C$3="e"),B20>$C$3),1,0) -> 0 | D20: 9 | E20: =DATE($I$7+D20,$J$7,$K$7) -> 48336 | F20: =IF(AND(NOT($C$3="e"),E20>$C$3),1,0) -> 0 | G20: =IF(C20=1,"",A20+2&"년차") -> 10년차 | H20: =IF(C20=1,"",B20) -> 48214 | I20: =IF(C20=1,"",15+INT((A20+IF($F$6=1,0,1)-IF(AND($F$6=1,$A$5=1),0,1))/2)) -> 18 | J20: =IF(F20=1,"",D20&"년근속") -> 9년근속 | L20: =IF(F20=1,"",E20) -> 48336 | N20: =IF(F20=1,"",15+INT((D20-1)/2)) -> 19
A21: 9 | B21: =DATE(IF($A$5<2,$I$7+A21+1,$I$7+A21),$P$7,$Q$7) -> 48580 | C21: =IF(AND(NOT($C$3="e"),B21>$C$3),1,0) -> 0 | D21: 10 | E21: =DATE($I$7+D21,$J$7,$K$7) -> 48701 | F21: =IF(AND(NOT($C$3="e"),E21>$C$3),1,0) -> 0 | G21: =IF(C21=1,"",A21+2&"년차") -> 11년차 | H21: =IF(C21=1,"",B21) -> 48580 | I21: =IF(C21=1,"",15+INT((A21+IF($F$6=1,0,1)-IF(AND($F$6=1,$A$5=1),0,1))/2)) -> 19 | J21: =IF(F21=1,"",D21&"년근속") -> 10년근속 | L21: =IF(F21=1,"",E21) -> 48701 | N21: =IF(F21=1,"",15+INT((D21-1)/2)) -> 19
A22: 10 | B22: =DATE(IF($A$5<2,$I$7+A22+1,$I$7+A22),$P$7,$Q$7) -> 48945 | C22: =IF(AND(NOT($C$3="e"),B22>$C$3),1,0) -> 0 | D22: 11 | E22: =DATE($I$7+D22,$J$7,$K$7) -> 49066 | F22: =IF(AND(NOT($C$3="e"),E22>$C$3),1,0) -> 0 | G22: =IF(C22=1,"",A22+2&"년차") -> 12년차 | H22: =IF(C22=1,"",B22) -> 48945 | I22: =IF(C22=1,"",15+INT((A22+IF($F$6=1,0,1)-IF(AND($F$6=1,$A$5=1),0,1))/2)) -> 19 | J22: =IF(F22=1,"",D22&"년근속") -> 11년근속 | L22: =IF(F22=1,"",E22) -> 49066 | N22: =IF(F22=1,"",15+INT((D22-1)/2)) -> 20
A23: 11 | B23: =DATE(IF($A$5<2,$I$7+A23+1,$I$7+A23),$P$7,$Q$7) -> 49310 | C23: =IF(AND(NOT($C$3="e"),B23>$C$3),1,0) -> 0 | D23: 12 | E23: =DATE($I$7+D23,$J$7,$K$7) -> 49431 | F23: =IF(AND(NOT($C$3="e"),E23>$C$3),1,0) -> 0 | G23: =IF(C23=1,"",A23+2&"년차") -> 13년차 | H23: =IF(C23=1,"",B23) -> 49310 | I23: =IF(C23=1,"",15+INT((A23+IF($F$6=1,0,1)-IF(AND($F$6=1,$A$5=1),0,1))/2)) -> 20 | J23: =IF(F23=1,"",D23&"년근속") -> 12년근속 | L23: =IF(F23=1,"",E23) -> 49431 | N23: =IF(F23=1,"",15+INT((D23-1)/2)) -> 20
A24: 12 | B24: =DATE(IF($A$5<2,$I$7+A24+1,$I$7+A24),$P$7,$Q$7) -> 49675 | C24: =IF(AND(NOT($C$3="e"),B24>$C$3),1,0) -> 0 | D24: 13 | E24: =DATE($I$7+D24,$J$7,$K$7) -> 49797 | F24: =IF(AND(NOT($C$3="e"),E24>$C$3),1,0) -> 0 | G24: =IF(C24=1,"",A24+2&"년차") -> 14년차 | H24: =IF(C24=1,"",B24) -> 49675 | I24: =IF(C24=1,"",15+INT((A24+IF($F$6=1,0,1)-IF(AND($F$6=1,$A$5=1),0,1))/2)) -> 20 | J24: =IF(F24=1,"",D24&"년근속") -> 13년근속 | L24: =IF(F24=1,"",E24) -> 49797 | N24: =IF(F24=1,"",15+INT((D24-1)/2)) -> 21
A25: 13 | B25: =DATE(IF($A$5<2,$I$7+A25+1,$I$7+A25),$P$7,$Q$7) -> 50041 | C25: =IF(AND(NOT($C$3="e"),B25>$C$3),1,0) -> 0 | D25: 14 | E25: =DATE($I$7+D25,$J$7,$K$7) -> 50162 | F25: =IF(AND(NOT($C$3="e"),E25>$C$3),1,0) -> 0 | G25: =IF(C25=1,"",A25+2&"년차") -> 15년차 | H25: =IF(C25=1,"",B25) -> 50041 | I25: =IF(C25=1,"",15+INT((A25+IF($F$6=1,0,1)-IF(AND($F$6=1,$A$5=1),0,1))/2)) -> 21 | J25: =IF(F25=1,"",D25&"년근속") -> 14년근속 | L25: =IF(F25=1,"",E25) -> 50162 | N25: =IF(F25=1,"",15+INT((D25-1)/2)) -> 21
... A32: 20 | B32: =DATE(IF($A$5<2,$I$7+A32+1,$I$7+A32),$P$7,$Q$7) -> 52597 | C32: =IF(AND(NOT($C$3="e"),B32>$C$3),1,0) -> 0 | D32: 21 | E32: =DATE($I$7+D32,$J$7,$K$7) -> 52719 | F32: =IF(AND(NOT($C$3="e"),E32>$C$3),1,0) -> 0 | G32: =IF(C32=1,"",A32+2&"년차") -> 22년차 | H32: =IF(C32=1,"",B32) -> 52597 | I32: =IF(C32=1,"",15+INT((A32+IF($F$6=1,0,1)-IF(AND($F$6=1,$A$5=1),0,1))/2)) -> 24 | J32: =IF(F32=1,"",D32&"년근속") -> 21년근속 | L32: =IF(F32=1,"",E32) -> 52719 | N32: =IF(F32=1,"",15+INT((D32-1)/2)) -> 25
A33: 21 | B33: =DATE(IF($A$5<2,$I$7+A33+1,$I$7+A33),$P$7,$Q$7) -> 52963 | C33: =IF(AND(NOT($C$3="e"),B33>$C$3),1,0) -> 0 | D33: 22 | E33: =DATE($I$7+D33,$J$7,$K$7) -> 53084 | F33: =IF(AND(NOT($C$3="e"),E33>$C$3),1,0) -> 0 | G33: =IF(C34>0,"",A34+2&"년차") -> 23년차 | H33: =IF(C34>0,"",IF(C3="e",IF(C34=1,C3+1,B34),"추가 "&A34-A32&"년치")) -> 52963 | I33: =IF(C34>0,"",IF(C3="e",15+INT((A34-1)/2),(A34-A32)*25)) -> 25 | J33: =IF(F34>0,"",D34&"년근속") -> 22년근속 | L33: =IF(F34>0,"",IF(C3="e",E34,"추가 "&D34-D32&"년치")) -> 53084 | N33: =IF(F34>0,"",IF(C3="e",15+INT((D34-1)/2),(D34-D32)*25)) -> 25
A34: =IF(C3="e",A32+1,IF(B3>C3,0,DATEDIF(B3,C3,"y"))) -> 21 | B34: =DATE(IF($A$5<2,$I$7+A34+1,$I$7+A34),$P$7,$Q$7) -> 52963 | C34: =IF(A32>A34-1,2,IF(AND(NOT(C3="e"),B34>C3),1,0)) -> 0 | D34: =IF(C3="e",D32+1,DATEDIF(A3,C3,"y")) -> 22 | E34: =DATE($I$7+D34,$J$7,$K$7) -> 53084 | F34: =IF(D32>D34-1,2,IF(AND(NOT(C3="e"),E34>C3),1,0)) -> 0 | G34: 합 계 | I34: =IF(C3="e","",SUM(I11:I33)) | J34: 합 계 | N34: =IF(C3="e","",SUM(N11:O33)) | P34: =IF($N$34>$I$34,ROUND(N34-I34,1)&"일분","해당없음") -> 해당없음
A35: =A34+1 -> 22 | B35: =DATE(IF($A$5<2,$I$7+A35+1,$I$7+A35),$P$7,$Q$7) -> 53328 | D35: =D34+1 -> 23 | E35: =DATE($I$7+D35,$J$7,$K$7) -> 53449 | G35: ※ 1) 회계연도 기준이 입사일 기준보다 불리하면 안되므로 퇴직시 입사일 기준에 미달할 경우 정산해야 함
G36: 2) 표는 두 기준의 차이에 따른 정산이므로 회계연도 기준의 미지급 수당과 추가수당을 합산 지급해야 함

Sheet 휴가대장
L1: 구분 | M1: 소수점 처리 | O1: 근속년수가산 | X1: 연차휴가 관리대장 | AV1: =IF(TODAY()>=DATE(IF($T$4>3,$R$4+1,$R$4),IF($T$4>3,$T$4-3,$T$4+9),$V$4),"월차 사용촉진을 실시할 경우 "&IF($T$4>3,$R$4+1,$R$4)&"/"&IF($T$4>3,$T$4-3,$T$4+9)&"/"&$V$4&"부터","")
A2: 적용년도 | B2: 연차차감 | C2: 월차 소멸 및 촉진 | L2: 옵션 선택 | M2: 소수점 그대로 | O2: 비례-15-15-16… | AV2: =IF(TODAY()>=DATE(IF($T$4>3,$R$4+1,$R$4),IF($T$4>3,$T$4-3,$T$4+9),$V$4),"다음해 대장도 함께 관리해야 함(기간 불일치)","")
A3: 개 시 일 | B3: 폐 지 일 | C3: 일부적용 | D3: 전부적용 | M3: １일단위 올림 | O3: 비례-15-16-16… | R3: 적 용 년 도 | T3: 회계연도 첫날 | X3: (회계연도 기준) | AV3: 옵션 | AW3: ■ 소수점 처리
A4: =DATE(R4,T4,V4) -> 45658 | B4: 42885 | C4: 43556 | D4: 43921 | M4: 반일단위 올림 | O4: 15-15-16-16… | R4: 2025 | S4: 년 | T4: 1 | U4: 월 | V4: 1 | W4: 일 | AC4: 범례 | AD4: 1차 사용촉진(시기지정·통보 촉구) | AJ4: 2차 사용촉진(시기지정·통보 실시) | AV4: 설정 | AW4: ■ 근속년수 가산
L5: 결과 | M5: 1 | O5: 1
A6: 계산 기초 | E6: 월차 소멸일수 | H6: 촉진일수 배분 | L6: 사용일수 배분 | P6: 잔여일수 | Q6: 번 | R6: 성 명 | S6: 입사일자 | V6: 금년 연차 | X6: 금년 월차 | Z6: 전년이월 월차 | AC6: 사용할 | AD6: 월별 사용일수 (사용촉진 실시한 일수 제외) | AP6: 촉진 가능 | AR6: 촉진가능(선) | AT6: 촉진가능(후) | AV6: 사용 일수 | AX6: 수당 발생 | AZ6: 월차 이월 | BB6: 초과
A7: 회계일:입사일 | B7: 입사일자 | C7: 회계연수 | D7: 초년월수 | E7: 최대일수 | F7: 전년월차 | G7: 금년월차 | H7: 촉진가능 | I7: 전년월차 | J7: 금년연차 | K7: 금년월차 | L7: 사용합계 | M7: 전년월차 | N7: 금년연차 | O7: 금년월차 | P7: 검 증 | S7: 년 | T7: 월 | U7: 일 | V7: 발생 | W7: 직접 | X7: 발생 | Y7: 직접 | Z7: 발생 | AA7: 직접 | AB7: 소진 | AC7: 총일수 | AD7: =IF($T$4>12,$T$4-12,$T$4)&"월" -> 1월 | AE7: =IF($T$4>11,$T$4-11,$T$4+1)&"월" -> 2월 | AF7: =IF($T$4>10,$T$4-10,$T$4+2)&"월" -> 3월 | AG7: =IF($T$4>9,$T$4-9,$T$4+3)&"월" -> 4월 | AH7: =IF($T$4>8,$T$4-8,$T$4+4)&"월" -> 5월 | AI7: =IF($T$4>7,$T$4-7,$T$4+5)&"월" -> 6월 | AJ7: =IF($T$4>6,$T$4-6,$T$4+6)&"월" -> 7월 | AK7: =IF($T$4>5,$T$4-5,$T$4+7)&"월" -> 8월 | AL7: =IF($T$4>4,$T$4-4,$T$4+8)&"월" -> 9월 | AM7: =IF($T$4>3,$T$4-3,$T$4+9)&"월" -> 10월 | AN7: =IF($T$4>2,$T$4-2,$T$4+10)&"월" -> 11월 | AO7: =IF($T$4>1,$T$4-1,$T$4+11)&"월" -> 12월 | AP7: 연차 | AQ7: 실시 | AR7: 월차 | AS7: 실시 | AT7: 월차 | AU7: 실시 | AV7: 연차 | AW7: 월차 | AX7: 연차 | AY7: 월차 | AZ7: 발생 | BA7: 소진 | BB7: 사용
A8: =IF(S8="",3,IF(T8*100+U8>$T$4*100+$V$4,0,IF(T8*100+U8=$T$4*100+$V$4,1,2))) -> 0 | B8: =IF(A8>2,"",DATE(S8,T8,U8)) -> 45047 | C8: =IF(A8>2,"",IF(B8>=$A$4,0,DATEDIF(B8,$A$4,"y"))) -> 1 | D8: =IF(A8>2,"",IF(B8<$A$4,DATEDIF(B8,$A$4,"m")-C8*12+IF(A8=1,1,0),DATEDIF(B8,DATE($R$4+1,$T$4,$V$4),"m"))-IF(U8=$V$4,1,0)) -> 7 | E8: =IF(A8>2,"",IF(OR(C8>1,B8<$C$4),0,IF(DATEDIF($C$4,B8,"m")>11,11,DATEDIF($C$4,B8,"m")))) -> 11 | F8: =IF(A8>2,"",IF(AND(C8=0,B8<=$A$4),IF($A$4<$D$4,0,IF(IF(AA8="",Z8,AA8)-AB8<E8,IF(AA8="",Z8,AA8)-AB8,E8-G8)),0)) -> 0 | G8: =IF(A8>2,"",IF(AND(C8=0,B8<=$A$4),IF($A$4<$D$4,IF(IF(Y8="",X8,Y8)<E8,IF(Y8="",X8,Y8),E8),IF(Y8="",X8,Y8)),0)) -> 0 | H8: =IF(A8>2,"",IF(IF(AA8="",Z8,AA8)-AB8-M8>F8,F8,IF(AA8="",Z8,AA8)-AB8-M8)+IF(IF(Y8="",X8,Y8)-O8>G8,G8,IF(Y8="",X8,Y8)-O8)) -> 0 | I8: =IF(A8>2,"",IF(AS8+AU8-IF(AU8<G8,AU8,G8)>F8,F8,AS8+AU8-IF(AU8<G8,AU8,G8))) -> 0 | J8: =IF(A8>2,"",IF(IF(W8="",V8,W8)<AQ8,IF(W8="",V8,W8),AQ8)) -> 0 | K8: =IF(A8>2,"",IF(AS8+AU8-IF(AU8<G8,AU8,G8)>F8,AS8+AU8-F8,IF(AU8<G8,AU8,G8))) -> 0 | L8: =IF(A8>2,"",SUM(AD8:AO8)) -> 0 | M8: =IF(A8>2,"",IF(IF(AA8="",Z8,AA8)-AB8-I8<L8,IF(AA8="",Z8,AA8)-AB8-I8,L8)) -> 0 | N8: =IF(A8>2,"",IF(IF(AA8="",Z8,AA8)-AB8+IF(W8="",V8,W8)-I8-J8<L8,IF(AA8="",Z8,AA8)-AB8+IF(W8="",V8,W8)-I8-J8-M8,L8-M8)) -> 0 | O8: =IF(A8>2,"",IF(AC8-I8-J8-K8<L8,AC8-I8-J8-K8-M8-N8,L8-M8-N8)) -> 0 | P8: =IF(A8>2,"",AC8-SUM(I8:L8)) -> 15 | Q8: 1 | R8: 박문식 | S8: 2023 | T8: 5 | U8: 1 | V8: =IF(A8>2,"",IF(C8>0,IF(C8=1,15,IF(C8>20,25,15+INT((C8+IF($O$5=1,0,1)-1)/2))),IF(B8<$A$4,IF($O$5=3,15,IF($M$5=1,15*($A$4-B8)/365,IF($M$5=2,ROUNDUP(15*($A$4-B8)/365,0),ROUNDUP(15*($A$4-B8)/365*2,0)/2))),0))) -> 15 | X8: =IF(A8>2,"",IF(C8>0,0,IF(B8<$A$4,11-D8,D8))) -> 0 | Z8: =IF(A8>2,"",IF(OR(B8<$B$4,B8>=$A$4),0,IF(C8=0,D8,IF(AND(C8=1,B8<$D$4),IF(11-D8>IF(B8>=$C$4,E8,0),11-D8-IF(B8>=$C$4,E8,0),0),0)))) -> 0 | AB8: 0 | AC8: =IF(A8>2,"",IF(W8="",V8,W8)+IF(Y8="",X8,Y8)+IF(AA8="",Z8,AA8)-AB8) -> 15 | AP8: =IF(A8>2,"",IF(W8="",V8,W8)-N8) -> 15 | AR8: =IF(A8>2,"",IF(H8>2,H8-2,0)) -> 0 | AT8: =IF(A8>2,"",IF(H8>2,2,H8)) -> 0 | AV8: =IF(A8>2,"",J8+N8) -> 0 | AW8: =IF(A8>2,"",I8+K8+M8+O8) -> 0 | AX8: =IF(A8>2,"",IF(W8="",V8,W8)-AV8) -> 15 | AY8: =IF(A8>2,"",IF(AND(C8<2,B8<=$A$4,B8>=$B$4),IF(AA8="",Z8,AA8)-AB8-I8-M8+IF(B8<$C$4,0,IF(AND(B8<$D$4,O8<IF(Y8="",X8,Y8)-G8),G8-K8,IF(Y8="",X8,Y8)-K8-O8)),0)) -> 0 | AZ8: =IF(A8>2,"",IF(B8>=$B$4,IF(Y8="",X8,Y8)-IF(B8<=$A$4,G8,0),0)) -> 0 | BA8: =IF(A8>2,"",IF(B8>=$B$4,IF(K8+O8>AZ8,AZ8,K8+O8),0)) -> 0 | BB8: =IF(A8>2,"",IF(P8>=0,"",-P8))
A9: =IF(S9="",3,IF(T9*100+U9>$T$4*100+$V$4,0,IF(T9*100+U9=$T$4*100+$V$4,1,2))) -> 0 | B9: =IF(A9>2,"",DATE(S9,T9,U9)) -> 45383 | C9: =IF(A9>2,"",IF(B9>=$A$4,0,DATEDIF(B9,$A$4,"y"))) -> 0 | D9: =IF(A9>2,"",IF(B9<$A$4,DATEDIF(B9,$A$4,"m")-C9*12+IF(A9=1,1,0),DATEDIF(B9,DATE($R$4+1,$T$4,$V$4),"m"))-IF(U9=$V$4,1,0)) -> 8 | E9: =IF(A9>2,"",IF(OR(C9>1,B9<$C$4),0,IF(DATEDIF($C$4,B9,"m")>11,11,DATEDIF($C$4,B9,"m")))) -> 11 | F9: =IF(A9>2,"",IF(AND(C9=0,B9<=$A$4),IF($A$4<$D$4,0,IF(IF(AA9="",Z9,AA9)-AB9<E9,IF(AA9="",Z9,AA9)-AB9,E9-G9)),0)) -> 0 | G9: =IF(A9>2,"",IF(AND(C9=0,B9<=$A$4),IF($A$4<$D$4,IF(IF(Y9="",X9,Y9)<E9,IF(Y9="",X9,Y9),E9),IF(Y9="",X9,Y9)),0)) -> 3 | H9: =IF(A9>2,"",IF(IF(AA9="",Z9,AA9)-AB9-M9>F9,F9,IF(AA9="",Z9,AA9)-AB9-M9)+IF(IF(Y9="",X9,Y9)-O9>G9,G9,IF(Y9="",X9,Y9)-O9)) -> 3 | I9: =IF(A9>2,"",IF(AS9+AU9-IF(AU9<G9,AU9,G9)>F9,F9,AS9+AU9-IF(AU9<G9,AU9,G9))) -> 0 | J9: =IF(A9>2,"",IF(IF(W9="",V9,W9)<AQ9,IF(W9="",V9,W9),AQ9)) -> 0 | K9: =IF(A9>2,"",IF(AS9+AU9-IF(AU9<G9,AU9,G9)>F9,AS9+AU9-F9,IF(AU9<G9,AU9,G9))) -> 0 | L9: =IF(A9>2,"",SUM(AD9:AO9)) -> 0 | M9: =IF(A9>2,"",IF(IF(AA9="",Z9,AA9)-AB9-I9<L9,IF(AA9="",Z9,AA9)-AB9-I9,L9)) -> 0 | N9: =IF(A9>2,"",IF(IF(AA9="",Z9,AA9)-AB9+IF(W9="",V9,W9)-I9-J9<L9,IF(AA9="",Z9,AA9)-AB9+IF(W9="",V9,W9)-I9-J9-M9,L9-M9)) -> 0 | O9: =IF(A9>2,"",IF(AC9-I9-J9-K9<L9,AC9-I9-J9-K9-M9-N9,L9-M9-N9)) -> 0 | P9: =IF(A9>2,"",AC9-SUM(I9:L9)) -> 14.30137 | Q9: 2 | R9: 장길석 | S9: 2024 | T9: 4 | U9: 1 | V9: =IF(A9>2,"",IF(C9>0,IF(C9=1,15,IF(C9>20,25,15+INT((C9+IF($O$5=1,0,1)-1)/2))),IF(B9<$A$4,IF($O$5=3,15,IF($M$5=1,15*($A$4-B9)/365,IF($M$5=2,ROUNDUP(15*($A$4-B9)/365,0),ROUNDUP(15*($A$4-B9)/365*2,0)/2))),0))) -> 11.30137 | X9: =IF(A9>2,"",IF(C9>0,0,IF(B9<$A$4,11-D9,D9))) -> 3 | Z9: =IF(A9>2,"",IF(OR(B9<$B$4,B9>=$A$4),0,IF(C9=0,D9,IF(AND(C9=1,B9<$D$4),IF(11-D9>IF(B9>=$C$4,E9,0),11-D9-IF(B9>=$C$4,E9,0),0),0)))) -> 8 | AB9: 8 | AC9: =IF(A9>2,"",IF(W9="",V9,W9)+IF(Y9="",X9,Y9)+IF(AA9="",Z9,AA9)-AB9) -> 14.30137 | AP9: =IF(A9>2,"",IF(W9="",V9,W9)-N9) -> 11.30137 | AR9: =IF(A9>2,"",IF(H9>2,H9-2,0)) -> 1 | AT9: =IF(A9>2,"",IF(H9>2,2,H9)) -> 2 | AV9: =IF(A9>2,"",J9+N9) -> 0 | AW9: =IF(A9>2,"",I9+K9+M9+O9) -> 0 | AX9: =IF(A9>2,"",IF(W9="",V9,W9)-AV9) -> 11.30137 | AY9: =IF(A9>2,"",IF(AND(C9<2,B9<=$A$4,B9>=$B$4),IF(AA9="",Z9,AA9)-AB9-I9-M9+IF(B9<$C$4,0,IF(AND(B9<$D$4,O9<IF(Y9="",X9,Y9)-G9),G9-K9,IF(Y9="",X9,Y9)-K9-O9)),0)) -> 3 | AZ9: =IF(A9>2,"",IF(B9>=$B$4,IF(Y9="",X9,Y9)-IF(B9<=$A$4,G9,0),0)) -> 0 | BA9: =IF(A9>2,"",IF(B9>=$B$4,IF(K9+O9>AZ9,AZ9,K9+O9),0)) -> 0 | BB9: =IF(A9>2,"",IF(P9>=0,"",-P9))
A10: =IF(S10="",3,IF(T10*100+U10>$T$4*100+$V$4,0,IF(T10*100+U10=$T$4*100+$V$4,1,2))) -> 0 | B10: =IF(A10>2,"",DATE(S10,T10,U10)) -> 45383 | C10: =IF(A10>2,"",IF(B10>=$A$4,0,DATEDIF(B10,$A$4,"y"))) -> 0 | D10: =IF(A10>2,"",IF(B10<$A$4,DATEDIF(B10,$A$4,"m")-C10*12+IF(A10=1,1,0),DATEDIF(B10,DATE($R$4+1,$T$4,$V$4),"m"))-IF(U10=$V$4,1,0)) -> 8 | E10: =IF(A10>2,"",IF(OR(C10>1,B10<$C$4),0,IF(DATEDIF($C$4,B10,"m")>11,11,DATEDIF($C$4,B10,"m")))) -> 11 | F10: =IF(A10>2,"",IF(AND(C10=0,B10<=$A$4),IF($A$4<$D$4,0,IF(IF(AA10="",Z10,AA10)-AB10<E10,IF(AA10="",Z10,AA10)-AB10,E10-G10)),0)) -> 0 | G10: =IF(A10>2,"",IF(AND(C10=0,B10<=$A$4),IF($A$4<$D$4,IF(IF(Y10="",X10,Y10)<E10,IF(Y10="",X10,Y10),E10),IF(Y10="",X10,Y10)),0)) -> 3 | H10: =IF(A10>2,"",IF(IF(AA10="",Z10,AA10)-AB10-M10>F10,F10,IF(AA10="",Z10,AA10)-AB10-M10)+IF(IF(Y10="",X10,Y10)-O10>G10,G10,IF(Y10="",X10,Y10)-O10)) -> 3 | I10: =IF(A10>2,"",IF(AS10+AU10-IF(AU10<G10,AU10,G10)>F10,F10,AS10+AU10-IF(AU10<G10,AU10,G10))) -> 0 | J10: =IF(A10>2,"",IF(IF(W10="",V10,W10)<AQ10,IF(W10="",V10,W10),AQ10)) -> 0 | K10: =IF(A10>2,"",IF(AS10+AU10-IF(AU10<G10,AU10,G10)>F10,AS10+AU10-F10,IF(AU10<G10,AU10,G10))) -> 0 | L10: =IF(A10>2,"",SUM(AD10:AO10)) -> 1 | M10: =IF(A10>2,"",IF(IF(AA10="",Z10,AA10)-AB10-I10<L10,IF(AA10="",Z10,AA10)-AB10-I10,L10)) -> 0 | N10: =IF(A10>2,"",IF(IF(AA10="",Z10,AA10)-AB10+IF(W10="",V10,W10)-I10-J10<L10,IF(AA10="",Z10,AA10)-AB10+IF(W10="",V10,W10)-I10-J10-M10,L10-M10)) -> 1 | O10: =IF(A10>2,"",IF(AC10-I10-J10-K10<L10,AC10-I10-J10-K10-M10-N10,L10-M10-N10)) -> 0 | P10: =IF(A10>2,"",AC10-SUM(I10:L10)) -> 13.30137 | Q10: 3 | R10: 김현기 | S10: 2024 | T10: 4 | U10: 1 | V10: =IF(A10>2,"",IF(C10>0,IF(C10=1,15,IF(C10>20,25,15+INT((C10+IF($O$5=1,0,1)-1)/2))),IF(B10<$A$4,IF($O$5=3,15,IF($M$5=1,15*($A$4-B10)/365,IF($M$5=2,ROUNDUP(15*($A$4-B10)/365,0),ROUNDUP(15*($A$4-B10)/365*2,0)/2))),0))) -> 11.30137 | X10: =IF(A10>2,"",IF(C10>0,0,IF(B10<$A$4,11-D10,D10))) -> 3 | Z10: =IF(A10>2,"",IF(OR(B10<$B$4,B10>=$A$4),0,IF(C10=0,D10,IF(AND(C10=1,B10<$D$4),IF(11-D10>IF(B10>=$C$4,E10,0),11-D10-IF(B10>=$C$4,E10,0),0),0)))) -> 8 | AB10: 8 | AC10: =IF(A10>2,"",IF(W10="",V10,W10)+IF(Y10="",X10,Y10)+IF(AA10="",Z10,AA10)-AB10) -> 14.30137 | AD10: 1 | AP10: =IF(A10>2,"",IF(W10="",V10,W10)-N10) -> 10.30137 | AR10: =IF(A10>2,"",IF(H10>2,H10-2,0)) -> 1 | AT10: =IF(A10>2,"",IF(H10>2,2,H10)) -> 2 | AV10: =IF(A10>2,"",J10+N10) -> 1 | AW10: =IF(A10>2,"",I10+K10+M10+O10) -> 0 | AX10: =IF(A10>2,"",IF(W10="",V10,W10)-AV10) -> 10.30137 | AY10: =IF(A10>2,"",IF(AND(C10<2,B10<=$A$4,B10>=$B$4),IF(AA10="",Z10,AA10)-AB10-I10-M10+IF(B10<$C$4,0,IF(AND(B10<$D$4,O10<IF(Y10="",X10,Y10)-G10),G10-K10,IF(Y10="",X10,Y10)-K10-O10)),0)) -> 3 | AZ10: =IF(A10>2,"",IF(B10>=$B$4,IF(Y10="",X10,Y10)-IF(B10<=$A$4,G10,0),0)) -> 0 | BA10: =IF(A10>2,"",IF(B10>=$B$4,IF(K10+O10>AZ10,AZ10,K10+O10),0)) -> 0 | BB10: =IF(A10>2,"",IF(P10>=0,"",-P10))
A11: =IF(S11="",3,IF(T11*100+U11>$T$4*100+$V$4,0,IF(T11*100+U11=$T$4*100+$V$4,1,2))) -> 0 | B11: =IF(A11>2,"",DATE(S11,T11,U11)) -> 45444 | C11: =IF(A11>2,"",IF(B11>=$A$4,0,DATEDIF(B11,$A$4,"y"))) -> 0 | D11: =IF(A11>2,"",IF(B11<$A$4,DATEDIF(B11,$A$4,"m")-C11*12+IF(A11=1,1,0),DATEDIF(B11,DATE($R$4+1,$T$4,$V$4),"m"))-IF(U11=$V$4,1,0)) -> 6 | E11: =IF(A11>2,"",IF(OR(C11>1,B11<$C$4),0,IF(DATEDIF($C$4,B11,"m")>11,11,DATEDIF($C$4,B11,"m")))) -> 11 | F11: =IF(A11>2,"",IF(AND(C11=0,B11<=$A$4),IF($A$4<$D$4,0,IF(IF(AA11="",Z11,AA11)-AB11<E11,IF(AA11="",Z11,AA11)-AB11,E11-G11)),0)) -> 0 | G11: =IF(A11>2,"",IF(AND(C11=0,B11<=$A$4),IF($A$4<$D$4,IF(IF(Y11="",X11,Y11)<E11,IF(Y11="",X11,Y11),E11),IF(Y11="",X11,Y11)),0)) -> 5 | H11: =IF(A11>2,"",IF(IF(AA11="",Z11,AA11)-AB11-M11>F11,F11,IF(AA11="",Z11,AA11)-AB11-M11)+IF(IF(Y11="",X11,Y11)-O11>G11,G11,IF(Y11="",X11,Y11)-O11)) -> 1.7763568e-15 | I11: =IF(A11>2,"",IF(AS11+AU11-IF(AU11<G11,AU11,G11)>F11,F11,AS11+AU11-IF(AU11<G11,AU11,G11))) -> 0 | J11: =IF(A11>2,"",IF(IF(W11="",V11,W11)<AQ11,IF(W11="",V11,W11),AQ11)) -> 0 | K11: =IF(A11>2,"",IF(AS11+AU11-IF(AU11<G11,AU11,G11)>F11,AS11+AU11-F11,IF(AU11<G11,AU11,G11))) -> 0 | L11: =IF(A11>2,"",SUM(AD11:AO11)) -> 14 | M11: =IF(A11>2,"",IF(IF(AA11="",Z11,AA11)-AB11-I11<L11,IF(AA11="",Z11,AA11)-AB11-I11,L11)) -> 0 | N11: =IF(A11>2,"",IF(IF(AA11="",Z11,AA11)-AB11+IF(W11="",V11,W11)-I11-J11<L11,IF(AA11="",Z11,AA11)-AB11+IF(W11="",V11,W11)-I11-J11-M11,L11-M11)) -> 8.7945205 | O11: =IF(A11>2,"",IF(AC11-I11-J11-K11<L11,AC11-I11-J11-K11-M11-N11,L11-M11-N11)) -> 5 | P11: =IF(A11>2,"",AC11-SUM(I11:L11)) -> -0.20547945 | Q11: 4 | R11: 김승희 | S11: 2024 | T11: 6 | U11: 1 | V11: =IF(A11>2,"",IF(C11>0,IF(C11=1,15,IF(C11>20,25,15+INT((C11+IF($O$5=1,0,1)-1)/2))),IF(B11<$A$4,IF($O$5=3,15,IF($M$5=1,15*($A$4-B11)/365,IF($M$5=2,ROUNDUP(15*($A$4-B11)/365,0),ROUNDUP(15*($A$4-B11)/365*2,0)/2))),0))) -> 8.7945205 | X11: =IF(A11>2,"",IF(C11>0,0,IF(B11<$A$4,11-D11,D11))) -> 5 | Z11: =IF(A11>2,"",IF(OR(B11<$B$4,B11>=$A$4),0,IF(C11=0,D11,IF(AND(C11=1,B11<$D$4),IF(11-D11>IF(B11>=$C$4,E11,0),11-D11-IF(B11>=$C$4,E11,0),0),0)))) -> 6 | AB11: 6 | AC11: =IF(A11>2,"",IF(W11="",V11,W11)+IF(Y11="",X11,Y11)+IF(AA11="",Z11,AA11)-AB11) -> 13.794521 | AD11: 1 | AE11: 1 | AF11: 11 | AG11: 1 | AP11: =IF(A11>2,"",IF(W11="",V11,W11)-N11) -> 0 | AR11: =IF(A11>2,"",IF(H11>2,H11-2,0)) -> 0 | AT11: =IF(A11>2,"",IF(H11>2,2,H11)) -> 1.7763568e-15 | AV11: =IF(A11>2,"",J11+N11) -> 8.7945205 | AW11: =IF(A11>2,"",I11+K11+M11+O11) -> 5 | AX11: =IF(A11>2,"",IF(W11="",V11,W11)-AV11) -> 0 | AY11: =IF(A11>2,"",IF(AND(C11<2,B11<=$A$4,B11>=$B$4),IF(AA11="",Z11,AA11)-AB11-I11-M11+IF(B11<$C$4,0,IF(AND(B11<$D$4,O11<IF(Y11="",X11,Y11)-G11),G11-K11,IF(Y11="",X11,Y11)-K11-O11)),0)) -> 1.7763568e-15 | AZ11: =IF(A11>2,"",IF(B11>=$B$4,IF(Y11="",X11,Y11)-IF(B11<=$A$4,G11,0),0)) -> 0 | BA11: =IF(A11>2,"",IF(B11>=$B$4,IF(K11+O11>AZ11,AZ11,K11+O11),0)) -> 0 | BB11: =IF(A11>2,"",IF(P11>=0,"",-P11)) -> 0.20547945
A12: =IF(S12="",3,IF(T12*100+U12>$T$4*100+$V$4,0,IF(T12*100+U12=$T$4*100+$V$4,1,2))) -> 3 | B12: =IF(A12>2,"",DATE(S12,T12,U12)) | C12: =IF(A12>2,"",IF(B12>=$A$4,0,DATEDIF(B12,$A$4,"y"))) | D12: =IF(A12>2,"",IF(B12<$A$4,DATEDIF(B12,$A$4,"m")-C12*12+IF(A12=1,1,0),DATEDIF(B12,DATE($R$4+1,$T$4,$V$4),"m"))-IF(U12=$V$4,1,0)) | E12: =IF(A12>2,"",IF(OR(C12>1,B12<$C$4),0,IF(DATEDIF($C$4,B12,"m")>11,11,DATEDIF($C$4,B12,"m")))) | F12: =IF(A12>2,"",IF(AND(C12=0,B12<=$A$4),IF($A$4<$D$4,0,IF(IF(AA12="",Z12,AA12)-AB12<E12,IF(AA12="",Z12,AA12)-AB12,E12-G12)),0)) | G12: =IF(A12>2,"",IF(AND(C12=0,B12<=$A$4),IF($A$4<$D$4,IF(IF(Y12="",X12,Y12)<E12,IF(Y12="",X12,Y12),E12),IF(Y12="",X12,Y12)),0)) | H12: =IF(A12>2,"",IF(IF(AA12="",Z12,AA12)-AB12-M12>F12,F12,IF(AA12="",Z12,AA12)-AB12-M12)+IF(IF(Y12="",X12,Y12)-O12>G12,G12,IF(Y12="",X12,Y12)-O12)) | I12: =IF(A12>2,"",IF(AS12+AU12-IF(AU12<G12,AU12,G12)>F12,F12,AS12+AU12-IF(AU12<G12,AU12,G12))) | J12: =IF(A12>2,"",IF(IF(W12="",V12,W12)<AQ12,IF(W12="",V12,W12),AQ12)) | K12: =IF(A12>2,"",IF(AS12+AU12-IF(AU12<G12,AU12,G12)>F12,AS12+AU12-F12,IF(AU12<G12,AU12,G12))) | L12: =IF(A12>2,"",SUM(AD12:AO12)) | M12: =IF(A12>2,"",IF(IF(AA12="",Z12,AA12)-AB12-I12<L12,IF(AA12="",Z12,AA12)-AB12-I12,L12)) | N12: =IF(A12>2,"",IF(IF(AA12="",Z12,AA12)-AB12+IF(W12="",V12,W12)-I12-J12<L12,IF(AA12="",Z12,AA12)-AB12+IF(W12="",V12,W12)-I12-J12-M12,L12-M12)) | O12: =IF(A12>2,"",IF(AC12-I12-J12-K12<L12,AC12-I12-J12-K12-M12-N12,L12-M12-N12)) | P12: =IF(A12>2,"",AC12-SUM(I12:L12)) | Q12: 5 | V12: =IF(A12>2,"",IF(C12>0,IF(C12=1,15,IF(C12>20,25,15+INT((C12+IF($O$5=1,0,1)-1)/2))),IF(B12<$A$4,IF($O$5=3,15,IF($M$5=1,15*($A$4-B12)/365,IF($M$5=2,ROUNDUP(15*($A$4-B12)/365,0),ROUNDUP(15*($A$4-B12)/365*2,0)/2))),0))) | X12: =IF(A12>2,"",IF(C12>0,0,IF(B12<$A$4,11-D12,D12))) | Z12: =IF(A12>2,"",IF(OR(B12<$B$4,B12>=$A$4),0,IF(C12=0,D12,IF(AND(C12=1,B12<$D$4),IF(11-D12>IF(B12>=$C$4,E12,0),11-D12-IF(B12>=$C$4,E12,0),0),0)))) | AC12: =IF(A12>2,"",IF(W12="",V12,W12)+IF(Y12="",X12,Y12)+IF(AA12="",Z12,AA12)-AB12) | AP12: =IF(A12>2,"",IF(W12="",V12,W12)-N12) | AR12: =IF(A12>2,"",IF(H12>2,H12-2,0)) | AT12: =IF(A12>2,"",IF(H12>2,2,H12)) | AV12: =IF(A12>2,"",J12+N12) | AW12: =IF(A12>2,"",I12+K12+M12+O12) | AX12: =IF(A12>2,"",IF(W12="",V12,W12)-AV12) | AY12: =IF(A12>2,"",IF(AND(C12<2,B12<=$A$4,B12>=$B$4),IF(AA12="",Z12,AA12)-AB12-I12-M12+IF(B12<$C$4,0,IF(AND(B12<$D$4,O12<IF(Y12="",X12,Y12)-G12),G12-K12,IF(Y12="",X12,Y12)-K12-O12)),0)) | AZ12: =IF(A12>2,"",IF(B12>=$B$4,IF(Y12="",X12,Y12)-IF(B12<=$A$4,G12,0),0)) | BA12: =IF(A12>2,"",IF(B12>=$B$4,IF(K12+O12>AZ12,AZ12,K12+O12),0)) | BB12: =IF(A12>2,"",IF(P12>=0,"",-P12))
A13: =IF(S13="",3,IF(T13*100+U13>$T$4*100+$V$4,0,IF(T13*100+U13=$T$4*100+$V$4,1,2))) -> 3 | B13: =IF(A13>2,"",DATE(S13,T13,U13)) | C13: =IF(A13>2,"",IF(B13>=$A$4,0,DATEDIF(B13,$A$4,"y"))) | D13: =IF(A13>2,"",IF(B13<$A$4,DATEDIF(B13,$A$4,"m")-C13*12+IF(A13=1,1,0),DATEDIF(B13,DATE($R$4+1,$T$4,$V$4),"m"))-IF(U13=$V$4,1,0)) | E13: =IF(A13>2,"",IF(OR(C13>1,B13<$C$4),0,IF(DATEDIF($C$4,B13,"m")>11,11,DATEDIF($C$4,B13,"m")))) | F13: =IF(A13>2,"",IF(AND(C13=0,B13<=$A$4),IF($A$4<$D$4,0,IF(IF(AA13="",Z13,AA13)-AB13<E13,IF(AA13="",Z13,AA13)-AB13,E13-G13)),0)) | G13: =IF(A13>2,"",IF(AND(C13=0,B13<=$A$4),IF($A$4<$D$4,IF(IF(Y13="",X13,Y13)<E13,IF(Y13="",X13,Y13),E13),IF(Y13="",X13,Y13)),0)) | H13: =IF(A13>2,"",IF(IF(AA13="",Z13,AA13)-AB13-M13>F13,F13,IF(AA13="",Z13,AA13)-AB13-M13)+IF(IF(Y13="",X13,Y13)-O13>G13,G13,IF(Y13="",X13,Y13)-O13)) | I13: =IF(A13>2,"",IF(AS13+AU13-IF(AU13<G13,AU13,G13)>F13,F13,AS13+AU13-IF(AU13<G13,AU13,G13))) | J13: =IF(A13>2,"",IF(IF(W13="",V13,W13)<AQ13,IF(W13="",V13,W13),AQ13)) | K13: =IF(A13>2,"",IF(AS13+AU13-IF(AU13<G13,AU13,G13)>F13,AS13+AU13-F13,IF(AU13<G13,AU13,G13))) | L13: =IF(A13>2,"",SUM(AD13:AO13)) | M13: =IF(A13>2,"",IF(IF(AA13="",Z13,AA13)-AB13-I13<L13,IF(AA13="",Z13,AA13)-AB13-I13,L13)) | N13: =IF(A13>2,"",IF(IF(AA13="",Z13,AA13)-AB13+IF(W13="",V13,W13)-I13-J13<L13,IF(AA13="",Z13,AA13)-AB13+IF(W13="",V13,W13)-I13-J13-M13,L13-M13)) | O13: =IF(A13>2,"",IF(AC13-I13-J13-K13<L13,AC13-I13-J13-K13-M13-N13,L13-M13-N13)) | P13: =IF(A13>2,"",AC13-SUM(I13:L13)) | Q13: 6 | V13: =IF(A13>2,"",IF(C13>0,IF(C13=1,15,IF(C13>20,25,15+INT((C13+IF($O$5=1,0,1)-1)/2))),IF(B13<$A$4,IF($O$5=3,15,IF($M$5=1,15*($A$4-B13)/365,IF($M$5=2,ROUNDUP(15*($A$4-B13)/365,0),ROUNDUP(15*($A$4-B13)/365*2,0)/2))),0))) | X13: =IF(A13>2,"",IF(C13>0,0,IF(B13<$A$4,11-D13,D13))) | Z13: =IF(A13>2,"",IF(OR(B13<$B$4,B13>=$A$4),0,IF(C13=0,D13,IF(AND(C13=1,B13<$D$4),IF(11-D13>IF(B13>=$C$4,E13,0),11-D13-IF(B13>=$C$4,E13,0),0),0)))) | AC13: =IF(A13>2,"",IF(W13="",V13,W13)+IF(Y13="",X13,Y13)+IF(AA13="",Z13,AA13)-AB13) | AP13: =IF(A13>2,"",IF(W13="",V13,W13)-N13) | AR13: =IF(A13>2,"",IF(H13>2,H13-2,0)) | AT13: =IF(A13>2,"",IF(H13>2,2,H13)) | AV13: =IF(A13>2,"",J13+N13) | AW13: =IF(A13>2,"",I13+K13+M13+O13) | AX13: =IF(A13>2,"",IF(W13="",V13,W13)-AV13) | AY13: =IF(A13>2,"",IF(AND(C13<2,B13<=$A$4,B13>=$B$4),IF(AA13="",Z13,AA13)-AB13-I13-M13+IF(B13<$C$4,0,IF(AND(B13<$D$4,O13<IF(Y13="",X13,Y13)-G13),G13-K13,IF(Y13="",X13,Y13)-K13-O13)),0)) | AZ13: =IF(A13>2,"",IF(B13>=$B$4,IF(Y13="",X13,Y13)-IF(B13<=$A$4,G13,0),0)) | BA13: =IF(A13>2,"",IF(B13>=$B$4,IF(K13+O13>AZ13,AZ13,K13+O13),0)) | BB13: =IF(A13>2,"",IF(P13>=0,"",-P13))
A14: =IF(S14="",3,IF(T14*100+U14>$T$4*100+$V$4,0,IF(T14*100+U14=$T$4*100+$V$4,1,2))) -> 3 | B14: =IF(A14>2,"",DATE(S14,T14,U14)) | C14: =IF(A14>2,"",IF(B14>=$A$4,0,DATEDIF(B14,$A$4,"y"))) | D14: =IF(A14>2,"",IF(B14<$A$4,DATEDIF(B14,$A$4,"m")-C14*12+IF(A14=1,1,0),DATEDIF(B14,DATE($R$4+1,$T$4,$V$4),"m"))-IF(U14=$V$4,1,0)) | E14: =IF(A14>2,"",IF(OR(C14>1,B14<$C$4),0,IF(DATEDIF($C$4,B14,"m")>11,11,DATEDIF($C$4,B14,"m")))) | F14: =IF(A14>2,"",IF(AND(C14=0,B14<=$A$4),IF($A$4<$D$4,0,IF(IF(AA14="",Z14,AA14)-AB14<E14,IF(AA14="",Z14,AA14)-AB14,E14-G14)),0)) | G14: =IF(A14>2,"",IF(AND(C14=0,B14<=$A$4),IF($A$4<$D$4,IF(IF(Y14="",X14,Y14)<E14,IF(Y14="",X14,Y14),E14),IF(Y14="",X14,Y14)),0)) | H14: =IF(A14>2,"",IF(IF(AA14="",Z14,AA14)-AB14-M14>F14,F14,IF(AA14="",Z14,AA14)-AB14-M14)+IF(IF(Y14="",X14,Y14)-O14>G14,G14,IF(Y14="",X14,Y14)-O14)) | I14: =IF(A14>2,"",IF(AS14+AU14-IF(AU14<G14,AU14,G14)>F14,F14,AS14+AU14-IF(AU14<G14,AU14,G14))) | J14: =IF(A14>2,"",IF(IF(W14="",V14,W14)<AQ14,IF(W14="",V14,W14),AQ14)) | K14: =IF(A14>2,"",IF(AS14+AU14-IF(AU14<G14,AU14,G14)>F14,AS14+AU14-F14,IF(AU14<G14,AU14,G14))) | L14: =IF(A14>2,"",SUM(AD14:AO14)) | M14: =IF(A14>2,"",IF(IF(AA14="",Z14,AA14)-AB14-I14<L14,IF(AA14="",Z14,AA14)-AB14-I14,L14)) | N14: =IF(A14>2,"",IF(IF(AA14="",Z14,AA14)-AB14+IF(W14="",V14,W14)-I14-J14<L14,IF(AA14="",Z14,AA14)-AB14+IF(W14="",V14,W14)-I14-J14-M14,L14-M14)) | O14: =IF(A14>2,"",IF(AC14-I14-J14-K14<L14,AC14-I14-J14-K14-M14-N14,L14-M14-N14)) | P14: =IF(A14>2,"",AC14-SUM(I14:L14)) | Q14: 7 | V14: =IF(A14>2,"",IF(C14>0,IF(C14=1,15,IF(C14>20,25,15+INT((C14+IF($O$5=1,0,1)-1)/2))),IF(B14<$A$4,IF($O$5=3,15,IF($M$5=1,15*($A$4-B14)/365,IF($M$5=2,ROUNDUP(15*($A$4-B14)/365,0),ROUNDUP(15*($A$4-B14)/365*2,0)/2))),0))) | X14: =IF(A14>2,"",IF(C14>0,0,IF(B14<$A$4,11-D14,D14))) | Z14: =IF(A14>2,"",IF(OR(B14<$B$4,B14>=$A$4),0,IF(C14=0,D14,IF(AND(C14=1,B14<$D$4),IF(11-D14>IF(B14>=$C$4,E14,0),11-D14-IF(B14>=$C$4,E14,0),0),0)))) | AC14: =IF(A14>2,"",IF(W14="",V14,W14)+IF(Y14="",X14,Y14)+IF(AA14="",Z14,AA14)-AB14) | AP14: =IF(A14>2,"",IF(W14="",V14,W14)-N14) | AR14: =IF(A14>2,"",IF(H14>2,H14-2,0)) | AT14: =IF(A14>2,"",IF(H14>2,2,H14)) | AV14: =IF(A14>2,"",J14+N14) | AW14: =IF(A14>2,"",I14+K14+M14+O14) | AX14: =IF(A14>2,"",IF(W14="",V14,W14)-AV14) | AY14: =IF(A14>2,"",IF(AND(C14<2,B14<=$A$4,B14>=$B$4),IF(AA14="",Z14,AA14)-AB14-I14-M14+IF(B14<$C$4,0,IF(AND(B14<$D$4,O14<IF(Y14="",X14,Y14)-G14),G14-K14,IF(Y14="",X14,Y14)-K14-O14)),0)) | AZ14: =IF(A14>2,"",IF(B14>=$B$4,IF(Y14="",X14,Y14)-IF(B14<=$A$4,G14,0),0)) | BA14: =IF(A14>2,"",IF(B14>=$B$4,IF(K14+O14>AZ14,AZ14,K14+O14),0)) | BB14: =IF(A14>2,"",IF(P14>=0,"",-P14))
A15: =IF(S15="",3,IF(T15*100+U15>$T$4*100+$V$4,0,IF(T15*100+U15=$T$4*100+$V$4,1,2))) -> 3 | B15: =IF(A15>2,"",DATE(S15,T15,U15)) | C15: =IF(A15>2,"",IF(B15>=$A$4,0,DATEDIF(B15,$A$4,"y"))) | D15: =IF(A15>2,"",IF(B15<$A$4,DATEDIF(B15,$A$4,"m")-C15*12+IF(A15=1,1,0),DATEDIF(B15,DATE($R$4+1,$T$4,$V$4),"m"))-IF(U15=$V$4,1,0)) | E15: =IF(A15>2,"",IF(OR(C15>1,B15<$C$4),0,IF(DATEDIF($C$4,B15,"m")>11,11,DATEDIF($C$4,B15,"m")))) | F15: =IF(A15>2,"",IF(AND(C15=0,B15<=$A$4),IF($A$4<$D$4,0,IF(IF(AA15="",Z15,AA15)-AB15<E15,IF(AA15="",Z15,AA15)-AB15,E15-G15)),0)) | G15: =IF(A15>2,"",IF(AND(C15=0,B15<=$A$4),IF($A$4<$D$4,IF(IF(Y15="",X15,Y15)<E15,IF(Y15="",X15,Y15),E15),IF(Y15="",X15,Y15)),0)) | H15: =IF(A15>2,"",IF(IF(AA15="",Z15,AA15)-AB15-M15>F15,F15,IF(AA15="",Z15,AA15)-AB15-M15)+IF(IF(Y15="",X15,Y15)-O15>G15,G15,IF(Y15="",X15,Y15)-O15)) | I15: =IF(A15>2,"",IF(AS15+AU15-IF(AU15<G15,AU15,G15)>F15,F15,AS15+AU15-IF(AU15<G15,AU15,G15))) | J15: =IF(A15>2,"",IF(IF(W15="",V15,W15)<AQ15,IF(W15="",V15,W15),AQ15)) | K15: =IF(A15>2,"",IF(AS15+AU15-IF(AU15<G15,AU15,G15)>F15,AS15+AU15-F15,IF(AU15<G15,AU15,G15))) | L15: =IF(A15>2,"",SUM(AD15:AO15)) | M15: =IF(A15>2,"",IF(IF(AA15="",Z15,AA15)-AB15-I15<L15,IF(AA15="",Z15,AA15)-AB15-I15,L15)) | N15: =IF(A15>2,"",IF(IF(AA15="",Z15,AA15)-AB15+IF(W15="",V15,W15)-I15-J15<L15,IF(AA15="",Z15,AA15)-AB15+IF(W15="",V15,W15)-I15-J15-M15,L15-M15)) | O15: =IF(A15>2,"",IF(AC15-I15-J15-K15<L15,AC15-I15-J15-K15-M15-N15,L15-M15-N15)) | P15: =IF(A15>2,"",AC15-SUM(I15:L15)) | Q15: 8 | V15: =IF(A15>2,"",IF(C15>0,IF(C15=1,15,IF(C15>20,25,15+INT((C15+IF($O$5=1,0,1)-1)/2))),IF(B15<$A$4,IF($O$5=3,15,IF($M$5=1,15*($A$4-B15)/365,IF($M$5=2,ROUNDUP(15*($A$4-B15)/365,0),ROUNDUP(15*($A$4-B15)/365*2,0)/2))),0))) | X15: =IF(A15>2,"",IF(C15>0,0,IF(B15<$A$4,11-D15,D15))) | Z15: =IF(A15>2,"",IF(OR(B15<$B$4,B15>=$A$4),0,IF(C15=0,D15,IF(AND(C15=1,B15<$D$4),IF(11-D15>IF(B15>=$C$4,E15,0),11-D15-IF(B15>=$C$4,E15,0),0),0)))) | AC15: =IF(A15>2,"",IF(W15="",V15,W15)+IF(Y15="",X15,Y15)+IF(AA15="",Z15,AA15)-AB15) | AP15: =IF(A15>2,"",IF(W15="",V15,W15)-N15) | AR15: =IF(A15>2,"",IF(H15>2,H15-2,0)) | AT15: =IF(A15>2,"",IF(H15>2,2,H15)) | AV15: =IF(A15>2,"",J15+N15) | AW15: =IF(A15>2,"",I15+K15+M15+O15) | AX15: =IF(A15>2,"",IF(W15="",V15,W15)-AV15) | AY15: =IF(A15>2,"",IF(AND(C15<2,B15<=$A$4,B15>=$B$4),IF(AA15="",Z15,AA15)-AB15-I15-M15+IF(B15<$C$4,0,IF(AND(B15<$D$4,O15<IF(Y15="",X15,Y15)-G15),G15-K15,IF(Y15="",X15,Y15)-K15-O15)),0)) | AZ15: =IF(A15>2,"",IF(B15>=$B$4,IF(Y15="",X15,Y15)-IF(B15<=$A$4,G15,0),0)) | BA15: =IF(A15>2,"",IF(B15>=$B$4,IF(K15+O15>AZ15,AZ15,K15+O15),0)) | BB15: =IF(A15>2,"",IF(P15>=0,"",-P15))
A16: =IF(S16="",3,IF(T16*100+U16>$T$4*100+$V$4,0,IF(T16*100+U16=$T$4*100+$V$4,1,2))) -> 3 | B16: =IF(A16>2,"",DATE(S16,T16,U16)) | C16: =IF(A16>2,"",IF(B16>=$A$4,0,DATEDIF(B16,$A$4,"y"))) | D16: =IF(A16>2,"",IF(B16<$A$4,DATEDIF(B16,$A$4,"m")-C16*12+IF(A16=1,1,0),DATEDIF(B16,DATE($R$4+1,$T$4,$V$4),"m"))-IF(U16=$V$4,1,0)) | E16: =IF(A16>2,"",IF(OR(C16>1,B16<$C$4),0,IF(DATEDIF($C$4,B16,"m")>11,11,DATEDIF($C$4,B16,"m")))) | F16: =IF(A16>2,"",IF(AND(C16=0,B16<=$A$4),IF($A$4<$D$4,0,IF(IF(AA16="",Z16,AA16)-AB16<E16,IF(AA16="",Z16,AA16)-AB16,E16-G16)),0)) | G16: =IF(A16>2,"",IF(AND(C16=0,B16<=$A$4),IF($A$4<$D$4,IF(IF(Y16="",X16,Y16)<E16,IF(Y16="",X16,Y16),E16),IF(Y16="",X16,Y16)),0)) | H16: =IF(A16>2,"",IF(IF(AA16="",Z16,AA16)-AB16-M16>F16,F16,IF(AA16="",Z16,AA16)-AB16-M16)+IF(IF(Y16="",X16,Y16)-O16>G16,G16,IF(Y16="",X16,Y16)-O16)) | I16: =IF(A16>2,"",IF(AS16+AU16-IF(AU16<G16,AU16,G16)>F16,F16,AS16+AU16-IF(AU16<G16,AU16,G16))) | J16: =IF(A16>2,"",IF(IF(W16="",V16,W16)<AQ16,IF(W16="",V16,W16),AQ16)) | K16: =IF(A16>2,"",IF(AS16+AU16-IF(AU16<G16,AU16,G16)>F16,AS16+AU16-F16,IF(AU16<G16,AU16,G16))) | L16: =IF(A16>2,"",SUM(AD16:AO16)) | M16: =IF(A16>2,"",IF(IF(AA16="",Z16,AA16)-AB16-I16<L16,IF(AA16="",Z16,AA16)-AB16-I16,L16)) | N16: =IF(A16>2,"",IF(IF(AA16="",Z16,AA16)-AB16+IF(W16="",V16,W16)-I16-J16<L16,IF(AA16="",Z16,AA16)-AB16+IF(W16="",V16,W16)-I16-J16-M16,L16-M16)) | O16: =IF(A16>2,"",IF(AC16-I16-J16-K16<L16,AC16-I16-J16-K16-M16-N16,L16-M16-N16)) | P16: =IF(A16>2,"",AC16-SUM(I16:L16)) | Q16: 9 | V16: =IF(A16>2,"",IF(C16>0,IF(C16=1,15,IF(C16>20,25,15+INT((C16+IF($O$5=1,0,1)-1)/2))),IF(B16<$A$4,IF($O$5=3,15,IF($M$5=1,15*($A$4-B16)/365,IF($M$5=2,ROUNDUP(15*($A$4-B16)/365,0),ROUNDUP(15*($A$4-B16)/365*2,0)/2))),0))) | X16: =IF(A16>2,"",IF(C16>0,0,IF(B16<$A$4,11-D16,D16))) | Z16: =IF(A16>2,"",IF(OR(B16<$B$4,B16>=$A$4),0,IF(C16=0,D16,IF(AND(C16=1,B16<$D$4),IF(11-D16>IF(B16>=$C$4,E16,0),11-D16-IF(B16>=$C$4,E16,0),0),0)))) | AC16: =IF(A16>2,"",IF(W16="",V16,W16)+IF(Y16="",X16,Y16)+IF(AA16="",Z16,AA16)-AB16) | AP16: =IF(A16>2,"",IF(W16="",V16,W16)-N16) | AR16: =IF(A16>2,"",IF(H16>2,H16-2,0)) | AT16: =IF(A16>2,"",IF(H16>2,2,H16)) | AV16: =IF(A16>2,"",J16+N16) | AW16: =IF(A16>2,"",I16+K16+M16+O16) | AX16: =IF(A16>2,"",IF(W16="",V16,W16)-AV16) | AY16: =IF(A16>2,"",IF(AND(C16<2,B16<=$A$4,B16>=$B$4),IF(AA16="",Z16,AA16)-AB16-I16-M16+IF(B16<$C$4,0,IF(AND(B16<$D$4,O16<IF(Y16="",X16,Y16)-G16),G16-K16,IF(Y16="",X16,Y16)-K16-O16)),0)) | AZ16: =IF(A16>2,"",IF(B16>=$B$4,IF(Y16="",X16,Y16)-IF(B16<=$A$4,G16,0),0)) | BA16: =IF(A16>2,"",IF(B16>=$B$4,IF(K16+O16>AZ16,AZ16,K16+O16),0)) | BB16: =IF(A16>2,"",IF(P16>=0,"",-P16))
A17: =IF(S17="",3,IF(T17*100+U17>$T$4*100+$V$4,0,IF(T17*100+U17=$T$4*100+$V$4,1,2))) -> 3 | B17: =IF(A17>2,"",DATE(S17,T17,U17)) | C17: =IF(A17>2,"",IF(B17>=$A$4,0,DATEDIF(B17,$A$4,"y"))) | D17: =IF(A17>2,"",IF(B17<$A$4,DATEDIF(B17,$A$4,"m")-C17*12+IF(A17=1,1,0),DATEDIF(B17,DATE($R$4+1,$T$4,$V$4),"m"))-IF(U17=$V$4,1,0)) | E17: =IF(A17>2,"",IF(OR(C17>1,B17<$C$4),0,IF(DATEDIF($C$4,B17,"m")>11,11,DATEDIF($C$4,B17,"m")))) | F17: =IF(A17>2,"",IF(AND(C17=0,B17<=$A$4),IF($A$4<$D$4,0,IF(IF(AA17="",Z17,AA17)-AB17<E17,IF(AA17="",Z17,AA17)-AB17,E17-G17)),0)) | G17: =IF(A17>2,"",IF(AND(C17=0,B17<=$A$4),IF($A$4<$D$4,IF(IF(Y17="",X17,Y17)<E17,IF(Y17="",X17,Y17),E17),IF(Y17="",X17,Y17)),0)) | H17: =IF(A17>2,"",IF(IF(AA17="",Z17,AA17)-AB17-M17>F17,F17,IF(AA17="",Z17,AA17)-AB17-M17)+IF(IF(Y17="",X17,Y17)-O17>G17,G17,IF(Y17="",X17,Y17)-O17)) | I17: =IF(A17>2,"",IF(AS17+AU17-IF(AU17<G17,AU17,G17)>F17,F17,AS17+AU17-IF(AU17<G17,AU17,G17))) | J17: =IF(A17>2,"",IF(IF(W17="",V17,W17)<AQ17,IF(W17="",V17,W17),AQ17)) | K17: =IF(A17>2,"",IF(AS17+AU17-IF(AU17<G17,AU17,G17)>F17,AS17+AU17-F17,IF(AU17<G17,AU17,G17))) | L17: =IF(A17>2,"",SUM(AD17:AO17)) | M17: =IF(A17>2,"",IF(IF(AA17="",Z17,AA17)-AB17-I17<L17,IF(AA17="",Z17,AA17)-AB17-I17,L17)) | N17: =IF(A17>2,"",IF(IF(AA17="",Z17,AA17)-AB17+IF(W17="",V17,W17)-I17-J17<L17,IF(AA17="",Z17,AA17)-AB17+IF(W17="",V17,W17)-I17-J17-M17,L17-M17)) | O17: =IF(A17>2,"",IF(AC17-I17-J17-K17<L17,AC17-I17-J17-K17-M17-N17,L17-M17-N17)) | P17: =IF(A17>2,"",AC17-SUM(I17:L17)) | Q17: 10 | V17: =IF(A17>2,"",IF(C17>0,IF(C17=1,15,IF(C17>20,25,15+INT((C17+IF($O$5=1,0,1)-1)/2))),IF(B17<$A$4,IF($O$5=3,15,IF($M$5=1,15*($A$4-B17)/365,IF($M$5=2,ROUNDUP(15*($A$4-B17)/365,0),ROUNDUP(15*($A$4-B17)/365*2,0)/2))),0))) | X17: =IF(A17>2,"",IF(C17>0,0,IF(B17<$A$4,11-D17,D17))) | Z17: =IF(A17>2,"",IF(OR(B17<$B$4,B17>=$A$4),0,IF(C17=0,D17,IF(AND(C17=1,B17<$D$4),IF(11-D17>IF(B17>=$C$4,E17,0),11-D17-IF(B17>=$C$4,E17,0),0),0)))) | AC17: =IF(A17>2,"",IF(W17="",V17,W17)+IF(Y17="",X17,Y17)+IF(AA17="",Z17,AA17)-AB17) | AP17: =IF(A17>2,"",IF(W17="",V17,W17)-N17) | AR17: =IF(A17>2,"",IF(H17>2,H17-2,0)) | AT17: =IF(A17>2,"",IF(H17>2,2,H17)) | AV17: =IF(A17>2,"",J17+N17) | AW17: =IF(A17>2,"",I17+K17+M17+O17) | AX17: =IF(A17>2,"",IF(W17="",V17,W17)-AV17) | AY17: =IF(A17>2,"",IF(AND(C17<2,B17<=$A$4,B17>=$B$4),IF(AA17="",Z17,AA17)-AB17-I17-M17+IF(B17<$C$4,0,IF(AND(B17<$D$4,O17<IF(Y17="",X17,Y17)-G17),G17-K17,IF(Y17="",X17,Y17)-K17-O17)),0)) | AZ17: =IF(A17>2,"",IF(B17>=$B$4,IF(Y17="",X17,Y17)-IF(B17<=$A$4,G17,0),0)) | BA17: =IF(A17>2,"",IF(B17>=$B$4,IF(K17+O17>AZ17,AZ17,K17+O17),0)) | BB17: =IF(A17>2,"",IF(P17>=0,"",-P17))
A18: =IF(S18="",3,IF(T18*100+U18>$T$4*100+$V$4,0,IF(T18*100+U18=$T$4*100+$V$4,1,2))) -> 3 | B18: =IF(A18>2,"",DATE(S18,T18,U18)) | C18: =IF(A18>2,"",IF(B18>=$A$4,0,DATEDIF(B18,$A$4,"y"))) | D18: =IF(A18>2,"",IF(B18<$A$4,DATEDIF(B18,$A$4,"m")-C18*12+IF(A18=1,1,0),DATEDIF(B18,DATE($R$4+1,$T$4,$V$4),"m"))-IF(U18=$V$4,1,0)) | E18: =IF(A18>2,"",IF(OR(C18>1,B18<$C$4),0,IF(DATEDIF($C$4,B18,"m")>11,11,DATEDIF($C$4,B18,"m")))) | F18: =IF(A18>2,"",IF(AND(C18=0,B18<=$A$4),IF($A$4<$D$4,0,IF(IF(AA18="",Z18,AA18)-AB18<E18,IF(AA18="",Z18,AA18)-AB18,E18-G18)),0)) | G18: =IF(A18>2,"",IF(AND(C18=0,B18<=$A$4),IF($A$4<$D$4,IF(IF(Y18="",X18,Y18)<E18,IF(Y18="",X18,Y18),E18),IF(Y18="",X18,Y18)),0)) | H18: =IF(A18>2,"",IF(IF(AA18="",Z18,AA18)-AB18-M18>F18,F18,IF(AA18="",Z18,AA18)-AB18-M18)+IF(IF(Y18="",X18,Y18)-O18>G18,G18,IF(Y18="",X18,Y18)-O18)) | I18: =IF(A18>2,"",IF(AS18+AU18-IF(AU18<G18,AU18,G18)>F18,F18,AS18+AU18-IF(AU18<G18,AU18,G18))) | J18: =IF(A18>2,"",IF(IF(W18="",V18,W18)<AQ18,IF(W18="",V18,W18),AQ18)) | K18: =IF(A18>2,"",IF(AS18+AU18-IF(AU18<G18,AU18,G18)>F18,AS18+AU18-F18,IF(AU18<G18,AU18,G18))) | L18: =IF(A18>2,"",SUM(AD18:AO18)) | M18: =IF(A18>2,"",IF(IF(AA18="",Z18,AA18)-AB18-I18<L18,IF(AA18="",Z18,AA18)-AB18-I18,L18)) | N18: =IF(A18>2,"",IF(IF(AA18="",Z18,AA18)-AB18+IF(W18="",V18,W18)-I18-J18<L18,IF(AA18="",Z18,AA18)-AB18+IF(W18="",V18,W18)-I18-J18-M18,L18-M18)) | O18: =IF(A18>2,"",IF(AC18-I18-J18-K18<L18,AC18-I18-J18-K18-M18-N18,L18-M18-N18)) | P18: =IF(A18>2,"",AC18-SUM(I18:L18)) | Q18: 11 | V18: =IF(A18>2,"",IF(C18>0,IF(C18=1,15,IF(C18>20,25,15+INT((C18+IF($O$5=1,0,1)-1)/2))),IF(B18<$A$4,IF($O$5=3,15,IF($M$5=1,15*($A$4-B18)/365,IF($M$5=2,ROUNDUP(15*($A$4-B18)/365,0),ROUNDUP(15*($A$4-B18)/365*2,0)/2))),0))) | X18: =IF(A18>2,"",IF(C18>0,0,IF(B18<$A$4,11-D18,D18))) | Z18: =IF(A18>2,"",IF(OR(B18<$B$4,B18>=$A$4),0,IF(C18=0,D18,IF(AND(C18=1,B18<$D$4),IF(11-D18>IF(B18>=$C$4,E18,0),11-D18-IF(B18>=$C$4,E18,0),0),0)))) | AC18: =IF(A18>2,"",IF(W18="",V18,W18)+IF(Y18="",X18,Y18)+IF(AA18="",Z18,AA18)-AB18) | AP18: =IF(A18>2,"",IF(W18="",V18,W18)-N18) | AR18: =IF(A18>2,"",IF(H18>2,H18-2,0)) | AT18: =IF(A18>2,"",IF(H18>2,2,H18)) | AV18: =IF(A18>2,"",J18+N18) | AW18: =IF(A18>2,"",I18+K18+M18+O18) | AX18: =IF(A18>2,"",IF(W18="",V18,W18)-AV18) | AY18: =IF(A18>2,"",IF(AND(C18<2,B18<=$A$4,B18>=$B$4),IF(AA18="",Z18,AA18)-AB18-I18-M18+IF(B18<$C$4,0,IF(AND(B18<$D$4,O18<IF(Y18="",X18,Y18)-G18),G18-K18,IF(Y18="",X18,Y18)-K18-O18)),0)) | AZ18: =IF(A18>2,"",IF(B18>=$B$4,IF(Y18="",X18,Y18)-IF(B18<=$A$4,G18,0),0)) | BA18: =IF(A18>2,"",IF(B18>=$B$4,IF(K18+O18>AZ18,AZ18,K18+O18),0)) | BB18: =IF(A18>2,"",IF(P18>=0,"",-P18))
A19: =IF(S19="",3,IF(T19*100+U19>$T$4*100+$V$4,0,IF(T19*100+U19=$T$4*100+$V$4,1,2))) -> 3 | B19: =IF(A19>2,"",DATE(S19,T19,U19)) | C19: =IF(A19>2,"",IF(B19>=$A$4,0,DATEDIF(B19,$A$4,"y"))) | D19: =IF(A19>2,"",IF(B19<$A$4,DATEDIF(B19,$A$4,"m")-C19*12+IF(A19=1,1,0),DATEDIF(B19,DATE($R$4+1,$T$4,$V$4),"m"))-IF(U19=$V$4,1,0)) | E19: =IF(A19>2,"",IF(OR(C19>1,B19<$C$4),0,IF(DATEDIF($C$4,B19,"m")>11,11,DATEDIF($C$4,B19,"m")))) | F19: =IF(A19>2,"",IF(AND(C19=0,B19<=$A$4),IF($A$4<$D$4,0,IF(IF(AA19="",Z19,AA19)-AB19<E19,IF(AA19="",Z19,AA19)-AB19,E19-G19)),0)) | G19: =IF(A19>2,"",IF(AND(C19=0,B19<=$A$4),IF($A$4<$D$4,IF(IF(Y19="",X19,Y19)<E19,IF(Y19="",X19,Y19),E19),IF(Y19="",X19,Y19)),0)) | H19: =IF(A19>2,"",IF(IF(AA19="",Z19,AA19)-AB19-M19>F19,F19,IF(AA19="",Z19,AA19)-AB19-M19)+IF(IF(Y19="",X19,Y19)-O19>G19,G19,IF(Y19="",X19,Y19)-O19)) | I19: =IF(A19>2,"",IF(AS19+AU19-IF(AU19<G19,AU19,G19)>F19,F19,AS19+AU19-IF(AU19<G19,AU19,G19))) | J19: =IF(A19>2,"",IF(IF(W19="",V19,W19)<AQ19,IF(W19="",V19,W19),AQ19)) | K19: =IF(A19>2,"",IF(AS19+AU19-IF(AU19<G19,AU19,G19)>F19,AS19+AU19-F19,IF(AU19<G19,AU19,G19))) | L19: =IF(A19>2,"",SUM(AD19:AO19)) | M19: =IF(A19>2,"",IF(IF(AA19="",Z19,AA19)-AB19-I19<L19,IF(AA19="",Z19,AA19)-AB19-I19,L19)) | N19: =IF(A19>2,"",IF(IF(AA19="",Z19,AA19)-AB19+IF(W19="",V19,W19)-I19-J19<L19,IF(AA19="",Z19,AA19)-AB19+IF(W19="",V19,W19)-I19-J19-M19,L19-M19)) | O19: =IF(A19>2,"",IF(AC19-I19-J19-K19<L19,AC19-I19-J19-K19-M19-N19,L19-M19-N19)) | P19: =IF(A19>2,"",AC19-SUM(I19:L19)) | Q19: 12 | V19: =IF(A19>2,"",IF(C19>0,IF(C19=1,15,IF(C19>20,25,15+INT((C19+IF($O$5=1,0,1)-1)/2))),IF(B19<$A$4,IF($O$5=3,15,IF($M$5=1,15*($A$4-B19)/365,IF($M$5=2,ROUNDUP(15*($A$4-B19)/365,0),ROUNDUP(15*($A$4-B19)/365*2,0)/2))),0))) | X19: =IF(A19>2,"",IF(C19>0,0,IF(B19<$A$4,11-D19,D19))) | Z19: =IF(A19>2,"",IF(OR(B19<$B$4,B19>=$A$4),0,IF(C19=0,D19,IF(AND(C19=1,B19<$D$4),IF(11-D19>IF(B19>=$C$4,E19,0),11-D19-IF(B19>=$C$4,E19,0),0),0)))) | AC19: =IF(A19>2,"",IF(W19="",V19,W19)+IF(Y19="",X19,Y19)+IF(AA19="",Z19,AA19)-AB19) | AP19: =IF(A19>2,"",IF(W19="",V19,W19)-N19) | AR19: =IF(A19>2,"",IF(H19>2,H19-2,0)) | AT19: =IF(A19>2,"",IF(H19>2,2,H19)) | AV19: =IF(A19>2,"",J19+N19) | AW19: =IF(A19>2,"",I19+K19+M19+O19) | AX19: =IF(A19>2,"",IF(W19="",V19,W19)-AV19) | AY19: =IF(A19>2,"",IF(AND(C19<2,B19<=$A$4,B19>=$B$4),IF(AA19="",Z19,AA19)-AB19-I19-M19+IF(B19<$C$4,0,IF(AND(B19<$D$4,O19<IF(Y19="",X19,Y19)-G19),G19-K19,IF(Y19="",X19,Y19)-K19-O19)),0)) | AZ19: =IF(A19>2,"",IF(B19>=$B$4,IF(Y19="",X19,Y19)-IF(B19<=$A$4,G19,0),0)) | BA19: =IF(A19>2,"",IF(B19>=$B$4,IF(K19+O19>AZ19,AZ19,K19+O19),0)) | BB19: =IF(A19>2,"",IF(P19>=0,"",-P19))
A20: =IF(S20="",3,IF(T20*100+U20>$T$4*100+$V$4,0,IF(T20*100+U20=$T$4*100+$V$4,1,2))) -> 3 | B20: =IF(A20>2,"",DATE(S20,T20,U20)) | C20: =IF(A20>2,"",IF(B20>=$A$4,0,DATEDIF(B20,$A$4,"y"))) | D20: =IF(A20>2,"",IF(B20<$A$4,DATEDIF(B20,$A$4,"m")-C20*12+IF(A20=1,1,0),DATEDIF(B20,DATE($R$4+1,$T$4,$V$4),"m"))-IF(U20=$V$4,1,0)) | E20: =IF(A20>2,"",IF(OR(C20>1,B20<$C$4),0,IF(DATEDIF($C$4,B20,"m")>11,11,DATEDIF($C$4,B20,"m")))) | F20: =IF(A20>2,"",IF(AND(C20=0,B20<=$A$4),IF($A$4<$D$4,0,IF(IF(AA20="",Z20,AA20)-AB20<E20,IF(AA20="",Z20,AA20)-AB20,E20-G20)),0)) | G20: =IF(A20>2,"",IF(AND(C20=0,B20<=$A$4),IF($A$4<$D$4,IF(IF(Y20="",X20,Y20)<E20,IF(Y20="",X20,Y20),E20),IF(Y20="",X20,Y20)),0)) | H20: =IF(A20>2,"",IF(IF(AA20="",Z20,AA20)-AB20-M20>F20,F20,IF(AA20="",Z20,AA20)-AB20-M20)+IF(IF(Y20="",X20,Y20)-O20>G20,G20,IF(Y20="",X20,Y20)-O20)) | I20: =IF(A20>2,"",IF(AS20+AU20-IF(AU20<G20,AU20,G20)>F20,F20,AS20+AU20-IF(AU20<G20,AU20,G20))) | J20: =IF(A20>2,"",IF(IF(W20="",V20,W20)<AQ20,IF(W20="",V20,W20),AQ20)) | K20: =IF(A20>2,"",IF(AS20+AU20-IF(AU20<G20,AU20,G20)>F20,AS20+AU20-F20,IF(AU20<G20,AU20,G20))) | L20: =IF(A20>2,"",SUM(AD20:AO20)) | M20: =IF(A20>2,"",IF(IF(AA20="",Z20,AA20)-AB20-I20<L20,IF(AA20="",Z20,AA20)-AB20-I20,L20)) | N20: =IF(A20>2,"",IF(IF(AA20="",Z20,AA20)-AB20+IF(W20="",V20,W20)-I20-J20<L20,IF(AA20="",Z20,AA20)-AB20+IF(W20="",V20,W20)-I20-J20-M20,L20-M20)) | O20: =IF(A20>2,"",IF(AC20-I20-J20-K20<L20,AC20-I20-J20-K20-M20-N20,L20-M20-N20)) | P20: =IF(A20>2,"",AC20-SUM(I20:L20)) | Q20: 13 | V20: =IF(A20>2,"",IF(C20>0,IF(C20=1,15,IF(C20>20,25,15+INT((C20+IF($O$5=1,0,1)-1)/2))),IF(B20<$A$4,IF($O$5=3,15,IF($M$5=1,15*($A$4-B20)/365,IF($M$5=2,ROUNDUP(15*($A$4-B20)/365,0),ROUNDUP(15*($A$4-B20)/365*2,0)/2))),0))) | X20: =IF(A20>2,"",IF(C20>0,0,IF(B20<$A$4,11-D20,D20))) | Z20: =IF(A20>2,"",IF(OR(B20<$B$4,B20>=$A$4),0,IF(C20=0,D20,IF(AND(C20=1,B20<$D$4),IF(11-D20>IF(B20>=$C$4,E20,0),11-D20-IF(B20>=$C$4,E20,0),0),0)))) | AC20: =IF(A20>2,"",IF(W20="",V20,W20)+IF(Y20="",X20,Y20)+IF(AA20="",Z20,AA20)-AB20) | AP20: =IF(A20>2,"",IF(W20="",V20,W20)-N20) | AR20: =IF(A20>2,"",IF(H20>2,H20-2,0)) | AT20: =IF(A20>2,"",IF(H20>2,2,H20)) | AV20: =IF(A20>2,"",J20+N20) | AW20: =IF(A20>2,"",I20+K20+M20+O20) | AX20: =IF(A20>2,"",IF(W20="",V20,W20)-AV20) | AY20: =IF(A20>2,"",IF(AND(C20<2,B20<=$A$4,B20>=$B$4),IF(AA20="",Z20,AA20)-AB20-I20-M20+IF(B20<$C$4,0,IF(AND(B20<$D$4,O20<IF(Y20="",X20,Y20)-G20),G20-K20,IF(Y20="",X20,Y20)-K20-O20)),0)) | AZ20: =IF(A20>2,"",IF(B20>=$B$4,IF(Y20="",X20,Y20)-IF(B20<=$A$4,G20,0),0)) | BA20: =IF(A20>2,"",IF(B20>=$B$4,IF(K20+O20>AZ20,AZ20,K20+O20),0)) | BB20: =IF(A20>2,"",IF(P20>=0,"",-P20))
A21: =IF(S21="",3,IF(T21*100+U21>$T$4*100+$V$4,0,IF(T21*100+U21=$T$4*100+$V$4,1,2))) -> 3 | B21: =IF(A21>2,"",DATE(S21,T21,U21)) | C21: =IF(A21>2,"",IF(B21>=$A$4,0,DATEDIF(B21,$A$4,"y"))) | D21: =IF(A21>2,"",IF(B21<$A$4,DATEDIF(B21,$A$4,"m")-C21*12+IF(A21=1,1,0),DATEDIF(B21,DATE($R$4+1,$T$4,$V$4),"m"))-IF(U21=$V$4,1,0)) | E21: =IF(A21>2,"",IF(OR(C21>1,B21<$C$4),0,IF(DATEDIF($C$4,B21,"m")>11,11,DATEDIF($C$4,B21,"m")))) | F21: =IF(A21>2,"",IF(AND(C21=0,B21<=$A$4),IF($A$4<$D$4,0,IF(IF(AA21="",Z21,AA21)-AB21<E21,IF(AA21="",Z21,AA21)-AB21,E21-G21)),0)) | G21: =IF(A21>2,"",IF(AND(C21=0,B21<=$A$4),IF($A$4<$D$4,IF(IF(Y21="",X21,Y21)<E21,IF(Y21="",X21,Y21),E21),IF(Y21="",X21,Y21)),0)) | H21: =IF(A21>2,"",IF(IF(AA21="",Z21,AA21)-AB21-M21>F21,F21,IF(AA21="",Z21,AA21)-AB21-M21)+IF(IF(Y21="",X21,Y21)-O21>G21,G21,IF(Y21="",X21,Y21)-O21)) | I21: =IF(A21>2,"",IF(AS21+AU21-IF(AU21<G21,AU21,G21)>F21,F21,AS21+AU21-IF(AU21<G21,AU21,G21))) | J21: =IF(A21>2,"",IF(IF(W21="",V21,W21)<AQ21,IF(W21="",V21,W21),AQ21)) | K21: =IF(A21>2,"",IF(AS21+AU21-IF(AU21<G21,AU21,G21)>F21,AS21+AU21-F21,IF(AU21<G21,AU21,G21))) | L21: =IF(A21>2,"",SUM(AD21:AO21)) | M21: =IF(A21>2,"",IF(IF(AA21="",Z21,AA21)-AB21-I21<L21,IF(AA21="",Z21,AA21)-AB21-I21,L21)) | N21: =IF(A21>2,"",IF(IF(AA21="",Z21,AA21)-AB21+IF(W21="",V21,W21)-I21-J21<L21,IF(AA21="",Z21,AA21)-AB21+IF(W21="",V21,W21)-I21-J21-M21,L21-M21)) | O21: =IF(A21>2,"",IF(AC21-I21-J21-K21<L21,AC21-I21-J21-K21-M21-N21,L21-M21-N21)) | P21: =IF(A21>2,"",AC21-SUM(I21:L21)) | Q21: 14 | V21: =IF(A21>2,"",IF(C21>0,IF(C21=1,15,IF(C21>20,25,15+INT((C21+IF($O$5=1,0,1)-1)/2))),IF(B21<$A$4,IF($O$5=3,15,IF($M$5=1,15*($A$4-B21)/365,IF($M$5=2,ROUNDUP(15*($A$4-B21)/365,0),ROUNDUP(15*($A$4-B21)/365*2,0)/2))),0))) | X21: =IF(A21>2,"",IF(C21>0,0,IF(B21<$A$4,11-D21,D21))) | Z21: =IF(A21>2,"",IF(OR(B21<$B$4,B21>=$A$4),0,IF(C21=0,D21,IF(AND(C21=1,B21<$D$4),IF(11-D21>IF(B21>=$C$4,E21,0),11-D21-IF(B21>=$C$4,E21,0),0),0)))) | AC21: =IF(A21>2,"",IF(W21="",V21,W21)+IF(Y21="",X21,Y21)+IF(AA21="",Z21,AA21)-AB21) | AP21: =IF(A21>2,"",IF(W21="",V21,W21)-N21) | AR21: =IF(A21>2,"",IF(H21>2,H21-2,0)) | AT21: =IF(A21>2,"",IF(H21>2,2,H21)) | AV21: =IF(A21>2,"",J21+N21) | AW21: =IF(A21>2,"",I21+K21+M21+O21) | AX21: =IF(A21>2,"",IF(W21="",V21,W21)-AV21) | AY21: =IF(A21>2,"",IF(AND(C21<2,B21<=$A$4,B21>=$B$4),IF(AA21="",Z21,AA21)-AB21-I21-M21+IF(B21<$C$4,0,IF(AND(B21<$D$4,O21<IF(Y21="",X21,Y21)-G21),G21-K21,IF(Y21="",X21,Y21)-K21-O21)),0)) | AZ21: =IF(A21>2,"",IF(B21>=$B$4,IF(Y21="",X21,Y21)-IF(B21<=$A$4,G21,0),0)) | BA21: =IF(A21>2,"",IF(B21>=$B$4,IF(K21+O21>AZ21,AZ21,K21+O21),0)) | BB21: =IF(A21>2,"",IF(P21>=0,"",-P21))
