Workbook

Sheet 서류준비(1세부)
B2: 번호 | C2: 내용 | D2: ETRI
B3: 1 | C3: 표지
C4: 요약문
C5: 최종 목표
C6: 전체내용
C7: 1. 연구개발과제의 필요성
C8: 1-1. 개요
C9: 1-2. 연구개발 대상의 국내외 현황
C10: 2. 연구개발과제의 목표 및 내용
C11: 2-1. 연구개발과제의 최종 목표
C12: 2-2. 연구개발과제의 단계별 목표
C13: 2-3. 연구개발과제의 연구 내용
C14: 2-4. 연구개발과제 수행일정 및 주요 결과물
C15: 3. 연구개발과제의 추진전략.방법 및 추진체계
... C58: 붙임3. 기술준비도 목표
B59: 2 | C59: 신청자격 적정성 및 자기진단서
B60: 3 | C60: 연구개발기관 대표 참여의사 확인서 및 기관 정보활용 동의서
B61: 4 | C61: 참여연구자 개인정보 및 과제정보 수집이용제공 동의서
B62: 5 | C62: 국가연구개발사업 동시수행과제수 준수 확인서
B63: 6 | C63: 주관연구개발기관 연구책임자 국가연구개발사업 과제 현황
B64: 7 | C64: 연구데이터 관리계획
B65: 8 | C65: 기술기여도 산정 근거
B66: 9 | C66: 연구개발기관의 연구개발비 사용 신청서
B67: 10 | C67: 우대사항 증빙서류
B68: 11 | C68: 사업자등록증
B69: 12 | C69: 국세지방세완납증명서/세금분납 계획서 (기업만)
B70: 13 | C70: 회계감사보고서/재무제표 (기업만)

Sheet 연구내용(1세부)
B2: 최종목표 :
B5: RFP 연구내용 | E5: 담당 기관/부서 | F5: 책임자 | G5: 연차별 연구내용
G6: 1년차 | H6: 2년차 | I6: 3년차
B7: [1단계]
B8: ①
C9: -
C10: -
C11: -
B12: ②
C13: -
C14: -
C15: -
B16: ③
C17: -
C18: -
C19: -
B20: [2단계]
B21: ④
C22: -
C23: -
C24: -
B25: ⑤
C26: -
C27: -
C28: -
B29: ⑥
C30: -
C31: -
C32: -

Sheet 성과지표(총괄)
B2: 통합
B3: 구분 | C3: 특허 | G3: 표준화 | M3: 기술이전 | N3: 상용화 (백만원) | O3: 기술료 (백만원) | P3: 성과홍보 | Q3: 시제품 | R3: S/W등록 | S3: 기술문서
C4: 국제 | E4: 국내 | G4: 국제 | J4: 국내
C5: 출원 | D5: 등록 | E5: 출원 | F5: 등록 | G5: 기고서제출 | H5: 기고서채택 | I5: 표준안채택 | J5: 기고서제출 | K5: 기고서채택 | L5: 표준안채택
B6: 1차년도 (2025년) | C6: ='성과지표(1세부)'!C6+'성과지표(2세부)'!C6+'성과지표(3세부)'!C6+'성과지표(4세부)'!C6 -> 0 | D6: ='성과지표(1세부)'!D6+'성과지표(2세부)'!D6+'성과지표(3세부)'!D6+'성과지표(4세부)'!D6 -> 0 | E6: ='성과지표(1세부)'!E6+'성과지표(2세부)'!E6+'성과지표(3세부)'!E6+'성과지표(4세부)'!E6 -> 0 | F6: ='성과지표(1세부)'!F6+'성과지표(2세부)'!F6+'성과지표(3세부)'!F6+'성과지표(4세부)'!F6 -> 0 | G6: ='성과지표(1세부)'!G6+'성과지표(2세부)'!G6+'성과지표(3세부)'!G6+'성과지표(4세부)'!G6 -> 0 | H6: ='성과지표(1세부)'!H6+'성과지표(2세부)'!H6+'성과지표(3세부)'!H6+'성과지표(4세부)'!H6 -> 0 | I6: ='성과지표(1세부)'!I6+'성과지표(2세부)'!I6+'성과지표(3세부)'!I6+'성과지표(4세부)'!I6 -> 0 | J6: ='성과지표(1세부)'!J6+'성과지표(2세부)'!J6+'성과지표(3세부)'!J6+'성과지표(4세부)'!J6 -> 0 | ... S6: ='성과지표(1세부)'!S6+'성과지표(2세부)'!S6+'성과지표(3세부)'!S6+'성과지표(4세부)'!S6 -> 0
B7: 2차년도 (2026년) | C7: ='성과지표(1세부)'!C7+'성과지표(2세부)'!C7+'성과지표(3세부)'!C7+'성과지표(4세부)'!C7 -> 0 | D7: ='성과지표(1세부)'!D7+'성과지표(2세부)'!D7+'성과지표(3세부)'!D7+'성과지표(4세부)'!D7 -> 0 | E7: ='성과지표(1세부)'!E7+'성과지표(2세부)'!E7+'성과지표(3세부)'!E7+'성과지표(4세부)'!E7 -> 0 | F7: ='성과지표(1세부)'!F7+'성과지표(2세부)'!F7+'성과지표(3세부)'!F7+'성과지표(4세부)'!F7 -> 0 | G7: ='성과지표(1세부)'!G7+'성과지표(2세부)'!G7+'성과지표(3세부)'!G7+'성과지표(4세부)'!G7 -> 0 | H7: ='성과지표(1세부)'!H7+'성과지표(2세부)'!H7+'성과지표(3세부)'!H7+'성과지표(4세부)'!H7 -> 0 | I7: ='성과지표(1세부)'!I7+'성과지표(2세부)'!I7+'성과지표(3세부)'!I7+'성과지표(4세부)'!I7 -> 0 | J7: ='성과지표(1세부)'!J7+'성과지표(2세부)'!J7+'성과지표(3세부)'!J7+'성과지표(4세부)'!J7 -> 0 | ... S7: ='성과지표(1세부)'!S7+'성과지표(2세부)'!S7+'성과지표(3세부)'!S7+'성과지표(4세부)'!S7 -> 0
B8: 3차년도 (2027년) | C8: ='성과지표(1세부)'!C8+'성과지표(2세부)'!C8+'성과지표(3세부)'!C8+'성과지표(4세부)'!C8 -> 0 | D8: ='성과지표(1세부)'!D8+'성과지표(2세부)'!D8+'성과지표(3세부)'!D8+'성과지표(4세부)'!D8 -> 0 | E8: ='성과지표(1세부)'!E8+'성과지표(2세부)'!E8+'성과지표(3세부)'!E8+'성과지표(4세부)'!E8 -> 0 | F8: ='성과지표(1세부)'!F8+'성과지표(2세부)'!F8+'성과지표(3세부)'!F8+'성과지표(4세부)'!F8 -> 0 | G8: ='성과지표(1세부)'!G8+'성과지표(2세부)'!G8+'성과지표(3세부)'!G8+'성과지표(4세부)'!G8 -> 0 | H8: ='성과지표(1세부)'!H8+'성과지표(2세부)'!H8+'성과지표(3세부)'!H8+'성과지표(4세부)'!H8 -> 0 | I8: ='성과지표(1세부)'!I8+'성과지표(2세부)'!I8+'성과지표(3세부)'!I8+'성과지표(4세부)'!I8 -> 0 | J8: ='성과지표(1세부)'!J8+'성과지표(2세부)'!J8+'성과지표(3세부)'!J8+'성과지표(4세부)'!J8 -> 0 | ... S8: ='성과지표(1세부)'!S8+'성과지표(2세부)'!S8+'성과지표(3세부)'!S8+'성과지표(4세부)'!S8 -> 0
B9: 4차년도 (2028년) | C9: ='성과지표(1세부)'!C9+'성과지표(2세부)'!C9+'성과지표(3세부)'!C9+'성과지표(4세부)'!C9 -> 0 | D9: ='성과지표(1세부)'!D9+'성과지표(2세부)'!D9+'성과지표(3세부)'!D9+'성과지표(4세부)'!D9 -> 0 | E9: ='성과지표(1세부)'!E9+'성과지표(2세부)'!E9+'성과지표(3세부)'!E9+'성과지표(4세부)'!E9 -> 0 | F9: ='성과지표(1세부)'!F9+'성과지표(2세부)'!F9+'성과지표(3세부)'!F9+'성과지표(4세부)'!F9 -> 0 | G9: ='성과지표(1세부)'!G9+'성과지표(2세부)'!G9+'성과지표(3세부)'!G9+'성과지표(4세부)'!G9 -> 0 | H9: ='성과지표(1세부)'!H9+'성과지표(2세부)'!H9+'성과지표(3세부)'!H9+'성과지표(4세부)'!H9 -> 0 | I9: ='성과지표(1세부)'!I9+'성과지표(2세부)'!I9+'성과지표(3세부)'!I9+'성과지표(4세부)'!I9 -> 0 | J9: ='성과지표(1세부)'!J9+'성과지표(2세부)'!J9+'성과지표(3세부)'!J9+'성과지표(4세부)'!J9 -> 0 | ... S9: ='성과지표(1세부)'!S9+'성과지표(2세부)'!S9+'성과지표(3세부)'!S9+'성과지표(4세부)'!S9 -> 0
B10: 5차년도 (2029년) | C10: ='성과지표(1세부)'!C10+'성과지표(2세부)'!C10+'성과지표(3세부)'!C10+'성과지표(4세부)'!C10 -> 0 | D10: ='성과지표(1세부)'!D10+'성과지표(2세부)'!D10+'성과지표(3세부)'!D10+'성과지표(4세부)'!D10 -> 0 | E10: ='성과지표(1세부)'!E10+'성과지표(2세부)'!E10+'성과지표(3세부)'!E10+'성과지표(4세부)'!E10 -> 0 | F10: ='성과지표(1세부)'!F10+'성과지표(2세부)'!F10+'성과지표(3세부)'!F10+'성과지표(4세부)'!F10 -> 0 | G10: ='성과지표(1세부)'!G10+'성과지표(2세부)'!G10+'성과지표(3세부)'!G10+'성과지표(4세부)'!G10 -> 0 | H10: ='성과지표(1세부)'!H10+'성과지표(2세부)'!H10+'성과지표(3세부)'!H10+'성과지표(4세부)'!H10 -> 0 | I10: ='성과지표(1세부)'!I10+'성과지표(2세부)'!I10+'성과지표(3세부)'!I10+'성과지표(4세부)'!I10 -> 0 | J10: ='성과지표(1세부)'!J10+'성과지표(2세부)'!J10+'성과지표(3세부)'!J10+'성과지표(4세부)'!J10 -> 0 | ... S10: ='성과지표(1세부)'!S10+'성과지표(2세부)'!S10+'성과지표(3세부)'!S10+'성과지표(4세부)'!S10 -> 0
B11: 합계 | C11: =SUM(C6:C10) -> 0 | D11: =SUM(D6:D10) -> 0 | E11: =SUM(E6:E10) -> 0 | F11: =SUM(F6:F10) -> 0 | G11: =SUM(G6:G10) -> 0 | H11: =SUM(H6:H10) -> 0 | I11: =SUM(I6:I10) -> 0 | J11: =SUM(J6:J10) -> 0 | ... S11: =SUM(S6:S10) -> 0

Sheet 성과지표(1세부)
B2: 통합
B3: 구분 | C3: 특허 | G3: 표준화 | M3: 기술이전 | N3: 상용화 (백만원) | O3: 기술료 (백만원) | P3: 성과홍보 | Q3: 시제품 | R3: S/W등록 | S3: 기술문서
C4: 국제 | E4: 국내 | G4: 국제 | J4: 국내
C5: 출원 | D5: 등록 | E5: 출원 | F5: 등록 | G5: 기고서제출 | H5: 기고서채택 | I5: 표준안채택 | J5: 기고서제출 | K5: 기고서채택 | L5: 표준안채택
B6: 1차년도 (2025년) | C6: =C28+C39+C50+C61+C72+C83+C94+C17 -> 0 | D6: =D28+D39+D50+D61+D72+D83+D94+D17 -> 0 | E6: =E28+E39+E50+E61+E72+E83+E94+E17 -> 0 | F6: =F28+F39+F50+F61+F72+F83+F94+F17 -> 0 | G6: =G28+G39+G50+G61+G72+G83+G94+G17 -> 0 | H6: =H28+H39+H50+H61+H72+H83+H94+H17 -> 0 | I6: =I28+I39+I50+I61+I72+I83+I94+I17 -> 0 | J6: =J28+J39+J50+J61+J72+J83+J94+J17 -> 0 | ... S6: =S28+S39+S50+S61+S72+S83+S94+S17 -> 0
B7: 2차년도 (2026년) | C7: =C29+C40+C51+C62+C73+C84+C95+C18 -> 0 | D7: =D29+D40+D51+D62+D73+D84+D95+D18 -> 0 | E7: =E29+E40+E51+E62+E73+E84+E95+E18 -> 0 | F7: =F29+F40+F51+F62+F73+F84+F95+F18 -> 0 | G7: =G29+G40+G51+G62+G73+G84+G95+G18 -> 0 | H7: =H29+H40+H51+H62+H73+H84+H95+H18 -> 0 | I7: =I29+I40+I51+I62+I73+I84+I95+I18 -> 0 | J7: =J29+J40+J51+J62+J73+J84+J95+J18 -> 0 | ... S7: =S29+S40+S51+S62+S73+S84+S95+S18 -> 0
B8: 3차년도 (2027년) | C8: =C30+C41+C52+C63+C74+C85+C96+C19 -> 0 | D8: =D30+D41+D52+D63+D74+D85+D96+D19 -> 0 | E8: =E30+E41+E52+E63+E74+E85+E96+E19 -> 0 | F8: =F30+F41+F52+F63+F74+F85+F96+F19 -> 0 | G8: =G30+G41+G52+G63+G74+G85+G96+G19 -> 0 | H8: =H30+H41+H52+H63+H74+H85+H96+H19 -> 0 | I8: =I30+I41+I52+I63+I74+I85+I96+I19 -> 0 | J8: =J30+J41+J52+J63+J74+J85+J96+J19 -> 0 | ... S8: =S30+S41+S52+S63+S74+S85+S96+S19 -> 0
B9: 4차년도 (2028년) | C9: =C31+C42+C53+C64+C75+C86+C97+C20 -> 0 | D9: =D31+D42+D53+D64+D75+D86+D97+D20 -> 0 | E9: =E31+E42+E53+E64+E75+E86+E97+E20 -> 0 | F9: =F31+F42+F53+F64+F75+F86+F97+F20 -> 0 | G9: =G31+G42+G53+G64+G75+G86+G97+G20 -> 0 | H9: =H31+H42+H53+H64+H75+H86+H97+H20 -> 0 | I9: =I31+I42+I53+I64+I75+I86+I97+I20 -> 0 | J9: =J31+J42+J53+J64+J75+J86+J97+J20 -> 0 | ... S9: =S31+S42+S53+S64+S75+S86+S97+S20 -> 0
B10: 5차년도 (2029년) | C10: =C32+C43+C54+C65+C76+C87+C98+C21 -> 0 | D10: =D32+D43+D54+D65+D76+D87+D98+D21 -> 0 | E10: =E32+E43+E54+E65+E76+E87+E98+E21 -> 0 | F10: =F32+F43+F54+F65+F76+F87+F98+F21 -> 0 | G10: =G32+G43+G54+G65+G76+G87+G98+G21 -> 0 | H10: =H32+H43+H54+H65+H76+H87+H98+H21 -> 0 | I10: =I32+I43+I54+I65+I76+I87+I98+I21 -> 0 | J10: =J32+J43+J54+J65+J76+J87+J98+J21 -> 0 | ... S10: =S32+S43+S54+S65+S76+S87+S98+S21 -> 0
B11: 합계 | C11: =C33+C44+C55+C66+C77+C88+C99+C22 -> 0 | D11: =D33+D44+D55+D66+D77+D88+D99+D22 -> 0 | E11: =E33+E44+E55+E66+E77+E88+E99+E22 -> 0 | F11: =F33+F44+F55+F66+F77+F88+F99+F22 -> 0 | G11: =G33+G44+G55+G66+G77+G88+G99+G22 -> 0 | H11: =H33+H44+H55+H66+H77+H88+H99+H22 -> 0 | I11: =I33+I44+I55+I66+I77+I88+I99+I22 -> 0 | J11: =J33+J44+J55+J66+J77+J88+J99+J22 -> 0 | ... S11: =S33+S44+S55+S66+S77+S88+S99+S22 -> 0
B13: 조정
B14: 구분 | C14: 특허 | G14: 표준화 | M14: 기술이전 | N14: 상용화 (백만원) | O14: 기술료 (백만원) | P14: 성과홍보 | Q14: 시제품 | R14: S/W등록 | S14: 기술문서
C15: 국제 | E15: 국내 | G15: 국제 | J15: 국내
C16: 출원 | D16: 등록 | E16: 출원 | F16: 등록 | G16: 기고서제출 | H16: 기고서채택 | I16: 표준안채택 | J16: 기고서제출 | K16: 기고서채택 | L16: 표준안채택
B17: 1차년도 (2025년)
B18: 2차년도 (2026년)
B19: 3차년도 (2027년)
B20: 4차년도 (2028년)
B21: 5차년도 (2029년)
B22: 합계 | C22: =SUM(C17:C21) -> 0 | D22: =SUM(D17:D21) -> 0 | E22: =SUM(E17:E21) -> 0 | F22: =SUM(F17:F21) -> 0 | G22: =SUM(G17:G21) -> 0 | H22: =SUM(H17:H21) -> 0 | I22: =SUM(I17:I21) -> 0 | J22: =SUM(J17:J21) -> 0 | ... S22: =SUM(S17:S21) -> 0
B24: 기관명
B25: 구분 | C25: 특허 | G25: 표준화 | M25: 기술이전 | N25: 상용화 (백만원) | O25: 기술료 (백만원) | P25: 성과홍보 | Q25: 시제품 | R25: S/W등록 | S25: 기술문서
C26: 국제 | E26: 국내 | G26: 국제 | J26: 국내
C27: 출원 | D27: 등록 | E27: 출원 | F27: 등록 | G27: 기고서제출 | H27: 기고서채택 | I27: 표준안채택 | J27: 기고서제출 | K27: 기고서채택 | L27: 표준안채택
B28: 1차년도 (2025년)
B29: 2차년도 (2026년)
B30: 3차년도 (2027년)
B31: 4차년도 (2028년)
B32: 5차년도 (2029년)
B33: 합계 | C33: =SUM(C28:C32) -> 0 | D33: =SUM(D28:D32) -> 0 | E33: =SUM(E28:E32) -> 0 | F33: =SUM(F28:F32) -> 0 | G33: =SUM(G28:G32) -> 0 | H33: =SUM(H28:H32) -> 0 | I33: =SUM(I28:I32) -> 0 | J33: =SUM(J28:J32) -> 0 | ... S33: =SUM(S28:S32) -> 0
B35: 기관명
B36: 구분 | C36: 특허 | G36: 표준화 | M36: 기술이전 | N36: 상용화 (백만원) | O36: 기술료 (백만원) | P36: 성과홍보 | Q36: 시제품 | R36: S/W등록 | S36: 기술문서
C37: 국제 | E37: 국내 | G37: 국제 | J37: 국내
C38: 출원 | D38: 등록 | E38: 출원 | F38: 등록 | G38: 기고서제출 | H38: 기고서채택 | I38: 표준안채택 | J38: 기고서제출 | K38: 기고서채택 | L38: 표준안채택
B39: 1차년도 (2025년)
B40: 2차년도 (2026년)
B41: 3차년도 (2027년)
B42: 4차년도 (2028년)
B43: 5차년도 (2029년)
B44: 합계 | C44: =SUM(C39:C43) -> 0 | D44: =SUM(D39:D43) -> 0 | E44: =SUM(E39:E43) -> 0 | F44: =SUM(F39:F43) -> 0 | G44: =SUM(G39:G43) -> 0 | H44: =SUM(H39:H43) -> 0 | I44: =SUM(I39:I43) -> 0 | J44: =SUM(J39:J43) -> 0 | ... S44: =SUM(S39:S43) -> 0
...

Sheet 성과지표(2세부)
B2: 통합
B3: 구분 | C3: 특허 | G3: 표준화 | M3: 기술이전 | N3: 상용화 (백만원) | O3: 기술료 (백만원) | P3: 성과홍보 | Q3: 시제품 | R3: S/W등록 | S3: 기술문서
C4: 국제 | E4: 국내 | G4: 국제 | J4: 국내
C5: 출원 | D5: 등록 | E5: 출원 | F5: 등록 | G5: 기고서제출 | H5: 기고서채택 | I5: 표준안채택 | J5: 기고서제출 | K5: 기고서채택 | L5: 표준안채택
B6: 1차년도 (2025년) | C6: =C28+C39+C50+C61+C72+C83+C94+C17 -> 0 | D6: =D28+D39+D50+D61+D72+D83+D94+D17 -> 0 | E6: =E28+E39+E50+E61+E72+E83+E94+E17 -> 0 | F6: =F28+F39+F50+F61+F72+F83+F94+F17 -> 0 | G6: =G28+G39+G50+G61+G72+G83+G94+G17 -> 0 | H6: =H28+H39+H50+H61+H72+H83+H94+H17 -> 0 | I6: =I28+I39+I50+I61+I72+I83+I94+I17 -> 0 | J6: =J28+J39+J50+J61+J72+J83+J94+J17 -> 0 | ... S6: =S28+S39+S50+S61+S72+S83+S94+S17 -> 0
B7: 2차년도 (2026년) | C7: =C29+C40+C51+C62+C73+C84+C95+C18 -> 0 | D7: =D29+D40+D51+D62+D73+D84+D95+D18 -> 0 | E7: =E29+E40+E51+E62+E73+E84+E95+E18 -> 0 | F7: =F29+F40+F51+F62+F73+F84+F95+F18 -> 0 | G7: =G29+G40+G51+G62+G73+G84+G95+G18 -> 0 | H7: =H29+H40+H51+H62+H73+H84+H95+H18 -> 0 | I7: =I29+I40+I51+I62+I73+I84+I95+I18 -> 0 | J7: =J29+J40+J51+J62+J73+J84+J95+J18 -> 0 | ... S7: =S29+S40+S51+S62+S73+S84+S95+S18 -> 0
B8: 3차년도 (2027년) | C8: =C30+C41+C52+C63+C74+C85+C96+C19 -> 0 | D8: =D30+D41+D52+D63+D74+D85+D96+D19 -> 0 | E8: =E30+E41+E52+E63+E74+E85+E96+E19 -> 0 | F8: =F30+F41+F52+F63+F74+F85+F96+F19 -> 0 | G8: =G30+G41+G52+G63+G74+G85+G96+G19 -> 0 | H8: =H30+H41+H52+H63+H74+H85+H96+H19 -> 0 | I8: =I30+I41+I52+I63+I74+I85+I96+I19 -> 0 | J8: =J30+J41+J52+J63+J74+J85+J96+J19 -> 0 | ... S8: =S30+S41+S52+S63+S74+S85+S96+S19 -> 0
B9: 4차년도 (2028년) | C9: =C31+C42+C53+C64+C75+C86+C97+C20 -> 0 | D9: =D31+D42+D53+D64+D75+D86+D97+D20 -> 0 | E9: =E31+E42+E53+E64+E75+E86+E97+E20 -> 0 | F9: =F31+F42+F53+F64+F75+F86+F97+F20 -> 0 | G9: =G31+G42+G53+G64+G75+G86+G97+G20 -> 0 | H9: =H31+H42+H53+H64+H75+H86+H97+H20 -> 0 | I9: =I31+I42+I53+I64+I75+I86+I97+I20 -> 0 | J9: =J31+J42+J53+J64+J75+J86+J97+J20 -> 0 | ... S9: =S31+S42+S53+S64+S75+S86+S97+S20 -> 0
B10: 5차년도 (2029년) | C10: =C32+C43+C54+C65+C76+C87+C98+C21 -> 0 | D10: =D32+D43+D54+D65+D76+D87+D98+D21 -> 0 | E10: =E32+E43+E54+E65+E76+E87+E98+E21 -> 0 | F10: =F32+F43+F54+F65+F76+F87+F98+F21 -> 0 | G10: =G32+G43+G54+G65+G76+G87+G98+G21 -> 0 | H10: =H32+H43+H54+H65+H76+H87+H98+H21 -> 0 | I10: =I32+I43+I54+I65+I76+I87+I98+I21 -> 0 | J10: =J32+J43+J54+J65+J76+J87+J98+J21 -> 0 | ... S10: =S32+S43+S54+S65+S76+S87+S98+S21 -> 0
B11: 합계 | C11: =C33+C44+C55+C66+C77+C88+C99+C22 -> 0 | D11: =D33+D44+D55+D66+D77+D88+D99+D22 -> 0 | E11: =E33+E44+E55+E66+E77+E88+E99+E22 -> 0 | F11: =F33+F44+F55+F66+F77+F88+F99+F22 -> 0 | G11: =G33+G44+G55+G66+G77+G88+G99+G22 -> 0 | H11: =H33+H44+H55+H66+H77+H88+H99+H22 -> 0 | I11: =I33+I44+I55+I66+I77+I88+I99+I22 -> 0 | J11: =J33+J44+J55+J66+J77+J88+J99+J22 -> 0 | ... S11: =S33+S44+S55+S66+S77+S88+S99+S22 -> 0
B13: 조정
B14: 구분 | C14: 특허 | G14: 표준화 | M14: 기술이전 | N14: 상용화 (백만원) | O14: 기술료 (백만원) | P14: 성과홍보 | Q14: 시제품 | R14: S/W등록 | S14: 기술문서
C15: 국제 | E15: 국내 | G15: 국제 | J15: 국내
C16: 출원 | D16: 등록 | E16: 출원 | F16: 등록 | G16: 기고서제출 | H16: 기고서채택 | I16: 표준안채택 | J16: 기고서제출 | K16: 기고서채택 | L16: 표준안채택
B17: 1차년도 (2025년)
B18: 2차년도 (2026년)
B19: 3차년도 (2027년)
B20: 4차년도 (2028년)
B21: 5차년도 (2029년)
B22: 합계 | C22: =SUM(C17:C21) -> 0 | D22: =SUM(D17:D21) -> 0 | E22: =SUM(E17:E21) -> 0 | F22: =SUM(F17:F21) -> 0 | G22: =SUM(G17:G21) -> 0 | H22: =SUM(H17:H21) -> 0 | I22: =SUM(I17:I21) -> 0 | J22: =SUM(J17:J21) -> 0 | ... S22: =SUM(S17:S21) -> 0
B24: 기관명
B25: 구분 | C25: 특허 | G25: 표준화 | M25: 기술이전 | N25: 상용화 (백만원) | O25: 기술료 (백만원) | P25: 성과홍보 | Q25: 시제품 | R25: S/W등록 | S25: 기술문서
C26: 국제 | E26: 국내 | G26: 국제 | J26: 국내
C27: 출원 | D27: 등록 | E27: 출원 | F27: 등록 | G27: 기고서제출 | H27: 기고서채택 | I27: 표준안채택 | J27: 기고서제출 | K27: 기고서채택 | L27: 표준안채택
B28: 1차년도 (2025년)
B29: 2차년도 (2026년)
B30: 3차년도 (2027년)
B31: 4차년도 (2028년)
B32: 5차년도 (2029년)
B33: 합계 | C33: =SUM(C28:C32) -> 0 | D33: =SUM(D28:D32) -> 0 | E33: =SUM(E28:E32) -> 0 | F33: =SUM(F28:F32) -> 0 | G33: =SUM(G28:G32) -> 0 | H33: =SUM(H28:H32) -> 0 | I33: =SUM(I28:I32) -> 0 | J33: =SUM(J28:J32) -> 0 | ... S33: =SUM(S28:S32) -> 0
B35: 기관명
B36: 구분 | C36: 특허 | G36: 표준화 | M36: 기술이전 | N36: 상용화 (백만원) | O36: 기술료 (백만원) | P36: 성과홍보 | Q36: 시제품 | R36: S/W등록 | S36: 기술문서
C37: 국제 | E37: 국내 | G37: 국제 | J37: 국내
C38: 출원 | D38: 등록 | E38: 출원 | F38: 등록 | G38: 기고서제출 | H38: 기고서채택 | I38: 표준안채택 | J38: 기고서제출 | K38: 기고서채택 | L38: 표준안채택
B39: 1차년도 (2025년)
B40: 2차년도 (2026년)
B41: 3차년도 (2027년)
B42: 4차년도 (2028년)
B43: 5차년도 (2029년)
B44: 합계 | C44: =SUM(C39:C43) -> 0 | D44: =SUM(D39:D43) -> 0 | E44: =SUM(E39:E43) -> 0 | F44: =SUM(F39:F43) -> 0 | G44: =SUM(G39:G43) -> 0 | H44: =SUM(H39:H43) -> 0 | I44: =SUM(I39:I43) -> 0 | J44: =SUM(J39:J43) -> 0 | ... S44: =SUM(S39:S43) -> 0
...

Sheet 성과지표(3세부)
B2: 통합
B3: 구분 | C3: 특허 | G3: 표준화 | M3: 기술이전 | N3: 상용화 (백만원) | O3: 기술료 (백만원) | P3: 성과홍보 | Q3: 시제품 | R3: S/W등록 | S3: 기술문서
C4: 국제 | E4: 국내 | G4: 국제 | J4: 국내
C5: 출원 | D5: 등록 | E5: 출원 | F5: 등록 | G5: 기고서제출 | H5: 기고서채택 | I5: 표준안채택 | J5: 기고서제출 | K5: 기고서채택 | L5: 표준안채택
B6: 1차년도 (2025년) | C6: =C28+C39+C50+C61+C72+C83+C94+C17 -> 0 | D6: =D28+D39+D50+D61+D72+D83+D94+D17 -> 0 | E6: =E28+E39+E50+E61+E72+E83+E94+E17 -> 0 | F6: =F28+F39+F50+F61+F72+F83+F94+F17 -> 0 | G6: =G28+G39+G50+G61+G72+G83+G94+G17 -> 0 | H6: =H28+H39+H50+H61+H72+H83+H94+H17 -> 0 | I6: =I28+I39+I50+I61+I72+I83+I94+I17 -> 0 | J6: =J28+J39+J50+J61+J72+J83+J94+J17 -> 0 | ... S6: =S28+S39+S50+S61+S72+S83+S94+S17 -> 0
B7: 2차년도 (2026년) | C7: =C29+C40+C51+C62+C73+C84+C95+C18 -> 0 | D7: =D29+D40+D51+D62+D73+D84+D95+D18 -> 0 | E7: =E29+E40+E51+E62+E73+E84+E95+E18 -> 0 | F7: =F29+F40+F51+F62+F73+F84+F95+F18 -> 0 | G7: =G29+G40+G51+G62+G73+G84+G95+G18 -> 0 | H7: =H29+H40+H51+H62+H73+H84+H95+H18 -> 0 | I7: =I29+I40+I51+I62+I73+I84+I95+I18 -> 0 | J7: =J29+J40+J51+J62+J73+J84+J95+J18 -> 0 | ... S7: =S29+S40+S51+S62+S73+S84+S95+S18 -> 0
B8: 3차년도 (2027년) | C8: =C30+C41+C52+C63+C74+C85+C96+C19 -> 0 | D8: =D30+D41+D52+D63+D74+D85+D96+D19 -> 0 | E8: =E30+E41+E52+E63+E74+E85+E96+E19 -> 0 | F8: =F30+F41+F52+F63+F74+F85+F96+F19 -> 0 | G8: =G30+G41+G52+G63+G74+G85+G96+G19 -> 0 | H8: =H30+H41+H52+H63+H74+H85+H96+H19 -> 0 | I8: =I30+I41+I52+I63+I74+I85+I96+I19 -> 0 | J8: =J30+J41+J52+J63+J74+J85+J96+J19 -> 0 | ... S8: =S30+S41+S52+S63+S74+S85+S96+S19 -> 0
B9: 4차년도 (2028년) | C9: =C31+C42+C53+C64+C75+C86+C97+C20 -> 0 | D9: =D31+D42+D53+D64+D75+D86+D97+D20 -> 0 | E9: =E31+E42+E53+E64+E75+E86+E97+E20 -> 0 | F9: =F31+F42+F53+F64+F75+F86+F97+F20 -> 0 | G9: =G31+G42+G53+G64+G75+G86+G97+G20 -> 0 | H9: =H31+H42+H53+H64+H75+H86+H97+H20 -> 0 | I9: =I31+I42+I53+I64+I75+I86+I97+I20 -> 0 | J9: =J31+J42+J53+J64+J75+J86+J97+J20 -> 0 | ... S9: =S31+S42+S53+S64+S75+S86+S97+S20 -> 0
B10: 5차년도 (2029년) | C10: =C32+C43+C54+C65+C76+C87+C98+C21 -> 0 | D10: =D32+D43+D54+D65+D76+D87+D98+D21 -> 0 | E10: =E32+E43+E54+E65+E76+E87+E98+E21 -> 0 | F10: =F32+F43+F54+F65+F76+F87+F98+F21 -> 0 | G10: =G32+G43+G54+G65+G76+G87+G98+G21 -> 0 | H10: =H32+H43+H54+H65+H76+H87+H98+H21 -> 0 | I10: =I32+I43+I54+I65+I76+I87+I98+I21 -> 0 | J10: =J32+J43+J54+J65+J76+J87+J98+J21 -> 0 | ... S10: =S32+S43+S54+S65+S76+S87+S98+S21 -> 0
B11: 합계 | C11: =C33+C44+C55+C66+C77+C88+C99+C22 -> 0 | D11: =D33+D44+D55+D66+D77+D88+D99+D22 -> 0 | E11: =E33+E44+E55+E66+E77+E88+E99+E22 -> 0 | F11: =F33+F44+F55+F66+F77+F88+F99+F22 -> 0 | G11: =G33+G44+G55+G66+G77+G88+G99+G22 -> 0 | H11: =H33+H44+H55+H66+H77+H88+H99+H22 -> 0 | I11: =I33+I44+I55+I66+I77+I88+I99+I22 -> 0 | J11: =J33+J44+J55+J66+J77+J88+J99+J22 -> 0 | ... S11: =S33+S44+S55+S66+S77+S88+S99+S22 -> 0
B13: 조정
B14: 구분 | C14: 특허 | G14: 표준화 | M14: 기술이전 | N14: 상용화 (백만원) | O14: 기술료 (백만원) | P14: 성과홍보 | Q14: 시제품 | R14: S/W등록 | S14: 기술문서
C15: 국제 | E15: 국내 | G15: 국제 | J15: 국내
C16: 출원 | D16: 등록 | E16: 출원 | F16: 등록 | G16: 기고서제출 | H16: 기고서채택 | I16: 표준안채택 | J16: 기고서제출 | K16: 기고서채택 | L16: 표준안채택
B17: 1차년도 (2025년)
B18: 2차년도 (2026년)
B19: 3차년도 (2027년)
B20: 4차년도 (2028년)
B21: 5차년도 (2029년)
B22: 합계 | C22: =SUM(C17:C21) -> 0 | D22: =SUM(D17:D21) -> 0 | E22: =SUM(E17:E21) -> 0 | F22: =SUM(F17:F21) -> 0 | G22: =SUM(G17:G21) -> 0 | H22: =SUM(H17:H21) -> 0 | I22: =SUM(I17:I21) -> 0 | J22: =SUM(J17:J21) -> 0 | ... S22: =SUM(S17:S21) -> 0
B24: 기관명
B25: 구분 | C25: 특허 | G25: 표준화 | M25: 기술이전 | N25: 상용화 (백만원) | O25: 기술료 (백만원) | P25: 성과홍보 | Q25: 시제품 | R25: S/W등록 | S25: 기술문서
C26: 국제 | E26: 국내 | G26: 국제 | J26: 국내
C27: 출원 | D27: 등록 | E27: 출원 | F27: 등록 | G27: 기고서제출 | H27: 기고서채택 | I27: 표준안채택 | J27: 기고서제출 | K27: 기고서채택 | L27: 표준안채택
B28: 1차년도 (2025년)
B29: 2차년도 (2026년)
B30: 3차년도 (2027년)
B31: 4차년도 (2028년)
B32: 5차년도 (2029년)
B33: 합계 | C33: =SUM(C28:C32) -> 0 | D33: =SUM(D28:D32) -> 0 | E33: =SUM(E28:E32) -> 0 | F33: =SUM(F28:F32) -> 0 | G33: =SUM(G28:G32) -> 0 | H33: =SUM(H28:H32) -> 0 | I33: =SUM(I28:I32) -> 0 | J33: =SUM(J28:J32) -> 0 | ... S33: =SUM(S28:S32) -> 0
B35: 기관명
B36: 구분 | C36: 특허 | G36: 표준화 | M36: 기술이전 | N36: 상용화 (백만원) | O36: 기술료 (백만원) | P36: 성과홍보 | Q36: 시제품 | R36: S/W등록 | S36: 기술문서
C37: 국제 | E37: 국내 | G37: 국제 | J37: 국내
C38: 출원 | D38: 등록 | E38: 출원 | F38: 등록 | G38: 기고서제출 | H38: 기고서채택 | I38: 표준안채택 | J38: 기고서제출 | K38: 기고서채택 | L38: 표준안채택
B39: 1차년도 (2025년)
B40: 2차년도 (2026년)
B41: 3차년도 (2027년)
B42: 4차년도 (2028년)
B43: 5차년도 (2029년)
B44: 합계 | C44: =SUM(C39:C43) -> 0 | D44: =SUM(D39:D43) -> 0 | E44: =SUM(E39:E43) -> 0 | F44: =SUM(F39:F43) -> 0 | G44: =SUM(G39:G43) -> 0 | H44: =SUM(H39:H43) -> 0 | I44: =SUM(I39:I43) -> 0 | J44: =SUM(J39:J43) -> 0 | ... S44: =SUM(S39:S43) -> 0
...

Sheet 성과지표(4세부)
B2: 통합
B3: 구분 | C3: 특허 | G3: 표준화 | M3: 기술이전 | N3: 상용화 (백만원) | O3: 기술료 (백만원) | P3: 성과홍보 | Q3: 시제품 | R3: S/W등록 | S3: 기술문서
C4: 국제 | E4: 국내 | G4: 국제 | J4: 국내
C5: 출원 | D5: 등록 | E5: 출원 | F5: 등록 | G5: 기고서제출 | H5: 기고서채택 | I5: 표준안채택 | J5: 기고서제출 | K5: 기고서채택 | L5: 표준안채택
B6: 1차년도 (2025년) | C6: =C28+C39+C50+C61+C72+C83+C94+C17 -> 0 | D6: =D28+D39+D50+D61+D72+D83+D94+D17 -> 0 | E6: =E28+E39+E50+E61+E72+E83+E94+E17 -> 0 | F6: =F28+F39+F50+F61+F72+F83+F94+F17 -> 0 | G6: =G28+G39+G50+G61+G72+G83+G94+G17 -> 0 | H6: =H28+H39+H50+H61+H72+H83+H94+H17 -> 0 | I6: =I28+I39+I50+I61+I72+I83+I94+I17 -> 0 | J6: =J28+J39+J50+J61+J72+J83+J94+J17 -> 0 | ... S6: =S28+S39+S50+S61+S72+S83+S94+S17 -> 0
B7: 2차년도 (2026년) | C7: =C29+C40+C51+C62+C73+C84+C95+C18 -> 0 | D7: =D29+D40+D51+D62+D73+D84+D95+D18 -> 0 | E7: =E29+E40+E51+E62+E73+E84+E95+E18 -> 0 | F7: =F29+F40+F51+F62+F73+F84+F95+F18 -> 0 | G7: =G29+G40+G51+G62+G73+G84+G95+G18 -> 0 | H7: =H29+H40+H51+H62+H73+H84+H95+H18 -> 0 | I7: =I29+I40+I51+I62+I73+I84+I95+I18 -> 0 | J7: =J29+J40+J51+J62+J73+J84+J95+J18 -> 0 | ... S7: =S29+S40+S51+S62+S73+S84+S95+S18 -> 0
B8: 3차년도 (2027년) | C8: =C30+C41+C52+C63+C74+C85+C96+C19 -> 0 | D8: =D30+D41+D52+D63+D74+D85+D96+D19 -> 0 | E8: =E30+E41+E52+E63+E74+E85+E96+E19 -> 0 | F8: =F30+F41+F52+F63+F74+F85+F96+F19 -> 0 | G8: =G30+G41+G52+G63+G74+G85+G96+G19 -> 0 | H8: =H30+H41+H52+H63+H74+H85+H96+H19 -> 0 | I8: =I30+I41+I52+I63+I74+I85+I96+I19 -> 0 | J8: =J30+J41+J52+J63+J74+J85+J96+J19 -> 0 | ... S8: =S30+S41+S52+S63+S74+S85+S96+S19 -> 0
B9: 4차년도 (2028년) | C9: =C31+C42+C53+C64+C75+C86+C97+C20 -> 0 | D9: =D31+D42+D53+D64+D75+D86+D97+D20 -> 0 | E9: =E31+E42+E53+E64+E75+E86+E97+E20 -> 0 | F9: =F31+F42+F53+F64+F75+F86+F97+F20 -> 0 | G9: =G31+G42+G53+G64+G75+G86+G97+G20 -> 0 | H9: =H31+H42+H53+H64+H75+H86+H97+H20 -> 0 | I9: =I31+I42+I53+I64+I75+I86+I97+I20 -> 0 | J9: =J31+J42+J53+J64+J75+J86+J97+J20 -> 0 | ... S9: =S31+S42+S53+S64+S75+S86+S97+S20 -> 0
B10: 5차년도 (2029년) | C10: =C32+C43+C54+C65+C76+C87+C98+C21 -> 0 | D10: =D32+D43+D54+D65+D76+D87+D98+D21 -> 0 | E10: =E32+E43+E54+E65+E76+E87+E98+E21 -> 0 | F10: =F32+F43+F54+F65+F76+F87+F98+F21 -> 0 | G10: =G32+G43+G54+G65+G76+G87+G98+G21 -> 0 | H10: =H32+H43+H54+H65+H76+H87+H98+H21 -> 0 | I10: =I32+I43+I54+I65+I76+I87+I98+I21 -> 0 | J10: =J32+J43+J54+J65+J76+J87+J98+J21 -> 0 | ... S10: =S32+S43+S54+S65+S76+S87+S98+S21 -> 0
B11: 합계 | C11: =C33+C44+C55+C66+C77+C88+C99+C22 -> 0 | D11: =D33+D44+D55+D66+D77+D88+D99+D22 -> 0 | E11: =E33+E44+E55+E66+E77+E88+E99+E22 -> 0 | F11: =F33+F44+F55+F66+F77+F88+F99+F22 -> 0 | G11: =G33+G44+G55+G66+G77+G88+G99+G22 -> 0 | H11: =H33+H44+H55+H66+H77+H88+H99+H22 -> 0 | I11: =I33+I44+I55+I66+I77+I88+I99+I22 -> 0 | J11: =J33+J44+J55+J66+J77+J88+J99+J22 -> 0 | ... S11: =S33+S44+S55+S66+S77+S88+S99+S22 -> 0
B13: 조정
B14: 구분 | C14: 특허 | G14: 표준화 | M14: 기술이전 | N14: 상용화 (백만원) | O14: 기술료 (백만원) | P14: 성과홍보 | Q14: 시제품 | R14: S/W등록 | S14: 기술문서
C15: 국제 | E15: 국내 | G15: 국제 | J15: 국내
C16: 출원 | D16: 등록 | E16: 출원 | F16: 등록 | G16: 기고서제출 | H16: 기고서채택 | I16: 표준안채택 | J16: 기고서제출 | K16: 기고서채택 | L16: 표준안채택
B17: 1차년도 (2025년)
B18: 2차년도 (2026년)
B19: 3차년도 (2027년)
B20: 4차년도 (2028년)
B21: 5차년도 (2029년)
B22: 합계 | C22: =SUM(C17:C21) -> 0 | D22: =SUM(D17:D21) -> 0 | E22: =SUM(E17:E21) -> 0 | F22: =SUM(F17:F21) -> 0 | G22: =SUM(G17:G21) -> 0 | H22: =SUM(H17:H21) -> 0 | I22: =SUM(I17:I21) -> 0 | J22: =SUM(J17:J21) -> 0 | ... S22: =SUM(S17:S21) -> 0
B24: 기관명
B25: 구분 | C25: 특허 | G25: 표준화 | M25: 기술이전 | N25: 상용화 (백만원) | O25: 기술료 (백만원) | P25: 성과홍보 | Q25: 시제품 | R25: S/W등록 | S25: 기술문서
C26: 국제 | E26: 국내 | G26: 국제 | J26: 국내
C27: 출원 | D27: 등록 | E27: 출원 | F27: 등록 | G27: 기고서제출 | H27: 기고서채택 | I27: 표준안채택 | J27: 기고서제출 | K27: 기고서채택 | L27: 표준안채택
B28: 1차년도 (2025년)
B29: 2차년도 (2026년)
B30: 3차년도 (2027년)
B31: 4차년도 (2028년)
B32: 5차년도 (2029년)
B33: 합계 | C33: =SUM(C28:C32) -> 0 | D33: =SUM(D28:D32) -> 0 | E33: =SUM(E28:E32) -> 0 | F33: =SUM(F28:F32) -> 0 | G33: =SUM(G28:G32) -> 0 | H33: =SUM(H28:H32) -> 0 | I33: =SUM(I28:I32) -> 0 | J33: =SUM(J28:J32) -> 0 | ... S33: =SUM(S28:S32) -> 0
B35: 기관명
B36: 구분 | C36: 특허 | G36: 표준화 | M36: 기술이전 | N36: 상용화 (백만원) | O36: 기술료 (백만원) | P36: 성과홍보 | Q36: 시제품 | R36: S/W등록 | S36: 기술문서
C37: 국제 | E37: 국내 | G37: 국제 | J37: 국내
C38: 출원 | D38: 등록 | E38: 출원 | F38: 등록 | G38: 기고서제출 | H38: 기고서채택 | I38: 표준안채택 | J38: 기고서제출 | K38: 기고서채택 | L38: 표준안채택
B39: 1차년도 (2025년)
B40: 2차년도 (2026년)
B41: 3차년도 (2027년)
B42: 4차년도 (2028년)
B43: 5차년도 (2029년)
B44: 합계 | C44: =SUM(C39:C43) -> 0 | D44: =SUM(D39:D43) -> 0 | E44: =SUM(E39:E43) -> 0 | F44: =SUM(F39:F43) -> 0 | G44: =SUM(G39:G43) -> 0 | H44: =SUM(H39:H43) -> 0 | I44: =SUM(I39:I43) -> 0 | J44: =SUM(J39:J43) -> 0 | ... S44: =SUM(S39:S43) -> 0
...

Sheet 연구개발비(총괄)
E2: 구분 | G2: 정부지원 | H2: 기관부담 | K2: 그 외 기관 등의 지원금 | Q2: 합 계
G3: 연구개발비 | H3: 연구개발비 | K3: 지방자치단체 | N3: 기타( )
E4: 단계 | F4: 연차 | G4: 현금 | H4: 현금 | I4: 현물 | J4: 소계 | K4: 현금 | L4: 현물 | M4: 소계 | N4: 현금 | O4: 현물 | P4: 소계 | Q4: 현금 | R4: 현물 | S4: 합계
E6: 총계 | G6: =SUM(G7:G11) -> 0 | H6: =SUM(H7:H11) -> 0 | I6: =SUM(I7:I11) -> 0 | J6: =SUM(J7:J11) -> 0 | K6: =SUM(K7:K11) -> 0 | L6: =SUM(L7:L11) -> 0 | M6: =SUM(M7:M11) -> 0 | N6: =SUM(N7:N11) -> 0 | ... S6: =SUM(S7:S11) -> 0
E7: 1 | F7: 1 | G7: =G20 -> 0 | H7: =H20 -> 0 | I7: =I20 -> 0 | J7: =H7+I7 -> 0 | K7: =K20 -> 0 | L7: =L20 -> 0 | M7: =K7+L7 -> 0 | N7: =N20 -> 0 | O7: =O20 -> 0 | P7: =N7+O7 -> 0 | Q7: =Q20 -> 0 | R7: =R20 -> 0 | S7: =S20 -> 0
F8: 2 | G8: =G21 -> 0 | H8: =H21 -> 0 | I8: =I21 -> 0 | J8: =H8+I8 -> 0 | K8: =K21 -> 0 | L8: =L21 -> 0 | M8: =K8+L8 -> 0 | N8: =N21 -> 0 | O8: =O21 -> 0 | P8: =N8+O8 -> 0 | Q8: =Q21 -> 0 | R8: =R21 -> 0 | S8: =S21 -> 0
F9: 3 | G9: =G22 -> 0 | H9: =H22 -> 0 | I9: =I22 -> 0 | J9: =H9+I9 -> 0 | K9: =K22 -> 0 | L9: =L22 -> 0 | M9: =K9+L9 -> 0 | N9: =N22 -> 0 | O9: =O22 -> 0 | P9: =N9+O9 -> 0 | Q9: =Q22 -> 0 | R9: =R22 -> 0 | S9: =S22 -> 0
E10: 2 | F10: 1 | G10: =G23 -> 0 | H10: =H23 -> 0 | I10: =I23 -> 0 | J10: =H10+I10 -> 0 | K10: =K23 -> 0 | L10: =L23 -> 0 | M10: =K10+L10 -> 0 | N10: =N23 -> 0 | O10: =O23 -> 0 | P10: =N10+O10 -> 0 | Q10: =Q23 -> 0 | R10: =R23 -> 0 | S10: =S23 -> 0
F11: 2 | G11: =G24 -> 0 | H11: =H24 -> 0 | I11: =I24 -> 0 | J11: =H11+I11 -> 0 | K11: =K24 -> 0 | L11: =L24 -> 0 | M11: =K11+L11 -> 0 | N11: =N24 -> 0 | O11: =O24 -> 0 | P11: =N11+O11 -> 0 | Q11: =Q24 -> 0 | R11: =R24 -> 0 | S11: =S24 -> 0
B15: 4-1. 연구개발비 지원.부담계획
D16: 구분 | G16: 정부지원 | H16: 기관부담 | K16: 그 외 기관 등의 지원금 | Q16: 합 계
G17: 연구개발비 | H17: 연구개발비 | K17: 지방자치단체 | N17: 기타( )
D18: 과제 | E18: 단계 | F18: 연차 | G18: 현금 | H18: 현금 | I18: 현물 | J18: 소계 | K18: 현금 | L18: 현물 | M18: 소계 | N18: 현금 | O18: 현물 | P18: 소계 | Q18: 현금 | R18: 현물 | S18: 합계
D20: 총괄 연구개발 과제 | E20: 1 | F20: 1 | G20: =G27+G34+G41+G48 -> 0 | H20: =H27+H34+H41+H48 -> 0 | I20: =I27+I34+I41+I48 -> 0 | J20: =J27+J34+J41+J48 -> 0 | K20: =K27+K34+K41+K48 -> 0 | L20: =L27+L34+L41+L48 -> 0 | M20: =M27+M34+M41+M48 -> 0 | N20: =N27+N34+N41+N48 -> 0 | ... S20: =S27+S34+S41+S48 -> 0
F21: 2 | G21: =G28+G35+G42+G49 -> 0 | H21: =H28+H35+H42+H49 -> 0 | I21: =I28+I35+I42+I49 -> 0 | J21: =J28+J35+J42+J49 -> 0 | K21: =K28+K35+K42+K49 -> 0 | L21: =L28+L35+L42+L49 -> 0 | M21: =M28+M35+M42+M49 -> 0 | N21: =N28+N35+N42+N49 -> 0 | ... S21: =S28+S35+S42+S49 -> 0
F22: 3 | G22: =G29+G36+G43+G50 -> 0 | H22: =H29+H36+H43+H50 -> 0 | I22: =I29+I36+I43+I50 -> 0 | J22: =J29+J36+J43+J50 -> 0 | K22: =K29+K36+K43+K50 -> 0 | L22: =L29+L36+L43+L50 -> 0 | M22: =M29+M36+M43+M50 -> 0 | N22: =N29+N36+N43+N50 -> 0 | ... S22: =S29+S36+S43+S50 -> 0
E23: 2 | F23: 1 | G23: =G30+G37+G44+G51 -> 0 | H23: =H30+H37+H44+H51 -> 0 | I23: =I30+I37+I44+I51 -> 0 | J23: =J30+J37+J44+J51 -> 0 | K23: =K30+K37+K44+K51 -> 0 | L23: =L30+L37+L44+L51 -> 0 | M23: =M30+M37+M44+M51 -> 0 | N23: =N30+N37+N44+N51 -> 0 | ... S23: =S30+S37+S44+S51 -> 0
F24: 2 | G24: =G31+G38+G45+G52 -> 0 | H24: =H31+H38+H45+H52 -> 0 | I24: =I31+I38+I45+I52 -> 0 | J24: =J31+J38+J45+J52 -> 0 | K24: =K31+K38+K45+K52 -> 0 | L24: =L31+L38+L45+L52 -> 0 | M24: =M31+M38+M45+M52 -> 0 | N24: =N31+N38+N45+N52 -> 0 | ... S24: =S31+S38+S45+S52 -> 0
E25: 소계 | F25: 1 | G25: =G32+G39+G46+G53 -> 0 | H25: =H32+H39+H46+H53 -> 0 | I25: =I32+I39+I46+I53 -> 0 | J25: =J32+J39+J46+J53 -> 0 | K25: =K32+K39+K46+K53 -> 0 | L25: =L32+L39+L46+L53 -> 0 | M25: =M32+M39+M46+M53 -> 0 | N25: =N32+N39+N46+N53 -> 0 | ... S25: =S32+S39+S46+S53 -> 0
F26: 2 | G26: =G33+G40+G47+G54 -> 0 | H26: =H33+H40+H47+H54 -> 0 | I26: =I33+I40+I47+I54 -> 0 | J26: =J33+J40+J47+J54 -> 0 | K26: =K33+K40+K47+K54 -> 0 | L26: =L33+L40+L47+L54 -> 0 | M26: =M33+M40+M47+M54 -> 0 | N26: =N33+N40+N47+N54 -> 0 | ... S26: =S33+S40+S47+S54 -> 0
D27: 연구개발 과제1 | E27: 1 | F27: 1 | G27: =SUM('연구개발비(1세부)'!G7:G13) -> 0 | H27: =SUM('연구개발비(1세부)'!H7:H13) -> 0 | I27: =SUM('연구개발비(1세부)'!I7:I13) -> 0 | J27: =SUM('연구개발비(1세부)'!J7:J13) -> 0 | K27: =SUM('연구개발비(1세부)'!K7:K13) -> 0 | L27: =SUM('연구개발비(1세부)'!L7:L13) -> 0 | M27: =SUM('연구개발비(1세부)'!M7:M13) -> 0 | N27: =SUM('연구개발비(1세부)'!N7:N13) -> 0 | ... S27: =SUM('연구개발비(1세부)'!S7:S13) -> 0
F28: 2 | G28: =SUM('연구개발비(1세부)'!G14:G20) -> 0 | H28: =SUM('연구개발비(1세부)'!H14:H20) -> 0 | I28: =SUM('연구개발비(1세부)'!I14:I20) -> 0 | J28: =SUM('연구개발비(1세부)'!J14:J20) -> 0 | K28: =SUM('연구개발비(1세부)'!K14:K20) -> 0 | L28: =SUM('연구개발비(1세부)'!L14:L20) -> 0 | M28: =SUM('연구개발비(1세부)'!M14:M20) -> 0 | N28: =SUM('연구개발비(1세부)'!N14:N20) -> 0 | ... S28: =SUM('연구개발비(1세부)'!S14:S20) -> 0
F29: 3 | G29: =SUM('연구개발비(1세부)'!G21:G27) -> 0 | H29: =SUM('연구개발비(1세부)'!H21:H27) -> 0 | I29: =SUM('연구개발비(1세부)'!I21:I27) -> 0 | J29: =SUM('연구개발비(1세부)'!J21:J27) -> 0 | K29: =SUM('연구개발비(1세부)'!K21:K27) -> 0 | L29: =SUM('연구개발비(1세부)'!L21:L27) -> 0 | M29: =SUM('연구개발비(1세부)'!M21:M27) -> 0 | N29: =SUM('연구개발비(1세부)'!N21:N27) -> 0 | ... S29: =SUM('연구개발비(1세부)'!S21:S27) -> 0
E30: 2 | F30: 1 | G30: =SUM('연구개발비(1세부)'!G29:G35) -> 0 | H30: =SUM('연구개발비(1세부)'!H29:H35) -> 0 | I30: =SUM('연구개발비(1세부)'!I29:I35) -> 0 | J30: =SUM('연구개발비(1세부)'!J29:J35) -> 0 | K30: =SUM('연구개발비(1세부)'!K29:K35) -> 0 | L30: =SUM('연구개발비(1세부)'!L29:L35) -> 0 | M30: =SUM('연구개발비(1세부)'!M29:M35) -> 0 | N30: =SUM('연구개발비(1세부)'!N29:N35) -> 0 | ... S30: =SUM('연구개발비(1세부)'!S29:S35) -> 0
F31: 2 | G31: =SUM('연구개발비(1세부)'!G36:G42) -> 0 | H31: =SUM('연구개발비(1세부)'!H36:H42) -> 0 | I31: =SUM('연구개발비(1세부)'!I36:I42) -> 0 | J31: =SUM('연구개발비(1세부)'!J36:J42) -> 0 | K31: =SUM('연구개발비(1세부)'!K36:K42) -> 0 | L31: =SUM('연구개발비(1세부)'!L36:L42) -> 0 | M31: =SUM('연구개발비(1세부)'!M36:M42) -> 0 | N31: =SUM('연구개발비(1세부)'!N36:N42) -> 0 | ... S31: =SUM('연구개발비(1세부)'!S36:S42) -> 0
E32: 소계 | F32: 1 | G32: =SUM(G27:G29) -> 0 | H32: =SUM(H27:H29) -> 0 | I32: =SUM(I27:I29) -> 0 | J32: =SUM(J27:J29) -> 0 | K32: =SUM(K27:K29) -> 0 | L32: =SUM(L27:L29) -> 0 | M32: =SUM(M27:M29) -> 0 | N32: =SUM(N27:N29) -> 0 | ... S32: =SUM(S27:S29) -> 0
F33: 2 | G33: =SUM(G30:G31) -> 0 | H33: =SUM(H30:H31) -> 0 | I33: =SUM(I30:I31) -> 0 | J33: =SUM(J30:J31) -> 0 | K33: =SUM(K30:K31) -> 0 | L33: =SUM(L30:L31) -> 0 | M33: =SUM(M30:M31) -> 0 | N33: =SUM(N30:N31) -> 0 | ... S33: =SUM(S30:S31) -> 0
D34: 연구개발 과제2 | E34: 1 | F34: 1 | G34: =SUM('연구개발비(2세부)'!G7:G13) -> 0 | H34: =SUM('연구개발비(2세부)'!H7:H13) -> 0 | I34: =SUM('연구개발비(2세부)'!I7:I13) -> 0 | J34: =SUM('연구개발비(2세부)'!J7:J13) -> 0 | K34: =SUM('연구개발비(2세부)'!K7:K13) -> 0 | L34: =SUM('연구개발비(2세부)'!L7:L13) -> 0 | M34: =SUM('연구개발비(2세부)'!M7:M13) -> 0 | N34: =SUM('연구개발비(2세부)'!N7:N13) -> 0 | ... S34: =SUM('연구개발비(2세부)'!S7:S13) -> 0
F35: 2 | G35: =SUM('연구개발비(2세부)'!G14:G20) -> 0 | H35: =SUM('연구개발비(2세부)'!H14:H20) -> 0 | I35: =SUM('연구개발비(2세부)'!I14:I20) -> 0 | J35: =SUM('연구개발비(2세부)'!J14:J20) -> 0 | K35: =SUM('연구개발비(2세부)'!K14:K20) -> 0 | L35: =SUM('연구개발비(2세부)'!L14:L20) -> 0 | M35: =SUM('연구개발비(2세부)'!M14:M20) -> 0 | N35: =SUM('연구개발비(2세부)'!N14:N20) -> 0 | ... S35: =SUM('연구개발비(2세부)'!S14:S20) -> 0
F36: 3 | G36: =SUM('연구개발비(2세부)'!G21:G27) -> 0 | H36: =SUM('연구개발비(2세부)'!H21:H27) -> 0 | I36: =SUM('연구개발비(2세부)'!I21:I27) -> 0 | J36: =SUM('연구개발비(2세부)'!J21:J27) -> 0 | K36: =SUM('연구개발비(2세부)'!K21:K27) -> 0 | L36: =SUM('연구개발비(2세부)'!L21:L27) -> 0 | M36: =SUM('연구개발비(2세부)'!M21:M27) -> 0 | N36: =SUM('연구개발비(2세부)'!N21:N27) -> 0 | ... S36: =SUM('연구개발비(2세부)'!S21:S27) -> 0
E37: 2 | F37: 1 | G37: =SUM('연구개발비(2세부)'!G21:G27) -> 0 | H37: =SUM('연구개발비(2세부)'!H21:H27) -> 0 | I37: =SUM('연구개발비(2세부)'!I21:I27) -> 0 | J37: =SUM('연구개발비(2세부)'!J21:J27) -> 0 | K37: =SUM('연구개발비(2세부)'!K21:K27) -> 0 | L37: =SUM('연구개발비(2세부)'!L21:L27) -> 0 | M37: =SUM('연구개발비(2세부)'!M21:M27) -> 0 | N37: =SUM('연구개발비(2세부)'!N21:N27) -> 0 | ... S37: =SUM('연구개발비(2세부)'!S21:S27) -> 0
F38: 2 | G38: =SUM('연구개발비(2세부)'!G36:G42) -> 0 | H38: =SUM('연구개발비(2세부)'!H36:H42) -> 0 | I38: =SUM('연구개발비(2세부)'!I36:I42) -> 0 | J38: =SUM('연구개발비(2세부)'!J36:J42) -> 0 | K38: =SUM('연구개발비(2세부)'!K36:K42) -> 0 | L38: =SUM('연구개발비(2세부)'!L36:L42) -> 0 | M38: =SUM('연구개발비(2세부)'!M36:M42) -> 0 | N38: =SUM('연구개발비(2세부)'!N36:N42) -> 0 | ... S38: =SUM('연구개발비(2세부)'!S36:S42) -> 0
E39: 소계 | F39: 1 | G39: =SUM(G34:G36) -> 0 | H39: =SUM(H34:H36) -> 0 | I39: =SUM(I34:I36) -> 0 | J39: =SUM(J34:J36) -> 0 | K39: =SUM(K34:K36) -> 0 | L39: =SUM(L34:L36) -> 0 | M39: =SUM(M34:M36) -> 0 | N39: =SUM(N34:N36) -> 0 | ... S39: =SUM(S34:S36) -> 0
F40: 2 | G40: =SUM(G37:G38) -> 0 | H40: =SUM(H37:H38) -> 0 | I40: =SUM(I37:I38) -> 0 | J40: =SUM(J37:J38) -> 0 | K40: =SUM(K37:K38) -> 0 | L40: =SUM(L37:L38) -> 0 | M40: =SUM(M37:M38) -> 0 | N40: =SUM(N37:N38) -> 0 | ... S40: =SUM(S37:S38) -> 0
D41: 연구개발 과제3 | E41: 1 | F41: 1 | G41: =SUM('연구개발비(3세부)'!G7:G13) -> 0 | H41: =SUM('연구개발비(3세부)'!H7:H13) -> 0 | I41: =SUM('연구개발비(3세부)'!I7:I13) -> 0 | J41: =SUM('연구개발비(3세부)'!J7:J13) -> 0 | K41: =SUM('연구개발비(3세부)'!K7:K13) -> 0 | L41: =SUM('연구개발비(3세부)'!L7:L13) -> 0 | M41: =SUM('연구개발비(3세부)'!M7:M13) -> 0 | N41: =SUM('연구개발비(3세부)'!N7:N13) -> 0 | ... S41: =SUM('연구개발비(3세부)'!S7:S13) -> 0
F42: 2 | G42: =SUM('연구개발비(3세부)'!G14:G20) -> 0 | H42: =SUM('연구개발비(3세부)'!H14:H20) -> 0 | I42: =SUM('연구개발비(3세부)'!I14:I20) -> 0 | J42: =SUM('연구개발비(3세부)'!J14:J20) -> 0 | K42: =SUM('연구개발비(3세부)'!K14:K20) -> 0 | L42: =SUM('연구개발비(3세부)'!L14:L20) -> 0 | M42: =SUM('연구개발비(3세부)'!M14:M20) -> 0 | N42: =SUM('연구개발비(3세부)'!N14:N20) -> 0 | ... S42: =SUM('연구개발비(3세부)'!S14:S20) -> 0
F43: 3 | G43: =SUM('연구개발비(3세부)'!G21:G27) -> 0 | H43: =SUM('연구개발비(3세부)'!H21:H27) -> 0 | I43: =SUM('연구개발비(3세부)'!I21:I27) -> 0 | J43: =SUM('연구개발비(3세부)'!J21:J27) -> 0 | K43: =SUM('연구개발비(3세부)'!K21:K27) -> 0 | L43: =SUM('연구개발비(3세부)'!L21:L27) -> 0 | M43: =SUM('연구개발비(3세부)'!M21:M27) -> 0 | N43: =SUM('연구개발비(3세부)'!N21:N27) -> 0 | ... S43: =SUM('연구개발비(3세부)'!S21:S27) -> 0
E44: 2 | F44: 1 | G44: =SUM('연구개발비(3세부)'!G21:G27) -> 0 | H44: =SUM('연구개발비(3세부)'!H21:H27) -> 0 | I44: =SUM('연구개발비(3세부)'!I21:I27) -> 0 | J44: =SUM('연구개발비(3세부)'!J21:J27) -> 0 | K44: =SUM('연구개발비(3세부)'!K21:K27) -> 0 | L44: =SUM('연구개발비(3세부)'!L21:L27) -> 0 | M44: =SUM('연구개발비(3세부)'!M21:M27) -> 0 | N44: =SUM('연구개발비(3세부)'!N21:N27) -> 0 | ... S44: =SUM('연구개발비(3세부)'!S21:S27) -> 0
F45: 2 | G45: =SUM('연구개발비(3세부)'!G36:G42) -> 0 | H45: =SUM('연구개발비(3세부)'!H36:H42) -> 0 | I45: =SUM('연구개발비(3세부)'!I36:I42) -> 0 | J45: =SUM('연구개발비(3세부)'!J36:J42) -> 0 | K45: =SUM('연구개발비(3세부)'!K36:K42) -> 0 | L45: =SUM('연구개발비(3세부)'!L36:L42) -> 0 | M45: =SUM('연구개발비(3세부)'!M36:M42) -> 0 | N45: =SUM('연구개발비(3세부)'!N36:N42) -> 0 | ... S45: =SUM('연구개발비(3세부)'!S36:S42) -> 0
E46: 소계 | F46: 1 | G46: =SUM(G41:G43) -> 0 | H46: =SUM(H41:H43) -> 0 | I46: =SUM(I41:I43) -> 0 | J46: =SUM(J41:J43) -> 0 | K46: =SUM(K41:K43) -> 0 | L46: =SUM(L41:L43) -> 0 | M46: =SUM(M41:M43) -> 0 | N46: =SUM(N41:N43) -> 0 | ... S46: =SUM(S41:S43) -> 0
...

Sheet 연구개발비(1세부)
B2: 2-1. 연구개발비 지원.부담계획
D3: 구분 | G3: 정부지원 | H3: 기관부담 | K3: 그 외 기관 등의 지원금 | Q3: 합 계
G4: 연구개발비 | H4: 연구개발비 | K4: 지방자치단체 | N4: 기타( )
D5: 단계 | E5: 연차 | F5: 연구개발기관명 | G5: 현금 | H5: 현금 | I5: 현물 | J5: 소계 | K5: 현금 | L5: 현물 | M5: 소계 | N5: 현금 | O5: 현물 | P5: 소계 | Q5: 현금 | R5: 현물 | S5: 합계
F6: (기관역할1｣)
D7: 1 | E7: 1 | J7: =SUM(H7:I7) -> 0 | K7: 0 | L7: 0 | M7: =SUM(K7:L7) -> 0 | N7: 0 | O7: 0 | P7: =SUM(N7:O7) -> 0 | Q7: =G7+H7+K7+N7 -> 0 | R7: =I7+L7+O7 -> 0 | S7: =SUM(Q7:R7) -> 0
J8: =SUM(H8:I8) -> 0 | K8: 0 | L8: 0 | M8: =SUM(K8:L8) -> 0 | N8: 0 | O8: 0 | P8: =SUM(N8:O8) -> 0 | Q8: =G8+H8+K8+N8 -> 0 | R8: =I8+L8+O8 -> 0 | S8: =SUM(Q8:R8) -> 0
J9: =SUM(H9:I9) -> 0 | K9: 0 | L9: 0 | M9: =SUM(K9:L9) -> 0 | N9: 0 | O9: 0 | P9: =SUM(N9:O9) -> 0 | Q9: =G9+H9+K9+N9 -> 0 | R9: =I9+L9+O9 -> 0 | S9: =SUM(Q9:R9) -> 0
J10: =SUM(H10:I10) -> 0 | K10: 0 | L10: 0 | M10: =SUM(K10:L10) -> 0 | N10: 0 | O10: 0 | P10: =SUM(N10:O10) -> 0 | Q10: =G10+H10+K10+N10 -> 0 | R10: =I10+L10+O10 -> 0 | S10: =SUM(Q10:R10) -> 0
J11: =SUM(H11:I11) -> 0 | K11: 0 | L11: 0 | M11: =SUM(K11:L11) -> 0 | N11: 0 | O11: 0 | P11: =SUM(N11:O11) -> 0 | Q11: =G11+H11+K11+N11 -> 0 | R11: =I11+L11+O11 -> 0 | S11: =SUM(Q11:R11) -> 0
J12: =SUM(H12:I12) -> 0 | K12: 0 | L12: 0 | M12: =SUM(K12:L12) -> 0 | N12: 0 | O12: 0 | P12: =SUM(N12:O12) -> 0 | Q12: =G12+H12+K12+N12 -> 0 | R12: =I12+L12+O12 -> 0 | S12: =SUM(Q12:R12) -> 0
J13: =SUM(H13:I13) -> 0 | K13: 0 | L13: 0 | M13: =SUM(K13:L13) -> 0 | N13: 0 | O13: 0 | P13: =SUM(N13:O13) -> 0 | Q13: =G13+H13+K13+N13 -> 0 | R13: =I13+L13+O13 -> 0 | S13: =SUM(Q13:R13) -> 0
E14: 2 | J14: =SUM(H14:I14) -> 0 | K14: 0 | L14: 0 | M14: =SUM(K14:L14) -> 0 | N14: 0 | O14: 0 | P14: =SUM(N14:O14) -> 0 | Q14: =G14+H14+K14+N14 -> 0 | R14: =I14+L14+O14 -> 0 | S14: =SUM(Q14:R14) -> 0
J15: =SUM(H15:I15) -> 0 | K15: 0 | L15: 0 | M15: =SUM(K15:L15) -> 0 | N15: 0 | O15: 0 | P15: =SUM(N15:O15) -> 0 | Q15: =G15+H15+K15+N15 -> 0 | R15: =I15+L15+O15 -> 0 | S15: =SUM(Q15:R15) -> 0
J16: =SUM(H16:I16) -> 0 | K16: 0 | L16: 0 | M16: =SUM(K16:L16) -> 0 | N16: 0 | O16: 0 | P16: =SUM(N16:O16) -> 0 | Q16: =G16+H16+K16+N16 -> 0 | R16: =I16+L16+O16 -> 0 | S16: =SUM(Q16:R16) -> 0
J17: =SUM(H17:I17) -> 0 | K17: 0 | L17: 0 | M17: =SUM(K17:L17) -> 0 | N17: 0 | O17: 0 | P17: =SUM(N17:O17) -> 0 | Q17: =G17+H17+K17+N17 -> 0 | R17: =I17+L17+O17 -> 0 | S17: =SUM(Q17:R17) -> 0
J18: =SUM(H18:I18) -> 0 | K18: 0 | L18: 0 | M18: =SUM(K18:L18) -> 0 | N18: 0 | O18: 0 | P18: =SUM(N18:O18) -> 0 | Q18: =G18+H18+K18+N18 -> 0 | R18: =I18+L18+O18 -> 0 | S18: =SUM(Q18:R18) -> 0
J19: =SUM(H19:I19) -> 0 | K19: 0 | L19: 0 | M19: =SUM(K19:L19) -> 0 | N19: 0 | O19: 0 | P19: =SUM(N19:O19) -> 0 | Q19: =G19+H19+K19+N19 -> 0 | R19: =I19+L19+O19 -> 0 | S19: =SUM(Q19:R19) -> 0
J20: =SUM(H20:I20) -> 0 | K20: 0 | L20: 0 | M20: =SUM(K20:L20) -> 0 | N20: 0 | O20: 0 | P20: =SUM(N20:O20) -> 0 | Q20: =G20+H20+K20+N20 -> 0 | R20: =I20+L20+O20 -> 0 | S20: =SUM(Q20:R20) -> 0
E21: 3 | J21: =SUM(H21:I21) -> 0 | K21: 0 | L21: 0 | M21: =SUM(K21:L21) -> 0 | N21: 0 | O21: 0 | P21: =SUM(N21:O21) -> 0 | Q21: =G21+H21+K21+N21 -> 0 | R21: =I21+L21+O21 -> 0 | S21: =SUM(Q21:R21) -> 0
J22: =SUM(H22:I22) -> 0 | K22: 0 | L22: 0 | M22: =SUM(K22:L22) -> 0 | N22: 0 | O22: 0 | P22: =SUM(N22:O22) -> 0 | Q22: =G22+H22+K22+N22 -> 0 | R22: =I22+L22+O22 -> 0 | S22: =SUM(Q22:R22) -> 0
J23: =SUM(H23:I23) -> 0 | K23: 0 | L23: 0 | M23: =SUM(K23:L23) -> 0 | N23: 0 | O23: 0 | P23: =SUM(N23:O23) -> 0 | Q23: =G23+H23+K23+N23 -> 0 | R23: =I23+L23+O23 -> 0 | S23: =SUM(Q23:R23) -> 0
J24: =SUM(H24:I24) -> 0 | K24: 0 | L24: 0 | M24: =SUM(K24:L24) -> 0 | N24: 0 | O24: 0 | P24: =SUM(N24:O24) -> 0 | Q24: =G24+H24+K24+N24 -> 0 | R24: =I24+L24+O24 -> 0 | S24: =SUM(Q24:R24) -> 0
J25: =SUM(H25:I25) -> 0 | K25: 0 | L25: 0 | M25: =SUM(K25:L25) -> 0 | N25: 0 | O25: 0 | P25: =SUM(N25:O25) -> 0 | Q25: =G25+H25+K25+N25 -> 0 | R25: =I25+L25+O25 -> 0 | S25: =SUM(Q25:R25) -> 0
J26: =SUM(H26:I26) -> 0 | K26: 0 | L26: 0 | M26: =SUM(K26:L26) -> 0 | N26: 0 | O26: 0 | P26: =SUM(N26:O26) -> 0 | Q26: =G26+H26+K26+N26 -> 0 | R26: =I26+L26+O26 -> 0 | S26: =SUM(Q26:R26) -> 0
J27: =SUM(H27:I27) -> 0 | K27: 0 | L27: 0 | M27: =SUM(K27:L27) -> 0 | N27: 0 | O27: 0 | P27: =SUM(N27:O27) -> 0 | Q27: =G27+H27+K27+N27 -> 0 | R27: =I27+L27+O27 -> 0 | S27: =SUM(Q27:R27) -> 0
E28: 소계 | G28: =SUM(G7:G27) -> 0 | H28: =SUM(H7:H27) -> 0 | I28: =SUM(I7:I27) -> 0 | J28: =SUM(J7:J27) -> 0 | K28: =SUM(K7:K27) -> 0 | L28: =SUM(L7:L27) -> 0 | M28: =SUM(M7:M27) -> 0 | N28: =SUM(N7:N27) -> 0 | ... S28: =SUM(S7:S27) -> 0
D29: 2 | E29: 4 | J29: =SUM(H29:I29) -> 0 | K29: 0 | L29: 0 | M29: =SUM(K29:L29) -> 0 | N29: 0 | O29: 0 | P29: =SUM(N29:O29) -> 0 | Q29: =G29+H29+K29+N29 -> 0 | R29: =I29+L29+O29 -> 0 | S29: =SUM(Q29:R29) -> 0
J30: =SUM(H30:I30) -> 0 | K30: 0 | L30: 0 | M30: =SUM(K30:L30) -> 0 | N30: 0 | O30: 0 | P30: =SUM(N30:O30) -> 0 | Q30: =G30+H30+K30+N30 -> 0 | R30: =I30+L30+O30 -> 0 | S30: =SUM(Q30:R30) -> 0
J31: =SUM(H31:I31) -> 0 | K31: 0 | L31: 0 | M31: =SUM(K31:L31) -> 0 | N31: 0 | O31: 0 | P31: =SUM(N31:O31) -> 0 | Q31: =G31+H31+K31+N31 -> 0 | R31: =I31+L31+O31 -> 0 | S31: =SUM(Q31:R31) -> 0
J32: =SUM(H32:I32) -> 0 | K32: 0 | L32: 0 | M32: =SUM(K32:L32) -> 0 | N32: 0 | O32: 0 | P32: =SUM(N32:O32) -> 0 | Q32: =G32+H32+K32+N32 -> 0 | R32: =I32+L32+O32 -> 0 | S32: =SUM(Q32:R32) -> 0
J33: =SUM(H33:I33) -> 0 | K33: 0 | L33: 0 | M33: =SUM(K33:L33) -> 0 | N33: 0 | O33: 0 | P33: =SUM(N33:O33) -> 0 | Q33: =G33+H33+K33+N33 -> 0 | R33: =I33+L33+O33 -> 0 | S33: =SUM(Q33:R33) -> 0
J34: =SUM(H34:I34) -> 0 | K34: 0 | L34: 0 | M34: =SUM(K34:L34) -> 0 | N34: 0 | O34: 0 | P34: =SUM(N34:O34) -> 0 | Q34: =G34+H34+K34+N34 -> 0 | R34: =I34+L34+O34 -> 0 | S34: =SUM(Q34:R34) -> 0
J35: =SUM(H35:I35) -> 0 | K35: 0 | L35: 0 | M35: =SUM(K35:L35) -> 0 | N35: 0 | O35: 0 | P35: =SUM(N35:O35) -> 0 | Q35: =G35+H35+K35+N35 -> 0 | R35: =I35+L35+O35 -> 0 | S35: =SUM(Q35:R35) -> 0
E36: 5 | J36: =SUM(H36:I36) -> 0 | K36: 0 | L36: 0 | M36: =SUM(K36:L36) -> 0 | N36: 0 | O36: 0 | P36: =SUM(N36:O36) -> 0 | Q36: =G36+H36+K36+N36 -> 0 | R36: =I36+L36+O36 -> 0 | S36: =SUM(Q36:R36) -> 0
J37: =SUM(H37:I37) -> 0 | K37: 0 | L37: 0 | M37: =SUM(K37:L37) -> 0 | N37: 0 | O37: 0 | P37: =SUM(N37:O37) -> 0 | Q37: =G37+H37+K37+N37 -> 0 | R37: =I37+L37+O37 -> 0 | S37: =SUM(Q37:R37) -> 0
J38: =SUM(H38:I38) -> 0 | K38: 0 | L38: 0 | M38: =SUM(K38:L38) -> 0 | N38: 0 | O38: 0 | P38: =SUM(N38:O38) -> 0 | Q38: =G38+H38+K38+N38 -> 0 | R38: =I38+L38+O38 -> 0 | S38: =SUM(Q38:R38) -> 0
J39: =SUM(H39:I39) -> 0 | K39: 0 | L39: 0 | M39: =SUM(K39:L39) -> 0 | N39: 0 | O39: 0 | P39: =SUM(N39:O39) -> 0 | Q39: =G39+H39+K39+N39 -> 0 | R39: =I39+L39+O39 -> 0 | S39: =SUM(Q39:R39) -> 0
J40: =SUM(H40:I40) -> 0 | K40: 0 | L40: 0 | M40: =SUM(K40:L40) -> 0 | N40: 0 | O40: 0 | P40: =SUM(N40:O40) -> 0 | Q40: =G40+H40+K40+N40 -> 0 | R40: =I40+L40+O40 -> 0 | S40: =SUM(Q40:R40) -> 0
J41: =SUM(H41:I41) -> 0 | K41: 0 | L41: 0 | M41: =SUM(K41:L41) -> 0 | N41: 0 | O41: 0 | P41: =SUM(N41:O41) -> 0 | Q41: =G41+H41+K41+N41 -> 0 | R41: =I41+L41+O41 -> 0 | S41: =SUM(Q41:R41) -> 0
...

Sheet 연구개발비(2세부)
B2: 2-1. 연구개발비 지원.부담계획
D3: 구분 | G3: 정부지원 | H3: 기관부담 | K3: 그 외 기관 등의 지원금 | Q3: 합 계
G4: 연구개발비 | H4: 연구개발비 | K4: 지방자치단체 | N4: 기타( )
D5: 단계 | E5: 연차 | F5: 연구개발기관명 | G5: 현금 | H5: 현금 | I5: 현물 | J5: 소계 | K5: 현금 | L5: 현물 | M5: 소계 | N5: 현금 | O5: 현물 | P5: 소계 | Q5: 현금 | R5: 현물 | S5: 합계
F6: (기관역할1｣)
D7: 1 | E7: 1 | J7: =SUM(H7:I7) -> 0 | K7: 0 | L7: 0 | M7: =SUM(K7:L7) -> 0 | N7: 0 | O7: 0 | P7: =SUM(N7:O7) -> 0 | Q7: =G7+H7+K7+N7 -> 0 | R7: =I7+L7+O7 -> 0 | S7: =SUM(Q7:R7) -> 0
J8: =SUM(H8:I8) -> 0 | K8: 0 | L8: 0 | M8: =SUM(K8:L8) -> 0 | N8: 0 | O8: 0 | P8: =SUM(N8:O8) -> 0 | Q8: =G8+H8+K8+N8 -> 0 | R8: =I8+L8+O8 -> 0 | S8: =SUM(Q8:R8) -> 0
J9: =SUM(H9:I9) -> 0 | K9: 0 | L9: 0 | M9: =SUM(K9:L9) -> 0 | N9: 0 | O9: 0 | P9: =SUM(N9:O9) -> 0 | Q9: =G9+H9+K9+N9 -> 0 | R9: =I9+L9+O9 -> 0 | S9: =SUM(Q9:R9) -> 0
J10: =SUM(H10:I10) -> 0 | K10: 0 | L10: 0 | M10: =SUM(K10:L10) -> 0 | N10: 0 | O10: 0 | P10: =SUM(N10:O10) -> 0 | Q10: =G10+H10+K10+N10 -> 0 | R10: =I10+L10+O10 -> 0 | S10: =SUM(Q10:R10) -> 0
J11: =SUM(H11:I11) -> 0 | K11: 0 | L11: 0 | M11: =SUM(K11:L11) -> 0 | N11: 0 | O11: 0 | P11: =SUM(N11:O11) -> 0 | Q11: =G11+H11+K11+N11 -> 0 | R11: =I11+L11+O11 -> 0 | S11: =SUM(Q11:R11) -> 0
J12: =SUM(H12:I12) -> 0 | K12: 0 | L12: 0 | M12: =SUM(K12:L12) -> 0 | N12: 0 | O12: 0 | P12: =SUM(N12:O12) -> 0 | Q12: =G12+H12+K12+N12 -> 0 | R12: =I12+L12+O12 -> 0 | S12: =SUM(Q12:R12) -> 0
J13: =SUM(H13:I13) -> 0 | K13: 0 | L13: 0 | M13: =SUM(K13:L13) -> 0 | N13: 0 | O13: 0 | P13: =SUM(N13:O13) -> 0 | Q13: =G13+H13+K13+N13 -> 0 | R13: =I13+L13+O13 -> 0 | S13: =SUM(Q13:R13) -> 0
E14: 2 | J14: =SUM(H14:I14) -> 0 | K14: 0 | L14: 0 | M14: =SUM(K14:L14) -> 0 | N14: 0 | O14: 0 | P14: =SUM(N14:O14) -> 0 | Q14: =G14+H14+K14+N14 -> 0 | R14: =I14+L14+O14 -> 0 | S14: =SUM(Q14:R14) -> 0
J15: =SUM(H15:I15) -> 0 | K15: 0 | L15: 0 | M15: =SUM(K15:L15) -> 0 | N15: 0 | O15: 0 | P15: =SUM(N15:O15) -> 0 | Q15: =G15+H15+K15+N15 -> 0 | R15: =I15+L15+O15 -> 0 | S15: =SUM(Q15:R15) -> 0
J16: =SUM(H16:I16) -> 0 | K16: 0 | L16: 0 | M16: =SUM(K16:L16) -> 0 | N16: 0 | O16: 0 | P16: =SUM(N16:O16) -> 0 | Q16: =G16+H16+K16+N16 -> 0 | R16: =I16+L16+O16 -> 0 | S16: =SUM(Q16:R16) -> 0
J17: =SUM(H17:I17) -> 0 | K17: 0 | L17: 0 | M17: =SUM(K17:L17) -> 0 | N17: 0 | O17: 0 | P17: =SUM(N17:O17) -> 0 | Q17: =G17+H17+K17+N17 -> 0 | R17: =I17+L17+O17 -> 0 | S17: =SUM(Q17:R17) -> 0
J18: =SUM(H18:I18) -> 0 | K18: 0 | L18: 0 | M18: =SUM(K18:L18) -> 0 | N18: 0 | O18: 0 | P18: =SUM(N18:O18) -> 0 | Q18: =G18+H18+K18+N18 -> 0 | R18: =I18+L18+O18 -> 0 | S18: =SUM(Q18:R18) -> 0
J19: =SUM(H19:I19) -> 0 | K19: 0 | L19: 0 | M19: =SUM(K19:L19) -> 0 | N19: 0 | O19: 0 | P19: =SUM(N19:O19) -> 0 | Q19: =G19+H19+K19+N19 -> 0 | R19: =I19+L19+O19 -> 0 | S19: =SUM(Q19:R19) -> 0
J20: =SUM(H20:I20) -> 0 | K20: 0 | L20: 0 | M20: =SUM(K20:L20) -> 0 | N20: 0 | O20: 0 | P20: =SUM(N20:O20) -> 0 | Q20: =G20+H20+K20+N20 -> 0 | R20: =I20+L20+O20 -> 0 | S20: =SUM(Q20:R20) -> 0
E21: 3 | J21: =SUM(H21:I21) -> 0 | K21: 0 | L21: 0 | M21: =SUM(K21:L21) -> 0 | N21: 0 | O21: 0 | P21: =SUM(N21:O21) -> 0 | Q21: =G21+H21+K21+N21 -> 0 | R21: =I21+L21+O21 -> 0 | S21: =SUM(Q21:R21) -> 0
J22: =SUM(H22:I22) -> 0 | K22: 0 | L22: 0 | M22: =SUM(K22:L22) -> 0 | N22: 0 | O22: 0 | P22: =SUM(N22:O22) -> 0 | Q22: =G22+H22+K22+N22 -> 0 | R22: =I22+L22+O22 -> 0 | S22: =SUM(Q22:R22) -> 0
J23: =SUM(H23:I23) -> 0 | K23: 0 | L23: 0 | M23: =SUM(K23:L23) -> 0 | N23: 0 | O23: 0 | P23: =SUM(N23:O23) -> 0 | Q23: =G23+H23+K23+N23 -> 0 | R23: =I23+L23+O23 -> 0 | S23: =SUM(Q23:R23) -> 0
J24: =SUM(H24:I24) -> 0 | K24: 0 | L24: 0 | M24: =SUM(K24:L24) -> 0 | N24: 0 | O24: 0 | P24: =SUM(N24:O24) -> 0 | Q24: =G24+H24+K24+N24 -> 0 | R24: =I24+L24+O24 -> 0 | S24: =SUM(Q24:R24) -> 0
J25: =SUM(H25:I25) -> 0 | K25: 0 | L25: 0 | M25: =SUM(K25:L25) -> 0 | N25: 0 | O25: 0 | P25: =SUM(N25:O25) -> 0 | Q25: =G25+H25+K25+N25 -> 0 | R25: =I25+L25+O25 -> 0 | S25: =SUM(Q25:R25) -> 0
J26: =SUM(H26:I26) -> 0 | K26: 0 | L26: 0 | M26: =SUM(K26:L26) -> 0 | N26: 0 | O26: 0 | P26: =SUM(N26:O26) -> 0 | Q26: =G26+H26+K26+N26 -> 0 | R26: =I26+L26+O26 -> 0 | S26: =SUM(Q26:R26) -> 0
J27: =SUM(H27:I27) -> 0 | K27: 0 | L27: 0 | M27: =SUM(K27:L27) -> 0 | N27: 0 | O27: 0 | P27: =SUM(N27:O27) -> 0 | Q27: =G27+H27+K27+N27 -> 0 | R27: =I27+L27+O27 -> 0 | S27: =SUM(Q27:R27) -> 0
E28: 소계 | G28: =SUM(G7:G27) -> 0 | H28: =SUM(H7:H27) -> 0 | I28: =SUM(I7:I27) -> 0 | J28: =SUM(J7:J27) -> 0 | K28: =SUM(K7:K27) -> 0 | L28: =SUM(L7:L27) -> 0 | M28: =SUM(M7:M27) -> 0 | N28: =SUM(N7:N27) -> 0 | ... S28: =SUM(S7:S27) -> 0
D29: 2 | E29: 4 | J29: =SUM(H29:I29) -> 0 | K29: 0 | L29: 0 | M29: =SUM(K29:L29) -> 0 | N29: 0 | O29: 0 | P29: =SUM(N29:O29) -> 0 | Q29: =G29+H29+K29+N29 -> 0 | R29: =I29+L29+O29 -> 0 | S29: =SUM(Q29:R29) -> 0
J30: =SUM(H30:I30) -> 0 | K30: 0 | L30: 0 | M30: =SUM(K30:L30) -> 0 | N30: 0 | O30: 0 | P30: =SUM(N30:O30) -> 0 | Q30: =G30+H30+K30+N30 -> 0 | R30: =I30+L30+O30 -> 0 | S30: =SUM(Q30:R30) -> 0
J31: =SUM(H31:I31) -> 0 | K31: 0 | L31: 0 | M31: =SUM(K31:L31) -> 0 | N31: 0 | O31: 0 | P31: =SUM(N31:O31) -> 0 | Q31: =G31+H31+K31+N31 -> 0 | R31: =I31+L31+O31 -> 0 | S31: =SUM(Q31:R31) -> 0
J32: =SUM(H32:I32) -> 0 | K32: 0 | L32: 0 | M32: =SUM(K32:L32) -> 0 | N32: 0 | O32: 0 | P32: =SUM(N32:O32) -> 0 | Q32: =G32+H32+K32+N32 -> 0 | R32: =I32+L32+O32 -> 0 | S32: =SUM(Q32:R32) -> 0
J33: =SUM(H33:I33) -> 0 | K33: 0 | L33: 0 | M33: =SUM(K33:L33) -> 0 | N33: 0 | O33: 0 | P33: =SUM(N33:O33) -> 0 | Q33: =G33+H33+K33+N33 -> 0 | R33: =I33+L33+O33 -> 0 | S33: =SUM(Q33:R33) -> 0
J34: =SUM(H34:I34) -> 0 | K34: 0 | L34: 0 | M34: =SUM(K34:L34) -> 0 | N34: 0 | O34: 0 | P34: =SUM(N34:O34) -> 0 | Q34: =G34+H34+K34+N34 -> 0 | R34: =I34+L34+O34 -> 0 | S34: =SUM(Q34:R34) -> 0
J35: =SUM(H35:I35) -> 0 | K35: 0 | L35: 0 | M35: =SUM(K35:L35) -> 0 | N35: 0 | O35: 0 | P35: =SUM(N35:O35) -> 0 | Q35: =G35+H35+K35+N35 -> 0 | R35: =I35+L35+O35 -> 0 | S35: =SUM(Q35:R35) -> 0
E36: 5 | J36: =SUM(H36:I36) -> 0 | K36: 0 | L36: 0 | M36: =SUM(K36:L36) -> 0 | N36: 0 | O36: 0 | P36: =SUM(N36:O36) -> 0 | Q36: =G36+H36+K36+N36 -> 0 | R36: =I36+L36+O36 -> 0 | S36: =SUM(Q36:R36) -> 0
J37: =SUM(H37:I37) -> 0 | K37: 0 | L37: 0 | M37: =SUM(K37:L37) -> 0 | N37: 0 | O37: 0 | P37: =SUM(N37:O37) -> 0 | Q37: =G37+H37+K37+N37 -> 0 | R37: =I37+L37+O37 -> 0 | S37: =SUM(Q37:R37) -> 0
J38: =SUM(H38:I38) -> 0 | K38: 0 | L38: 0 | M38: =SUM(K38:L38) -> 0 | N38: 0 | O38: 0 | P38: =SUM(N38:O38) -> 0 | Q38: =G38+H38+K38+N38 -> 0 | R38: =I38+L38+O38 -> 0 | S38: =SUM(Q38:R38) -> 0
J39: =SUM(H39:I39) -> 0 | K39: 0 | L39: 0 | M39: =SUM(K39:L39) -> 0 | N39: 0 | O39: 0 | P39: =SUM(N39:O39) -> 0 | Q39: =G39+H39+K39+N39 -> 0 | R39: =I39+L39+O39 -> 0 | S39: =SUM(Q39:R39) -> 0
J40: =SUM(H40:I40) -> 0 | K40: 0 | L40: 0 | M40: =SUM(K40:L40) -> 0 | N40: 0 | O40: 0 | P40: =SUM(N40:O40) -> 0 | Q40: =G40+H40+K40+N40 -> 0 | R40: =I40+L40+O40 -> 0 | S40: =SUM(Q40:R40) -> 0
J41: =SUM(H41:I41) -> 0 | K41: 0 | L41: 0 | M41: =SUM(K41:L41) -> 0 | N41: 0 | O41: 0 | P41: =SUM(N41:O41) -> 0 | Q41: =G41+H41+K41+N41 -> 0 | R41: =I41+L41+O41 -> 0 | S41: =SUM(Q41:R41) -> 0
...

Sheet 연구개발비(3세부)
B2: 2-1. 연구개발비 지원.부담계획
D3: 구분 | G3: 정부지원 | H3: 기관부담 | K3: 그 외 기관 등의 지원금 | Q3: 합 계
G4: 연구개발비 | H4: 연구개발비 | K4: 지방자치단체 | N4: 기타( )
D5: 단계 | E5: 연차 | F5: 연구개발기관명 | G5: 현금 | H5: 현금 | I5: 현물 | J5: 소계 | K5: 현금 | L5: 현물 | M5: 소계 | N5: 현금 | O5: 현물 | P5: 소계 | Q5: 현금 | R5: 현물 | S5: 합계
F6: (기관역할1｣)
D7: 1 | E7: 1 | J7: =SUM(H7:I7) -> 0 | K7: 0 | L7: 0 | M7: =SUM(K7:L7) -> 0 | N7: 0 | O7: 0 | P7: =SUM(N7:O7) -> 0 | Q7: =G7+H7+K7+N7 -> 0 | R7: =I7+L7+O7 -> 0 | S7: =SUM(Q7:R7) -> 0
J8: =SUM(H8:I8) -> 0 | K8: 0 | L8: 0 | M8: =SUM(K8:L8) -> 0 | N8: 0 | O8: 0 | P8: =SUM(N8:O8) -> 0 | Q8: =G8+H8+K8+N8 -> 0 | R8: =I8+L8+O8 -> 0 | S8: =SUM(Q8:R8) -> 0
J9: =SUM(H9:I9) -> 0 | K9: 0 | L9: 0 | M9: =SUM(K9:L9) -> 0 | N9: 0 | O9: 0 | P9: =SUM(N9:O9) -> 0 | Q9: =G9+H9+K9+N9 -> 0 | R9: =I9+L9+O9 -> 0 | S9: =SUM(Q9:R9) -> 0
J10: =SUM(H10:I10) -> 0 | K10: 0 | L10: 0 | M10: =SUM(K10:L10) -> 0 | N10: 0 | O10: 0 | P10: =SUM(N10:O10) -> 0 | Q10: =G10+H10+K10+N10 -> 0 | R10: =I10+L10+O10 -> 0 | S10: =SUM(Q10:R10) -> 0
J11: =SUM(H11:I11) -> 0 | K11: 0 | L11: 0 | M11: =SUM(K11:L11) -> 0 | N11: 0 | O11: 0 | P11: =SUM(N11:O11) -> 0 | Q11: =G11+H11+K11+N11 -> 0 | R11: =I11+L11+O11 -> 0 | S11: =SUM(Q11:R11) -> 0
J12: =SUM(H12:I12) -> 0 | K12: 0 | L12: 0 | M12: =SUM(K12:L12) -> 0 | N12: 0 | O12: 0 | P12: =SUM(N12:O12) -> 0 | Q12: =G12+H12+K12+N12 -> 0 | R12: =I12+L12+O12 -> 0 | S12: =SUM(Q12:R12) -> 0
J13: =SUM(H13:I13) -> 0 | K13: 0 | L13: 0 | M13: =SUM(K13:L13) -> 0 | N13: 0 | O13: 0 | P13: =SUM(N13:O13) -> 0 | Q13: =G13+H13+K13+N13 -> 0 | R13: =I13+L13+O13 -> 0 | S13: =SUM(Q13:R13) -> 0
E14: 2 | J14: =SUM(H14:I14) -> 0 | K14: 0 | L14: 0 | M14: =SUM(K14:L14) -> 0 | N14: 0 | O14: 0 | P14: =SUM(N14:O14) -> 0 | Q14: =G14+H14+K14+N14 -> 0 | R14: =I14+L14+O14 -> 0 | S14: =SUM(Q14:R14) -> 0
J15: =SUM(H15:I15) -> 0 | K15: 0 | L15: 0 | M15: =SUM(K15:L15) -> 0 | N15: 0 | O15: 0 | P15: =SUM(N15:O15) -> 0 | Q15: =G15+H15+K15+N15 -> 0 | R15: =I15+L15+O15 -> 0 | S15: =SUM(Q15:R15) -> 0
J16: =SUM(H16:I16) -> 0 | K16: 0 | L16: 0 | M16: =SUM(K16:L16) -> 0 | N16: 0 | O16: 0 | P16: =SUM(N16:O16) -> 0 | Q16: =G16+H16+K16+N16 -> 0 | R16: =I16+L16+O16 -> 0 | S16: =SUM(Q16:R16) -> 0
J17: =SUM(H17:I17) -> 0 | K17: 0 | L17: 0 | M17: =SUM(K17:L17) -> 0 | N17: 0 | O17: 0 | P17: =SUM(N17:O17) -> 0 | Q17: =G17+H17+K17+N17 -> 0 | R17: =I17+L17+O17 -> 0 | S17: =SUM(Q17:R17) -> 0
J18: =SUM(H18:I18) -> 0 | K18: 0 | L18: 0 | M18: =SUM(K18:L18) -> 0 | N18: 0 | O18: 0 | P18: =SUM(N18:O18) -> 0 | Q18: =G18+H18+K18+N18 -> 0 | R18: =I18+L18+O18 -> 0 | S18: =SUM(Q18:R18) -> 0
J19: =SUM(H19:I19) -> 0 | K19: 0 | L19: 0 | M19: =SUM(K19:L19) -> 0 | N19: 0 | O19: 0 | P19: =SUM(N19:O19) -> 0 | Q19: =G19+H19+K19+N19 -> 0 | R19: =I19+L19+O19 -> 0 | S19: =SUM(Q19:R19) -> 0
J20: =SUM(H20:I20) -> 0 | K20: 0 | L20: 0 | M20: =SUM(K20:L20) -> 0 | N20: 0 | O20: 0 | P20: =SUM(N20:O20) -> 0 | Q20: =G20+H20+K20+N20 -> 0 | R20: =I20+L20+O20 -> 0 | S20: =SUM(Q20:R20) -> 0
E21: 3 | J21: =SUM(H21:I21) -> 0 | K21: 0 | L21: 0 | M21: =SUM(K21:L21) -> 0 | N21: 0 | O21: 0 | P21: =SUM(N21:O21) -> 0 | Q21: =G21+H21+K21+N21 -> 0 | R21: =I21+L21+O21 -> 0 | S21: =SUM(Q21:R21) -> 0
J22: =SUM(H22:I22) -> 0 | K22: 0 | L22: 0 | M22: =SUM(K22:L22) -> 0 | N22: 0 | O22: 0 | P22: =SUM(N22:O22) -> 0 | Q22: =G22+H22+K22+N22 -> 0 | R22: =I22+L22+O22 -> 0 | S22: =SUM(Q22:R22) -> 0
J23: =SUM(H23:I23) -> 0 | K23: 0 | L23: 0 | M23: =SUM(K23:L23) -> 0 | N23: 0 | O23: 0 | P23: =SUM(N23:O23) -> 0 | Q23: =G23+H23+K23+N23 -> 0 | R23: =I23+L23+O23 -> 0 | S23: =SUM(Q23:R23) -> 0
J24: =SUM(H24:I24) -> 0 | K24: 0 | L24: 0 | M24: =SUM(K24:L24) -> 0 | N24: 0 | O24: 0 | P24: =SUM(N24:O24) -> 0 | Q24: =G24+H24+K24+N24 -> 0 | R24: =I24+L24+O24 -> 0 | S24: =SUM(Q24:R24) -> 0
J25: =SUM(H25:I25) -> 0 | K25: 0 | L25: 0 | M25: =SUM(K25:L25) -> 0 | N25: 0 | O25: 0 | P25: =SUM(N25:O25) -> 0 | Q25: =G25+H25+K25+N25 -> 0 | R25: =I25+L25+O25 -> 0 | S25: =SUM(Q25:R25) -> 0
J26: =SUM(H26:I26) -> 0 | K26: 0 | L26: 0 | M26: =SUM(K26:L26) -> 0 | N26: 0 | O26: 0 | P26: =SUM(N26:O26) -> 0 | Q26: =G26+H26+K26+N26 -> 0 | R26: =I26+L26+O26 -> 0 | S26: =SUM(Q26:R26) -> 0
J27: =SUM(H27:I27) -> 0 | K27: 0 | L27: 0 | M27: =SUM(K27:L27) -> 0 | N27: 0 | O27: 0 | P27: =SUM(N27:O27) -> 0 | Q27: =G27+H27+K27+N27 -> 0 | R27: =I27+L27+O27 -> 0 | S27: =SUM(Q27:R27) -> 0
E28: 소계 | G28: =SUM(G7:G27) -> 0 | H28: =SUM(H7:H27) -> 0 | I28: =SUM(I7:I27) -> 0 | J28: =SUM(J7:J27) -> 0 | K28: =SUM(K7:K27) -> 0 | L28: =SUM(L7:L27) -> 0 | M28: =SUM(M7:M27) -> 0 | N28: =SUM(N7:N27) -> 0 | ... S28: =SUM(S7:S27) -> 0
D29: 2 | E29: 4 | J29: =SUM(H29:I29) -> 0 | K29: 0 | L29: 0 | M29: =SUM(K29:L29) -> 0 | N29: 0 | O29: 0 | P29: =SUM(N29:O29) -> 0 | Q29: =G29+H29+K29+N29 -> 0 | R29: =I29+L29+O29 -> 0 | S29: =SUM(Q29:R29) -> 0
J30: =SUM(H30:I30) -> 0 | K30: 0 | L30: 0 | M30: =SUM(K30:L30) -> 0 | N30: 0 | O30: 0 | P30: =SUM(N30:O30) -> 0 | Q30: =G30+H30+K30+N30 -> 0 | R30: =I30+L30+O30 -> 0 | S30: =SUM(Q30:R30) -> 0
J31: =SUM(H31:I31) -> 0 | K31: 0 | L31: 0 | M31: =SUM(K31:L31) -> 0 | N31: 0 | O31: 0 | P31: =SUM(N31:O31) -> 0 | Q31: =G31+H31+K31+N31 -> 0 | R31: =I31+L31+O31 -> 0 | S31: =SUM(Q31:R31) -> 0
J32: =SUM(H32:I32) -> 0 | K32: 0 | L32: 0 | M32: =SUM(K32:L32) -> 0 | N32: 0 | O32: 0 | P32: =SUM(N32:O32) -> 0 | Q32: =G32+H32+K32+N32 -> 0 | R32: =I32+L32+O32 -> 0 | S32: =SUM(Q32:R32) -> 0
J33: =SUM(H33:I33) -> 0 | K33: 0 | L33: 0 | M33: =SUM(K33:L33) -> 0 | N33: 0 | O33: 0 | P33: =SUM(N33:O33) -> 0 | Q33: =G33+H33+K33+N33 -> 0 | R33: =I33+L33+O33 -> 0 | S33: =SUM(Q33:R33) -> 0
J34: =SUM(H34:I34) -> 0 | K34: 0 | L34: 0 | M34: =SUM(K34:L34) -> 0 | N34: 0 | O34: 0 | P34: =SUM(N34:O34) -> 0 | Q34: =G34+H34+K34+N34 -> 0 | R34: =I34+L34+O34 -> 0 | S34: =SUM(Q34:R34) -> 0
J35: =SUM(H35:I35) -> 0 | K35: 0 | L35: 0 | M35: =SUM(K35:L35) -> 0 | N35: 0 | O35: 0 | P35: =SUM(N35:O35) -> 0 | Q35: =G35+H35+K35+N35 -> 0 | R35: =I35+L35+O35 -> 0 | S35: =SUM(Q35:R35) -> 0
E36: 5 | J36: =SUM(H36:I36) -> 0 | K36: 0 | L36: 0 | M36: =SUM(K36:L36) -> 0 | N36: 0 | O36: 0 | P36: =SUM(N36:O36) -> 0 | Q36: =G36+H36+K36+N36 -> 0 | R36: =I36+L36+O36 -> 0 | S36: =SUM(Q36:R36) -> 0
J37: =SUM(H37:I37) -> 0 | K37: 0 | L37: 0 | M37: =SUM(K37:L37) -> 0 | N37: 0 | O37: 0 | P37: =SUM(N37:O37) -> 0 | Q37: =G37+H37+K37+N37 -> 0 | R37: =I37+L37+O37 -> 0 | S37: =SUM(Q37:R37) -> 0
J38: =SUM(H38:I38) -> 0 | K38: 0 | L38: 0 | M38: =SUM(K38:L38) -> 0 | N38: 0 | O38: 0 | P38: =SUM(N38:O38) -> 0 | Q38: =G38+H38+K38+N38 -> 0 | R38: =I38+L38+O38 -> 0 | S38: =SUM(Q38:R38) -> 0
J39: =SUM(H39:I39) -> 0 | K39: 0 | L39: 0 | M39: =SUM(K39:L39) -> 0 | N39: 0 | O39: 0 | P39: =SUM(N39:O39) -> 0 | Q39: =G39+H39+K39+N39 -> 0 | R39: =I39+L39+O39 -> 0 | S39: =SUM(Q39:R39) -> 0
J40: =SUM(H40:I40) -> 0 | K40: 0 | L40: 0 | M40: =SUM(K40:L40) -> 0 | N40: 0 | O40: 0 | P40: =SUM(N40:O40) -> 0 | Q40: =G40+H40+K40+N40 -> 0 | R40: =I40+L40+O40 -> 0 | S40: =SUM(Q40:R40) -> 0
J41: =SUM(H41:I41) -> 0 | K41: 0 | L41: 0 | M41: =SUM(K41:L41) -> 0 | N41: 0 | O41: 0 | P41: =SUM(N41:O41) -> 0 | Q41: =G41+H41+K41+N41 -> 0 | R41: =I41+L41+O41 -> 0 | S41: =SUM(Q41:R41) -> 0
...

Sheet 연구개발비(4세부)
B2: 2-1. 연구개발비 지원.부담계획
D3: 구분 | G3: 정부지원 | H3: 기관부담 | K3: 그 외 기관 등의 지원금 | Q3: 합 계
G4: 연구개발비 | H4: 연구개발비 | K4: 지방자치단체 | N4: 기타( )
D5: 단계 | E5: 연차 | F5: 연구개발기관명 | G5: 현금 | H5: 현금 | I5: 현물 | J5: 소계 | K5: 현금 | L5: 현물 | M5: 소계 | N5: 현금 | O5: 현물 | P5: 소계 | Q5: 현금 | R5: 현물 | S5: 합계
F6: (기관역할1｣)
D7: 1 | E7: 1 | J7: =SUM(H7:I7) -> 0 | K7: 0 | L7: 0 | M7: =SUM(K7:L7) -> 0 | N7: 0 | O7: 0 | P7: =SUM(N7:O7) -> 0 | Q7: =G7+H7+K7+N7 -> 0 | R7: =I7+L7+O7 -> 0 | S7: =SUM(Q7:R7) -> 0
J8: =SUM(H8:I8) -> 0 | K8: 0 | L8: 0 | M8: =SUM(K8:L8) -> 0 | N8: 0 | O8: 0 | P8: =SUM(N8:O8) -> 0 | Q8: =G8+H8+K8+N8 -> 0 | R8: =I8+L8+O8 -> 0 | S8: =SUM(Q8:R8) -> 0
J9: =SUM(H9:I9) -> 0 | K9: 0 | L9: 0 | M9: =SUM(K9:L9) -> 0 | N9: 0 | O9: 0 | P9: =SUM(N9:O9) -> 0 | Q9: =G9+H9+K9+N9 -> 0 | R9: =I9+L9+O9 -> 0 | S9: =SUM(Q9:R9) -> 0
J10: =SUM(H10:I10) -> 0 | K10: 0 | L10: 0 | M10: =SUM(K10:L10) -> 0 | N10: 0 | O10: 0 | P10: =SUM(N10:O10) -> 0 | Q10: =G10+H10+K10+N10 -> 0 | R10: =I10+L10+O10 -> 0 | S10: =SUM(Q10:R10) -> 0
J11: =SUM(H11:I11) -> 0 | K11: 0 | L11: 0 | M11: =SUM(K11:L11) -> 0 | N11: 0 | O11: 0 | P11: =SUM(N11:O11) -> 0 | Q11: =G11+H11+K11+N11 -> 0 | R11: =I11+L11+O11 -> 0 | S11: =SUM(Q11:R11) -> 0
J12: =SUM(H12:I12) -> 0 | K12: 0 | L12: 0 | M12: =SUM(K12:L12) -> 0 | N12: 0 | O12: 0 | P12: =SUM(N12:O12) -> 0 | Q12: =G12+H12+K12+N12 -> 0 | R12: =I12+L12+O12 -> 0 | S12: =SUM(Q12:R12) -> 0
J13: =SUM(H13:I13) -> 0 | K13: 0 | L13: 0 | M13: =SUM(K13:L13) -> 0 | N13: 0 | O13: 0 | P13: =SUM(N13:O13) -> 0 | Q13: =G13+H13+K13+N13 -> 0 | R13: =I13+L13+O13 -> 0 | S13: =SUM(Q13:R13) -> 0
E14: 2 | J14: =SUM(H14:I14) -> 0 | K14: 0 | L14: 0 | M14: =SUM(K14:L14) -> 0 | N14: 0 | O14: 0 | P14: =SUM(N14:O14) -> 0 | Q14: =G14+H14+K14+N14 -> 0 | R14: =I14+L14+O14 -> 0 | S14: =SUM(Q14:R14) -> 0
J15: =SUM(H15:I15) -> 0 | K15: 0 | L15: 0 | M15: =SUM(K15:L15) -> 0 | N15: 0 | O15: 0 | P15: =SUM(N15:O15) -> 0 | Q15: =G15+H15+K15+N15 -> 0 | R15: =I15+L15+O15 -> 0 | S15: =SUM(Q15:R15) -> 0
J16: =SUM(H16:I16) -> 0 | K16: 0 | L16: 0 | M16: =SUM(K16:L16) -> 0 | N16: 0 | O16: 0 | P16: =SUM(N16:O16) -> 0 | Q16: =G16+H16+K16+N16 -> 0 | R16: =I16+L16+O16 -> 0 | S16: =SUM(Q16:R16) -> 0
J17: =SUM(H17:I17) -> 0 | K17: 0 | L17: 0 | M17: =SUM(K17:L17) -> 0 | N17: 0 | O17: 0 | P17: =SUM(N17:O17) -> 0 | Q17: =G17+H17+K17+N17 -> 0 | R17: =I17+L17+O17 -> 0 | S17: =SUM(Q17:R17) -> 0
J18: =SUM(H18:I18) -> 0 | K18: 0 | L18: 0 | M18: =SUM(K18:L18) -> 0 | N18: 0 | O18: 0 | P18: =SUM(N18:O18) -> 0 | Q18: =G18+H18+K18+N18 -> 0 | R18: =I18+L18+O18 -> 0 | S18: =SUM(Q18:R18) -> 0
J19: =SUM(H19:I19) -> 0 | K19: 0 | L19: 0 | M19: =SUM(K19:L19) -> 0 | N19: 0 | O19: 0 | P19: =SUM(N19:O19) -> 0 | Q19: =G19+H19+K19+N19 -> 0 | R19: =I19+L19+O19 -> 0 | S19: =SUM(Q19:R19) -> 0
J20: =SUM(H20:I20) -> 0 | K20: 0 | L20: 0 | M20: =SUM(K20:L20) -> 0 | N20: 0 | O20: 0 | P20: =SUM(N20:O20) -> 0 | Q20: =G20+H20+K20+N20 -> 0 | R20: =I20+L20+O20 -> 0 | S20: =SUM(Q20:R20) -> 0
E21: 3 | J21: =SUM(H21:I21) -> 0 | K21: 0 | L21: 0 | M21: =SUM(K21:L21) -> 0 | N21: 0 | O21: 0 | P21: =SUM(N21:O21) -> 0 | Q21: =G21+H21+K21+N21 -> 0 | R21: =I21+L21+O21 -> 0 | S21: =SUM(Q21:R21) -> 0
J22: =SUM(H22:I22) -> 0 | K22: 0 | L22: 0 | M22: =SUM(K22:L22) -> 0 | N22: 0 | O22: 0 | P22: =SUM(N22:O22) -> 0 | Q22: =G22+H22+K22+N22 -> 0 | R22: =I22+L22+O22 -> 0 | S22: =SUM(Q22:R22) -> 0
J23: =SUM(H23:I23) -> 0 | K23: 0 | L23: 0 | M23: =SUM(K23:L23) -> 0 | N23: 0 | O23: 0 | P23: =SUM(N23:O23) -> 0 | Q23: =G23+H23+K23+N23 -> 0 | R23: =I23+L23+O23 -> 0 | S23: =SUM(Q23:R23) -> 0
J24: =SUM(H24:I24) -> 0 | K24: 0 | L24: 0 | M24: =SUM(K24:L24) -> 0 | N24: 0 | O24: 0 | P24: =SUM(N24:O24) -> 0 | Q24: =G24+H24+K24+N24 -> 0 | R24: =I24+L24+O24 -> 0 | S24: =SUM(Q24:R24) -> 0
J25: =SUM(H25:I25) -> 0 | K25: 0 | L25: 0 | M25: =SUM(K25:L25) -> 0 | N25: 0 | O25: 0 | P25: =SUM(N25:O25) -> 0 | Q25: =G25+H25+K25+N25 -> 0 | R25: =I25+L25+O25 -> 0 | S25: =SUM(Q25:R25) -> 0
J26: =SUM(H26:I26) -> 0 | K26: 0 | L26: 0 | M26: =SUM(K26:L26) -> 0 | N26: 0 | O26: 0 | P26: =SUM(N26:O26) -> 0 | Q26: =G26+H26+K26+N26 -> 0 | R26: =I26+L26+O26 -> 0 | S26: =SUM(Q26:R26) -> 0
J27: =SUM(H27:I27) -> 0 | K27: 0 | L27: 0 | M27: =SUM(K27:L27) -> 0 | N27: 0 | O27: 0 | P27: =SUM(N27:O27) -> 0 | Q27: =G27+H27+K27+N27 -> 0 | R27: =I27+L27+O27 -> 0 | S27: =SUM(Q27:R27) -> 0
E28: 소계 | G28: =SUM(G7:G27) -> 0 | H28: =SUM(H7:H27) -> 0 | I28: =SUM(I7:I27) -> 0 | J28: =SUM(J7:J27) -> 0 | K28: =SUM(K7:K27) -> 0 | L28: =SUM(L7:L27) -> 0 | M28: =SUM(M7:M27) -> 0 | N28: =SUM(N7:N27) -> 0 | ... S28: =SUM(S7:S27) -> 0
